Workbook

Sheet P&L
A1: alche — 24-Month P&L
A2: Pre-Seed | EUR 500K @ EUR 2.5M Cap | v4: Annual subs + B2B + Gift Cards + Corrected App/Rent costs
A3: All amounts in EUR net of VAT. Click any cell to see the formula.
A4: Budget P&L (EUR) | B4: M1 | C4: M2 | D4: M3 | E4: M4 | F4: M5 | G4: M6 | H4: M7 | I4: M8 | J4: M9 | K4: M10 | L4: M11 | M4: M12 | N4: M13 | O4: M14 | P4: M15 | Q4: M16 | R4: M17 | S4: M18 | T4: M19 | U4: M20 | V4: M21 | W4: M22 | X4: M23 | Y4: M24 | Z4: TOTAL
A5: SUBSCRIBER METRICS
A6: New Subs Added | B6: ='Growth Curves'!B15 -> 0 | C6: ='Growth Curves'!C15 -> 0 | D6: ='Growth Curves'!D15 -> 0 | E6: ='Growth Curves'!E15 -> 15 | F6: ='Growth Curves'!F15 -> 15 | G6: ='Growth Curves'!G15 -> 15 | H6: ='Growth Curves'!H15 -> 22 | I6: ='Growth Curves'!I15 -> 22 | ... Y6: ='Growth Curves'!Y15 -> 38 | Z6: =SUM(B6:Y6) -> 615
A7: Churned Subs | B7: ='Growth Curves'!B16 -> 0 | C7: ='Growth Curves'!C16 -> 0 | D7: ='Growth Curves'!D16 -> 0 | E7: ='Growth Curves'!E16 -> 0 | F7: ='Growth Curves'!F16 -> 1 | G7: ='Growth Curves'!G16 -> 2 | H7: ='Growth Curves'!H16 -> 3 | I7: ='Growth Curves'!I16 -> 5 | ... Y7: ='Growth Curves'!Y16 -> 26 | Z7: =SUM(B7:Y7) -> 278
A8: Total Subscribers | B8: ='Growth Curves'!B17 -> 0 | C8: ='Growth Curves'!C17 -> 0 | D8: ='Growth Curves'!D17 -> 0 | E8: ='Growth Curves'!E17 -> 15 | F8: ='Growth Curves'!F17 -> 29 | G8: ='Growth Curves'!G17 -> 42 | H8: ='Growth Curves'!H17 -> 61 | I8: ='Growth Curves'!I17 -> 78 | ... Y8: ='Growth Curves'!Y17 -> 337 | Z8: =SUM(B8:Y8) -> 3804
A9: Core (52%) | B9: ='Growth Curves'!B18 -> 0 | C9: ='Growth Curves'!C18 -> 0 | D9: ='Growth Curves'!D18 -> 0 | E9: ='Growth Curves'!E18 -> 8 | F9: ='Growth Curves'!F18 -> 15 | G9: ='Growth Curves'!G18 -> 22 | H9: ='Growth Curves'!H18 -> 32 | I9: ='Growth Curves'!I18 -> 41 | ... Y9: ='Growth Curves'!Y18 -> 175 | Z9: =SUM(B9:Y9) -> 1978
A10: Pro (38%) | B10: ='Growth Curves'!B19 -> 0 | C10: ='Growth Curves'!C19 -> 0 | D10: ='Growth Curves'!D19 -> 0 | E10: ='Growth Curves'!E19 -> 6 | F10: ='Growth Curves'!F19 -> 11 | G10: ='Growth Curves'!G19 -> 16 | H10: ='Growth Curves'!H19 -> 23 | I10: ='Growth Curves'!I19 -> 30 | ... Y10: ='Growth Curves'!Y19 -> 128 | Z10: =SUM(B10:Y10) -> 1447
A11: Premium (10%) | B11: ='Growth Curves'!B20 -> 0 | C11: ='Growth Curves'!C20 -> 0 | D11: ='Growth Curves'!D20 -> 0 | E11: ='Growth Curves'!E20 -> 1 | F11: ='Growth Curves'!F20 -> 3 | G11: ='Growth Curves'!G20 -> 4 | H11: ='Growth Curves'!H20 -> 6 | I11: ='Growth Curves'!I20 -> 7 | ... Y11: ='Growth Curves'!Y20 -> 34 | Z11: =SUM(B11:Y11) -> 379
A13: INCOME
A14: Retail Products (D11: EUR 49 validated, COGS EUR 23.50)
A15: Units sold | B15: ='Growth Curves'!B4 -> 0 | C15: ='Growth Curves'!C4 -> 0 | D15: ='Growth Curves'!D4 -> 0 | E15: ='Growth Curves'!E4 -> 50 | F15: ='Growth Curves'!F4 -> 100 | G15: ='Growth Curves'!G4 -> 150 | H15: ='Growth Curves'!H4 -> 250 | I15: ='Growth Curves'!I4 -> 350 | ... Y15: ='Growth Curves'!Y4 -> 4600 | Z15: =SUM(B15:Y15) -> 35500
A16: Price/unit | B16: =Assumptions!B22 -> 49 | C16: =Assumptions!B22 -> 49 | D16: =Assumptions!B22 -> 49 | E16: =Assumptions!B22 -> 49 | F16: =Assumptions!B22 -> 49 | G16: =Assumptions!B22 -> 49 | H16: =Assumptions!B22 -> 49 | I16: =Assumptions!B22 -> 49 | J16: =Assumptions!B22 -> 49 | K16: =Assumptions!B22 -> 49 | L16: =Assumptions!B22 -> 49 | M16: =Assumptions!B22 -> 49 | N16: =Assumptions!B22 -> 49 | O16: =Assumptions!B22 -> 49 | P16: =Assumptions!B22 -> 49 | Q16: =Assumptions!B22 -> 49 | R16: =Assumptions!B22 -> 49 | S16: =Assumptions!B22 -> 49 | T16: =Assumptions!B22 -> 49 | U16: =Assumptions!B22 -> 49 | V16: =Assumptions!B22 -> 49 | W16: =Assumptions!B22 -> 49 | X16: =Assumptions!B22 -> 49 | Y16: =Assumptions!B22 -> 49 | Z16: =SUM(B16:Y16) -> 1176
A17: Revenue | B17: =B15*Assumptions!B22 -> 0 | C17: =C15*Assumptions!B22 -> 0 | D17: =D15*Assumptions!B22 -> 0 | E17: =E15*Assumptions!B22 -> 2450 | F17: =F15*Assumptions!B22 -> 4900 | G17: =G15*Assumptions!B22 -> 7350 | H17: =H15*Assumptions!B22 -> 12250 | I17: =I15*Assumptions!B22 -> 17150 | J17: =J15*Assumptions!B22 -> 22050 | K17: =K15*Assumptions!B22 -> 29400 | L17: =L15*Assumptions!B22 -> 36750 | M17: =M15*Assumptions!B22 -> 44100 | N17: =N15*Assumptions!B22 -> 53900 | O17: =O15*Assumptions!B22 -> 63700 | P17: =P15*Assumptions!B22 -> 73500 | Q17: =Q15*Assumptions!B22 -> 88200 | R17: =R15*Assumptions!B22 -> 102900 | S17: =S15*Assumptions!B22 -> 117600 | T17: =T15*Assumptions!B22 -> 132300 | U17: =U15*Assumptions!B22 -> 147000 | V17: =V15*Assumptions!B22 -> 166600 | W17: =W15*Assumptions!B22 -> 186200 | X17: =X15*Assumptions!B22 -> 205800 | Y17: =Y15*Assumptions!B22 -> 225400 | Z17: =SUM(B17:Y17) -> 1739500
A18: LED Therapy (Free with Smoothie)
A19: Sessions (self-service) | B19: ='Growth Curves'!B5 -> 0 | C19: ='Growth Curves'!C5 -> 0 | D19: ='Growth Curves'!D5 -> 0 | E19: ='Growth Curves'!E5 -> 10 | F19: ='Growth Curves'!F5 -> 20 | G19: ='Growth Curves'!G5 -> 35 | H19: ='Growth Curves'!H5 -> 50 | I19: ='Growth Curves'!I5 -> 65 | ... Y19: ='Growth Curves'!Y5 -> 300 | Z19: =SUM(B19:Y19) -> 3660
A20: Price/session | B20: =Assumptions!B24 -> 0 | C20: =Assumptions!B24 -> 0 | D20: =Assumptions!B24 -> 0 | E20: =Assumptions!B24 -> 0 | F20: =Assumptions!B24 -> 0 | G20: =Assumptions!B24 -> 0 | H20: =Assumptions!B24 -> 0 | I20: =Assumptions!B24 -> 0 | J20: =Assumptions!B24 -> 0 | K20: =Assumptions!B24 -> 0 | L20: =Assumptions!B24 -> 0 | M20: =Assumptions!B24 -> 0 | N20: =Assumptions!B24 -> 0 | O20: =Assumptions!B24 -> 0 | P20: =Assumptions!B24 -> 0 | Q20: =Assumptions!B24 -> 0 | R20: =Assumptions!B24 -> 0 | S20: =Assumptions!B24 -> 0 | T20: =Assumptions!B24 -> 0 | U20: =Assumptions!B24 -> 0 | V20: =Assumptions!B24 -> 0 | W20: =Assumptions!B24 -> 0 | X20: =Assumptions!B24 -> 0 | Y20: =Assumptions!B24 -> 0 | Z20: =SUM(B20:Y20) -> 0
A21: Revenue (EUR 0 — free amenity) | B21: =B19*Assumptions!B24 -> 0 | C21: =C19*Assumptions!B24 -> 0 | D21: =D19*Assumptions!B24 -> 0 | E21: =E19*Assumptions!B24 -> 0 | F21: =F19*Assumptions!B24 -> 0 | G21: =G19*Assumptions!B24 -> 0 | H21: =H19*Assumptions!B24 -> 0 | I21: =I19*Assumptions!B24 -> 0 | J21: =J19*Assumptions!B24 -> 0 | K21: =K19*Assumptions!B24 -> 0 | L21: =L19*Assumptions!B24 -> 0 | M21: =M19*Assumptions!B24 -> 0 | N21: =N19*Assumptions!B24 -> 0 | O21: =O19*Assumptions!B24 -> 0 | P21: =P19*Assumptions!B24 -> 0 | Q21: =Q19*Assumptions!B24 -> 0 | R21: =R19*Assumptions!B24 -> 0 | S21: =S19*Assumptions!B24 -> 0 | T21: =T19*Assumptions!B24 -> 0 | U21: =U19*Assumptions!B24 -> 0 | V21: =V19*Assumptions!B24 -> 0 | W21: =W19*Assumptions!B24 -> 0 | X21: =X19*Assumptions!B24 -> 0 | Y21: =Y19*Assumptions!B24 -> 0 | Z21: =SUM(B21:Y21) -> 0
A22: Smoothie Bar
A23: Units sold | B23: ='Growth Curves'!B6 -> 0 | C23: ='Growth Curves'!C6 -> 0 | D23: ='Growth Curves'!D6 -> 0 | E23: ='Growth Curves'!E6 -> 100 | F23: ='Growth Curves'!F6 -> 150 | G23: ='Growth Curves'!G6 -> 250 | H23: ='Growth Curves'!H6 -> 350 | I23: ='Growth Curves'!I6 -> 450 | ... Y23: ='Growth Curves'!Y6 -> 2000 | Z23: =SUM(B23:Y23) -> 22050
A24: Price/smoothie | B24: =Assumptions!B26 -> 9.67 | C24: =Assumptions!B26 -> 9.67 | D24: =Assumptions!B26 -> 9.67 | E24: =Assumptions!B26 -> 9.67 | F24: =Assumptions!B26 -> 9.67 | G24: =Assumptions!B26 -> 9.67 | H24: =Assumptions!B26 -> 9.67 | I24: =Assumptions!B26 -> 9.67 | J24: =Assumptions!B26 -> 9.67 | K24: =Assumptions!B26 -> 9.67 | L24: =Assumptions!B26 -> 9.67 | M24: =Assumptions!B26 -> 9.67 | N24: =Assumptions!B26 -> 9.67 | O24: =Assumptions!B26 -> 9.67 | P24: =Assumptions!B26 -> 9.67 | Q24: =Assumptions!B26 -> 9.67 | R24: =Assumptions!B26 -> 9.67 | S24: =Assumptions!B26 -> 9.67 | T24: =Assumptions!B26 -> 9.67 | U24: =Assumptions!B26 -> 9.67 | V24: =Assumptions!B26 -> 9.67 | W24: =Assumptions!B26 -> 9.67 | X24: =Assumptions!B26 -> 9.67 | Y24: =Assumptions!B26 -> 9.67 | Z24: =SUM(B24:Y24) -> 232.08
A25: Revenue | B25: =ROUND(B23*Assumptions!B26,0) -> 0 | C25: =ROUND(C23*Assumptions!B26,0) -> 0 | D25: =ROUND(D23*Assumptions!B26,0) -> 0 | E25: =ROUND(E23*Assumptions!B26,0) -> 967 | F25: =ROUND(F23*Assumptions!B26,0) -> 1451 | G25: =ROUND(G23*Assumptions!B26,0) -> 2418 | H25: =ROUND(H23*Assumptions!B26,0) -> 3385 | I25: =ROUND(I23*Assumptions!B26,0) -> 4352 | J25: =ROUND(J23*Assumptions!B26,0) -> 5319 | K25: =ROUND(K23*Assumptions!B26,0) -> 6286 | L25: =ROUND(L23*Assumptions!B26,0) -> 7253 | M25: =ROUND(M23*Assumptions!B26,0) -> 8220 | N25: =ROUND(N23*Assumptions!B26,0) -> 9187 | O25: =ROUND(O23*Assumptions!B26,0) -> 10154 | P25: =ROUND(P23*Assumptions!B26,0) -> 11121 | Q25: =ROUND(Q23*Assumptions!B26,0) -> 12088 | R25: =ROUND(R23*Assumptions!B26,0) -> 13055 | S25: =ROUND(S23*Assumptions!B26,0) -> 14022 | T25: =ROUND(T23*Assumptions!B26,0) -> 14989 | U25: =ROUND(U23*Assumptions!B26,0) -> 15956 | V25: =ROUND(V23*Assumptions!B26,0) -> 16923 | W25: =ROUND(W23*Assumptions!B26,0) -> 17890 | X25: =ROUND(X23*Assumptions!B26,0) -> 18857 | Y25: =ROUND(Y23*Assumptions!B26,0) -> 19340 | Z25: =SUM(B25:Y25) -> 213233
A26: Community Events
A27: Event count | B27: ='Growth Curves'!B7 -> 0 | C27: ='Growth Curves'!C7 -> 0 | D27: ='Growth Curves'!D7 -> 0 | E27: ='Growth Curves'!E7 -> 1 | F27: ='Growth Curves'!F7 -> 1 | G27: ='Growth Curves'!G7 -> 2 | H27: ='Growth Curves'!H7 -> 2 | I27: ='Growth Curves'!I7 -> 3 | ... Y27: ='Growth Curves'!Y7 -> 5 | Z27: =SUM(B27:Y27) -> 72
A28: Avg attendees/event | B28: ='Growth Curves'!B8 -> 0 | C28: ='Growth Curves'!C8 -> 0 | D28: ='Growth Curves'!D8 -> 0 | E28: ='Growth Curves'!E8 -> 12 | F28: ='Growth Curves'!F8 -> 15 | G28: ='Growth Curves'!G8 -> 15 | H28: ='Growth Curves'!H8 -> 18 | I28: ='Growth Curves'!I8 -> 18 | ... Y28: ='Growth Curves'!Y8 -> 25 | Z28: =SUM(B28:Y28) -> 442
A29: Total attendees | B29: =B27*B28 -> 0 | C29: =C27*C28 -> 0 | D29: =D27*D28 -> 0 | E29: =E27*E28 -> 12 | F29: =F27*F28 -> 15 | G29: =G27*G28 -> 30 | H29: =H27*H28 -> 36 | I29: =I27*I28 -> 54 | ... Y29: =Y27*Y28 -> 125 | Z29: =SUM(B29:Y29) -> 1606
A30: Price/ticket | B30: =Assumptions!B28 -> 35 | C30: =Assumptions!B28 -> 35 | D30: =Assumptions!B28 -> 35 | E30: =Assumptions!B28 -> 35 | F30: =Assumptions!B28 -> 35 | G30: =Assumptions!B28 -> 35 | H30: =Assumptions!B28 -> 35 | I30: =Assumptions!B28 -> 35 | J30: =Assumptions!B28 -> 35 | K30: =Assumptions!B28 -> 35 | L30: =Assumptions!B28 -> 35 | M30: =Assumptions!B28 -> 35 | N30: =Assumptions!B28 -> 35 | O30: =Assumptions!B28 -> 35 | P30: =Assumptions!B28 -> 35 | Q30: =Assumptions!B28 -> 35 | R30: =Assumptions!B28 -> 35 | S30: =Assumptions!B28 -> 35 | T30: =Assumptions!B28 -> 35 | U30: =Assumptions!B28 -> 35 | V30: =Assumptions!B28 -> 35 | W30: =Assumptions!B28 -> 35 | X30: =Assumptions!B28 -> 35 | Y30: =Assumptions!B28 -> 35 | Z30: =SUM(B30:Y30) -> 840
A31: Revenue | B31: =B29*Assumptions!B28 -> 0 | C31: =C29*Assumptions!B28 -> 0 | D31: =D29*Assumptions!B28 -> 0 | E31: =E29*Assumptions!B28 -> 420 | F31: =F29*Assumptions!B28 -> 525 | G31: =G29*Assumptions!B28 -> 1050 | H31: =H29*Assumptions!B28 -> 1260 | I31: =I29*Assumptions!B28 -> 1890 | J31: =J29*Assumptions!B28 -> 1890 | K31: =K29*Assumptions!B28 -> 2100 | L31: =L29*Assumptions!B28 -> 2100 | M31: =M29*Assumptions!B28 -> 2100 | N31: =N29*Assumptions!B28 -> 2310 | O31: =O29*Assumptions!B28 -> 2310 | P31: =P29*Assumptions!B28 -> 3080 | Q31: =Q29*Assumptions!B28 -> 3080 | R31: =R29*Assumptions!B28 -> 3360 | S31: =S29*Assumptions!B28 -> 3360 | T31: =T29*Assumptions!B28 -> 3500 | U31: =U29*Assumptions!B28 -> 4375 | V31: =V29*Assumptions!B28 -> 4375 | W31: =W29*Assumptions!B28 -> 4375 | X31: =X29*Assumptions!B28 -> 4375 | Y31: =Y29*Assumptions!B28 -> 4375 | Z31: =SUM(B31:Y31) -> 56210
A32: Doctor SaaS (D1: EUR 99/mo)
A33: Clinics listed | B33: ='Growth Curves'!B9 -> 0 | C33: ='Growth Curves'!C9 -> 0 | D33: ='Growth Curves'!D9 -> 0 | E33: ='Growth Curves'!E9 -> 0 | F33: ='Growth Curves'!F9 -> 0 | G33: ='Growth Curves'!G9 -> 2 | H33: ='Growth Curves'!H9 -> 5 | I33: ='Growth Curves'!I9 -> 8 | ... Y33: ='Growth Curves'!Y9 -> 20 | Z33: =SUM(B33:Y33) -> 306
A34: Fee/month | B34: =Assumptions!B31 -> 99 | C34: =Assumptions!B31 -> 99 | D34: =Assumptions!B31 -> 99 | E34: =Assumptions!B31 -> 99 | F34: =Assumptions!B31 -> 99 | G34: =Assumptions!B31 -> 99 | H34: =Assumptions!B31 -> 99 | I34: =Assumptions!B31 -> 99 | J34: =Assumptions!B31 -> 99 | K34: =Assumptions!B31 -> 99 | L34: =Assumptions!B31 -> 99 | M34: =Assumptions!B31 -> 99 | N34: =Assumptions!B31 -> 99 | O34: =Assumptions!B31 -> 99 | P34: =Assumptions!B31 -> 99 | Q34: =Assumptions!B31 -> 99 | R34: =Assumptions!B31 -> 99 | S34: =Assumptions!B31 -> 99 | T34: =Assumptions!B31 -> 99 | U34: =Assumptions!B31 -> 99 | V34: =Assumptions!B31 -> 99 | W34: =Assumptions!B31 -> 99 | X34: =Assumptions!B31 -> 99 | Y34: =Assumptions!B31 -> 99 | Z34: =SUM(B34:Y34) -> 2376
A35: Revenue | B35: =B33*Assumptions!B31 -> 0 | C35: =C33*Assumptions!B31 -> 0 | D35: =D33*Assumptions!B31 -> 0 | E35: =E33*Assumptions!B31 -> 0 | F35: =F33*Assumptions!B31 -> 0 | G35: =G33*Assumptions!B31 -> 198 | H35: =H33*Assumptions!B31 -> 495 | I35: =I33*Assumptions!B31 -> 792 | J35: =J33*Assumptions!B31 -> 990 | K35: =K33*Assumptions!B31 -> 1188 | L35: =L33*Assumptions!B31 -> 1485 | M35: =M33*Assumptions!B31 -> 1683 | N35: =N33*Assumptions!B31 -> 1782 | O35: =O33*Assumptions!B31 -> 1881 | P35: =P33*Assumptions!B31 -> 1980 | Q35: =Q33*Assumptions!B31 -> 1980 | R35: =R33*Assumptions!B31 -> 1980 | S35: =S33*Assumptions!B31 -> 1980 | T35: =T33*Assumptions!B31 -> 1980 | U35: =U33*Assumptions!B31 -> 1980 | V35: =V33*Assumptions!B31 -> 1980 | W35: =W33*Assumptions!B31 -> 1980 | X35: =X33*Assumptions!B31 -> 1980 | Y35: =Y33*Assumptions!B31 -> 1980 | Z35: =SUM(B35:Y35) -> 30294
A36: CGM Referral Commission (D3: EUR 15/user/mo — Premium 3-mo gate or add-on) | B36: 0 | C36: 0 | D36: 0 | E36: 0 | F36: 0 | G36: 0 | H36: 45 | I36: 90 | J36: 135 | K36: 180 | L36: 225 | M36: 270 | N36: 315 | O36: 360 | P36: 405 | Q36: 450 | R36: 480 | S36: 510 | T36: 540 | U36: 570 | V36: 585 | W36: 600 | X36: 615 | Y36: 630 | Z36: =SUM(B36:Y36) -> 7005
A37: Restaurant (D2: Phase 2 — EUR 0) | B37: 0 | C37: 0 | D37: 0 | E37: 0 | F37: 0 | G37: 0 | H37: 0 | I37: 0 | J37: 0 | K37: 0 | L37: 0 | M37: 0 | N37: 0 | O37: 0 | P37: 0 | Q37: 0 | R37: 0 | S37: 0 | T37: 0 | U37: 0 | V37: 0 | W37: 0 | X37: 0 | Y37: 0 | Z37: =SUM(B37:Y37) -> 0
A38: Subscriptions (EX-01: blended monthly + annual recognition)
A39: Core (blended: monthly EUR 19 / annual EUR 190/yr) | B39: =ROUND('Growth Curves'!B18*((1-IF(1<=6,Assumptions!B131,IF(1<=11,0.25,Assumptions!B132)))*Assumptions!B5+IF(1<=6,Assumptions!B131,IF(1<=11,0.25,Assumptions!B132))*Assumptions!B128/12),0) -> 0 | C39: =ROUND('Growth Curves'!C18*((1-IF(2<=6,Assumptions!B131,IF(2<=11,0.25,Assumptions!B132)))*Assumptions!B5+IF(2<=6,Assumptions!B131,IF(2<=11,0.25,Assumptions!B132))*Assumptions!B128/12),0) -> 0 | D39: =ROUND('Growth Curves'!D18*((1-IF(3<=6,Assumptions!B131,IF(3<=11,0.25,Assumptions!B132)))*Assumptions!B5+IF(3<=6,Assumptions!B131,IF(3<=11,0.25,Assumptions!B132))*Assumptions!B128/12),0) -> 0 | E39: =ROUND('Growth Curves'!E18*((1-IF(4<=6,Assumptions!B131,IF(4<=11,0.25,Assumptions!B132)))*Assumptions!B5+IF(4<=6,Assumptions!B131,IF(4<=11,0.25,Assumptions!B132))*Assumptions!B128/12),0) -> 147 | F39: =ROUND('Growth Curves'!F18*((1-IF(5<=6,Assumptions!B131,IF(5<=11,0.25,Assumptions!B132)))*Assumptions!B5+IF(5<=6,Assumptions!B131,IF(5<=11,0.25,Assumptions!B132))*Assumptions!B128/12),0) -> 276 | G39: =ROUND('Growth Curves'!G18*((1-IF(6<=6,Assumptions!B131,IF(6<=11,0.25,Assumptions!B132)))*Assumptions!B5+IF(6<=6,Assumptions!B131,IF(6<=11,0.25,Assumptions!B132))*Assumptions!B128/12),0) -> 404 | H39: =ROUND('Growth Curves'!H18*((1-IF(7<=6,Assumptions!B131,IF(7<=11,0.25,Assumptions!B132)))*Assumptions!B5+IF(7<=6,Assumptions!B131,IF(7<=11,0.25,Assumptions!B132))*Assumptions!B128/12),0) -> 583 | I39: =ROUND('Growth Curves'!I18*((1-IF(8<=6,Assumptions!B131,IF(8<=11,0.25,Assumptions!B132)))*Assumptions!B5+IF(8<=6,Assumptions!B131,IF(8<=11,0.25,Assumptions!B132))*Assumptions!B128/12),0) -> 747 | J39: =ROUND('Growth Curves'!J18*((1-IF(9<=6,Assumptions!B131,IF(9<=11,0.25,Assumptions!B132)))*Assumptions!B5+IF(9<=6,Assumptions!B131,IF(9<=11,0.25,Assumptions!B132))*Assumptions!B128/12),0) -> 892 | K39: =ROUND('Growth Curves'!K18*((1-IF(10<=6,Assumptions!B131,IF(10<=11,0.25,Assumptions!B132)))*Assumptions!B5+IF(10<=6,Assumptions!B131,IF(10<=11,0.25,Assumptions!B132))*Assumptions!B128/12),0) -> 1074 | L39: =ROUND('Growth Curves'!L18*((1-IF(11<=6,Assumptions!B131,IF(11<=11,0.25,Assumptions!B132)))*Assumptions!B5+IF(11<=6,Assumptions!B131,IF(11<=11,0.25,Assumptions!B132))*Assumptions!B128/12),0) -> 1256 | M39: =ROUND('Growth Curves'!M18*((1-IF(12<=6,Assumptions!B131,IF(12<=11,0.25,Assumptions!B132)))*Assumptions!B5+IF(12<=6,Assumptions!B131,IF(12<=11,0.25,Assumptions!B132))*Assumptions!B128/12),0) -> 1408 | N39: =ROUND('Growth Curves'!N18*((1-IF(13<=6,Assumptions!B131,IF(13<=11,0.25,Assumptions!B132)))*Assumptions!B5+IF(13<=6,Assumptions!B131,IF(13<=11,0.25,Assumptions!B132))*Assumptions!B128/12),0) -> 1588 | O39: =ROUND('Growth Curves'!O18*((1-IF(14<=6,Assumptions!B131,IF(14<=11,0.25,Assumptions!B132)))*Assumptions!B5+IF(14<=6,Assumptions!B131,IF(14<=11,0.25,Assumptions!B132))*Assumptions!B128/12),0) -> 1769 | P39: =ROUND('Growth Curves'!P18*((1-IF(15<=6,Assumptions!B131,IF(15<=11,0.25,Assumptions!B132)))*Assumptions!B5+IF(15<=6,Assumptions!B131,IF(15<=11,0.25,Assumptions!B132))*Assumptions!B128/12),0) -> 1931 | Q39: =ROUND('Growth Curves'!Q18*((1-IF(16<=6,Assumptions!B131,IF(16<=11,0.25,Assumptions!B132)))*Assumptions!B5+IF(16<=6,Assumptions!B131,IF(16<=11,0.25,Assumptions!B132))*Assumptions!B128/12),0) -> 2076 | R39: =ROUND('Growth Curves'!R18*((1-IF(17<=6,Assumptions!B131,IF(17<=11,0.25,Assumptions!B132)))*Assumptions!B5+IF(17<=6,Assumptions!B131,IF(17<=11,0.25,Assumptions!B132))*Assumptions!B128/12),0) -> 2202 | S39: =ROUND('Growth Curves'!S18*((1-IF(18<=6,Assumptions!B131,IF(18<=11,0.25,Assumptions!B132)))*Assumptions!B5+IF(18<=6,Assumptions!B131,IF(18<=11,0.25,Assumptions!B132))*Assumptions!B128/12),0) -> 2328 | T39: =ROUND('Growth Curves'!T18*((1-IF(19<=6,Assumptions!B131,IF(19<=11,0.25,Assumptions!B132)))*Assumptions!B5+IF(19<=6,Assumptions!B131,IF(19<=11,0.25,Assumptions!B132))*Assumptions!B128/12),0) -> 2491 | U39: =ROUND('Growth Curves'!U18*((1-IF(20<=6,Assumptions!B131,IF(20<=11,0.25,Assumptions!B132)))*Assumptions!B5+IF(20<=6,Assumptions!B131,IF(20<=11,0.25,Assumptions!B132))*Assumptions!B128/12),0) -> 2653 | V39: =ROUND('Growth Curves'!V18*((1-IF(21<=6,Assumptions!B131,IF(21<=11,0.25,Assumptions!B132)))*Assumptions!B5+IF(21<=6,Assumptions!B131,IF(21<=11,0.25,Assumptions!B132))*Assumptions!B128/12),0) -> 2798 | W39: =ROUND('Growth Curves'!W18*((1-IF(22<=6,Assumptions!B131,IF(22<=11,0.25,Assumptions!B132)))*Assumptions!B5+IF(22<=6,Assumptions!B131,IF(22<=11,0.25,Assumptions!B132))*Assumptions!B128/12),0) -> 2924 | X39: =ROUND('Growth Curves'!X18*((1-IF(23<=6,Assumptions!B131,IF(23<=11,0.25,Assumptions!B132)))*Assumptions!B5+IF(23<=6,Assumptions!B131,IF(23<=11,0.25,Assumptions!B132))*Assumptions!B128/12),0) -> 3050 | Y39: =ROUND('Growth Curves'!Y18*((1-IF(24<=6,Assumptions!B131,IF(24<=11,0.25,Assumptions!B132)))*Assumptions!B5+IF(24<=6,Assumptions!B131,IF(24<=11,0.25,Assumptions!B132))*Assumptions!B128/12),0) -> 3159 | Z39: =SUM(B39:Y39) -> 35756
A40: Pro (blended: monthly EUR 49 / annual EUR 490/yr) | B40: =ROUND('Growth Curves'!B19*((1-IF(1<=6,Assumptions!B131,IF(1<=11,0.25,Assumptions!B132)))*Assumptions!B6+IF(1<=6,Assumptions!B131,IF(1<=11,0.25,Assumptions!B132))*Assumptions!B129/12),0) -> 0 | C40: =ROUND('Growth Curves'!C19*((1-IF(2<=6,Assumptions!B131,IF(2<=11,0.25,Assumptions!B132)))*Assumptions!B6+IF(2<=6,Assumptions!B131,IF(2<=11,0.25,Assumptions!B132))*Assumptions!B129/12),0) -> 0 | D40: =ROUND('Growth Curves'!D19*((1-IF(3<=6,Assumptions!B131,IF(3<=11,0.25,Assumptions!B132)))*Assumptions!B6+IF(3<=6,Assumptions!B131,IF(3<=11,0.25,Assumptions!B132))*Assumptions!B129/12),0) -> 0 | E40: =ROUND('Growth Curves'!E19*((1-IF(4<=6,Assumptions!B131,IF(4<=11,0.25,Assumptions!B132)))*Assumptions!B6+IF(4<=6,Assumptions!B131,IF(4<=11,0.25,Assumptions!B132))*Assumptions!B129/12),0) -> 284 | F40: =ROUND('Growth Curves'!F19*((1-IF(5<=6,Assumptions!B131,IF(5<=11,0.25,Assumptions!B132)))*Assumptions!B6+IF(5<=6,Assumptions!B131,IF(5<=11,0.25,Assumptions!B132))*Assumptions!B129/12),0) -> 521 | G40: =ROUND('Growth Curves'!G19*((1-IF(6<=6,Assumptions!B131,IF(6<=11,0.25,Assumptions!B132)))*Assumptions!B6+IF(6<=6,Assumptions!B131,IF(6<=11,0.25,Assumptions!B132))*Assumptions!B129/12),0) -> 758 | H40: =ROUND('Growth Curves'!H19*((1-IF(7<=6,Assumptions!B131,IF(7<=11,0.25,Assumptions!B132)))*Assumptions!B6+IF(7<=6,Assumptions!B131,IF(7<=11,0.25,Assumptions!B132))*Assumptions!B129/12),0) -> 1080 | I40: =ROUND('Growth Curves'!I19*((1-IF(8<=6,Assumptions!B131,IF(8<=11,0.25,Assumptions!B132)))*Assumptions!B6+IF(8<=6,Assumptions!B131,IF(8<=11,0.25,Assumptions!B132))*Assumptions!B129/12),0) -> 1409 | J40: =ROUND('Growth Curves'!J19*((1-IF(9<=6,Assumptions!B131,IF(9<=11,0.25,Assumptions!B132)))*Assumptions!B6+IF(9<=6,Assumptions!B131,IF(9<=11,0.25,Assumptions!B132))*Assumptions!B129/12),0) -> 1691 | K40: =ROUND('Growth Curves'!K19*((1-IF(10<=6,Assumptions!B131,IF(10<=11,0.25,Assumptions!B132)))*Assumptions!B6+IF(10<=6,Assumptions!B131,IF(10<=11,0.25,Assumptions!B132))*Assumptions!B129/12),0) -> 2019 | L40: =ROUND('Growth Curves'!L19*((1-IF(11<=6,Assumptions!B131,IF(11<=11,0.25,Assumptions!B132)))*Assumptions!B6+IF(11<=6,Assumptions!B131,IF(11<=11,0.25,Assumptions!B132))*Assumptions!B129/12),0) -> 2395 | M40: =ROUND('Growth Curves'!M19*((1-IF(12<=6,Assumptions!B131,IF(12<=11,0.25,Assumptions!B132)))*Assumptions!B6+IF(12<=6,Assumptions!B131,IF(12<=11,0.25,Assumptions!B132))*Assumptions!B129/12),0) -> 2653 | N40: =ROUND('Growth Curves'!N19*((1-IF(13<=6,Assumptions!B131,IF(13<=11,0.25,Assumptions!B132)))*Assumptions!B6+IF(13<=6,Assumptions!B131,IF(13<=11,0.25,Assumptions!B132))*Assumptions!B129/12),0) -> 3026 | O40: =ROUND('Growth Curves'!O19*((1-IF(14<=6,Assumptions!B131,IF(14<=11,0.25,Assumptions!B132)))*Assumptions!B6+IF(14<=6,Assumptions!B131,IF(14<=11,0.25,Assumptions!B132))*Assumptions!B129/12),0) -> 3305 | P40: =ROUND('Growth Curves'!P19*((1-IF(15<=6,Assumptions!B131,IF(15<=11,0.25,Assumptions!B132)))*Assumptions!B6+IF(15<=6,Assumptions!B131,IF(15<=11,0.25,Assumptions!B132))*Assumptions!B129/12),0) -> 3631 | Q40: =ROUND('Growth Curves'!Q19*((1-IF(16<=6,Assumptions!B131,IF(16<=11,0.25,Assumptions!B132)))*Assumptions!B6+IF(16<=6,Assumptions!B131,IF(16<=11,0.25,Assumptions!B132))*Assumptions!B129/12),0) -> 3910 | R40: =ROUND('Growth Curves'!R19*((1-IF(17<=6,Assumptions!B131,IF(17<=11,0.25,Assumptions!B132)))*Assumptions!B6+IF(17<=6,Assumptions!B131,IF(17<=11,0.25,Assumptions!B132))*Assumptions!B129/12),0) -> 4143 | S40: =ROUND('Growth Curves'!S19*((1-IF(18<=6,Assumptions!B131,IF(18<=11,0.25,Assumptions!B132)))*Assumptions!B6+IF(18<=6,Assumptions!B131,IF(18<=11,0.25,Assumptions!B132))*Assumptions!B129/12),0) -> 4376 | T40: =ROUND('Growth Curves'!T19*((1-IF(19<=6,Assumptions!B131,IF(19<=11,0.25,Assumptions!B132)))*Assumptions!B6+IF(19<=6,Assumptions!B131,IF(19<=11,0.25,Assumptions!B132))*Assumptions!B129/12),0) -> 4702 | U40: =ROUND('Growth Curves'!U19*((1-IF(20<=6,Assumptions!B131,IF(20<=11,0.25,Assumptions!B132)))*Assumptions!B6+IF(20<=6,Assumptions!B131,IF(20<=11,0.25,Assumptions!B132))*Assumptions!B129/12),0) -> 5027 | V40: =ROUND('Growth Curves'!V19*((1-IF(21<=6,Assumptions!B131,IF(21<=11,0.25,Assumptions!B132)))*Assumptions!B6+IF(21<=6,Assumptions!B131,IF(21<=11,0.25,Assumptions!B132))*Assumptions!B129/12),0) -> 5260 | W40: =ROUND('Growth Curves'!W19*((1-IF(22<=6,Assumptions!B131,IF(22<=11,0.25,Assumptions!B132)))*Assumptions!B6+IF(22<=6,Assumptions!B131,IF(22<=11,0.25,Assumptions!B132))*Assumptions!B129/12),0) -> 5539 | X40: =ROUND('Growth Curves'!X19*((1-IF(23<=6,Assumptions!B131,IF(23<=11,0.25,Assumptions!B132)))*Assumptions!B6+IF(23<=6,Assumptions!B131,IF(23<=11,0.25,Assumptions!B132))*Assumptions!B129/12),0) -> 5772 | Y40: =ROUND('Growth Curves'!Y19*((1-IF(24<=6,Assumptions!B131,IF(24<=11,0.25,Assumptions!B132)))*Assumptions!B6+IF(24<=6,Assumptions!B131,IF(24<=11,0.25,Assumptions!B132))*Assumptions!B129/12),0) -> 5958 | Z40: =SUM(B40:Y40) -> 67459
A41: Premium (blended: monthly EUR 99 / annual EUR 990/yr) | B41: =ROUND('Growth Curves'!B20*((1-IF(1<=6,Assumptions!B131,IF(1<=11,0.25,Assumptions!B132)))*Assumptions!B7+IF(1<=6,Assumptions!B131,IF(1<=11,0.25,Assumptions!B132))*Assumptions!B130/12),0) -> 0 | C41: =ROUND('Growth Curves'!C20*((1-IF(2<=6,Assumptions!B131,IF(2<=11,0.25,Assumptions!B132)))*Assumptions!B7+IF(2<=6,Assumptions!B131,IF(2<=11,0.25,Assumptions!B132))*Assumptions!B130/12),0) -> 0 | D41: =ROUND('Growth Curves'!D20*((1-IF(3<=6,Assumptions!B131,IF(3<=11,0.25,Assumptions!B132)))*Assumptions!B7+IF(3<=6,Assumptions!B131,IF(3<=11,0.25,Assumptions!B132))*Assumptions!B130/12),0) -> 0 | E41: =ROUND('Growth Curves'!E20*((1-IF(4<=6,Assumptions!B131,IF(4<=11,0.25,Assumptions!B132)))*Assumptions!B7+IF(4<=6,Assumptions!B131,IF(4<=11,0.25,Assumptions!B132))*Assumptions!B130/12),0) -> 96 | F41: =ROUND('Growth Curves'!F20*((1-IF(5<=6,Assumptions!B131,IF(5<=11,0.25,Assumptions!B132)))*Assumptions!B7+IF(5<=6,Assumptions!B131,IF(5<=11,0.25,Assumptions!B132))*Assumptions!B130/12),0) -> 287 | G41: =ROUND('Growth Curves'!G20*((1-IF(6<=6,Assumptions!B131,IF(6<=11,0.25,Assumptions!B132)))*Assumptions!B7+IF(6<=6,Assumptions!B131,IF(6<=11,0.25,Assumptions!B132))*Assumptions!B130/12),0) -> 383 | H41: =ROUND('Growth Curves'!H20*((1-IF(7<=6,Assumptions!B131,IF(7<=11,0.25,Assumptions!B132)))*Assumptions!B7+IF(7<=6,Assumptions!B131,IF(7<=11,0.25,Assumptions!B132))*Assumptions!B130/12),0) -> 569 | I41: =ROUND('Growth Curves'!I20*((1-IF(8<=6,Assumptions!B131,IF(8<=11,0.25,Assumptions!B132)))*Assumptions!B7+IF(8<=6,Assumptions!B131,IF(8<=11,0.25,Assumptions!B132))*Assumptions!B130/12),0) -> 664 | J41: =ROUND('Growth Curves'!J20*((1-IF(9<=6,Assumptions!B131,IF(9<=11,0.25,Assumptions!B132)))*Assumptions!B7+IF(9<=6,Assumptions!B131,IF(9<=11,0.25,Assumptions!B132))*Assumptions!B130/12),0) -> 854 | K41: =ROUND('Growth Curves'!K20*((1-IF(10<=6,Assumptions!B131,IF(10<=11,0.25,Assumptions!B132)))*Assumptions!B7+IF(10<=6,Assumptions!B131,IF(10<=11,0.25,Assumptions!B132))*Assumptions!B130/12),0) -> 1139 | L41: =ROUND('Growth Curves'!L20*((1-IF(11<=6,Assumptions!B131,IF(11<=11,0.25,Assumptions!B132)))*Assumptions!B7+IF(11<=6,Assumptions!B131,IF(11<=11,0.25,Assumptions!B132))*Assumptions!B130/12),0) -> 1233 | M41: =ROUND('Growth Curves'!M20*((1-IF(12<=6,Assumptions!B131,IF(12<=11,0.25,Assumptions!B132)))*Assumptions!B7+IF(12<=6,Assumptions!B131,IF(12<=11,0.25,Assumptions!B132))*Assumptions!B130/12),0) -> 1411 | N41: =ROUND('Growth Curves'!N20*((1-IF(13<=6,Assumptions!B131,IF(13<=11,0.25,Assumptions!B132)))*Assumptions!B7+IF(13<=6,Assumptions!B131,IF(13<=11,0.25,Assumptions!B132))*Assumptions!B130/12),0) -> 1599 | O41: =ROUND('Growth Curves'!O20*((1-IF(14<=6,Assumptions!B131,IF(14<=11,0.25,Assumptions!B132)))*Assumptions!B7+IF(14<=6,Assumptions!B131,IF(14<=11,0.25,Assumptions!B132))*Assumptions!B130/12),0) -> 1787 | P41: =ROUND('Growth Curves'!P20*((1-IF(15<=6,Assumptions!B131,IF(15<=11,0.25,Assumptions!B132)))*Assumptions!B7+IF(15<=6,Assumptions!B131,IF(15<=11,0.25,Assumptions!B132))*Assumptions!B130/12),0) -> 1881 | Q41: =ROUND('Growth Curves'!Q20*((1-IF(16<=6,Assumptions!B131,IF(16<=11,0.25,Assumptions!B132)))*Assumptions!B7+IF(16<=6,Assumptions!B131,IF(16<=11,0.25,Assumptions!B132))*Assumptions!B130/12),0) -> 2069 | R41: =ROUND('Growth Curves'!R20*((1-IF(17<=6,Assumptions!B131,IF(17<=11,0.25,Assumptions!B132)))*Assumptions!B7+IF(17<=6,Assumptions!B131,IF(17<=11,0.25,Assumptions!B132))*Assumptions!B130/12),0) -> 2257 | S41: =ROUND('Growth Curves'!S20*((1-IF(18<=6,Assumptions!B131,IF(18<=11,0.25,Assumptions!B132)))*Assumptions!B7+IF(18<=6,Assumptions!B131,IF(18<=11,0.25,Assumptions!B132))*Assumptions!B130/12),0) -> 2351 | T41: =ROUND('Growth Curves'!T20*((1-IF(19<=6,Assumptions!B131,IF(19<=11,0.25,Assumptions!B132)))*Assumptions!B7+IF(19<=6,Assumptions!B131,IF(19<=11,0.25,Assumptions!B132))*Assumptions!B130/12),0) -> 2539 | U41: =ROUND('Growth Curves'!U20*((1-IF(20<=6,Assumptions!B131,IF(20<=11,0.25,Assumptions!B132)))*Assumptions!B7+IF(20<=6,Assumptions!B131,IF(20<=11,0.25,Assumptions!B132))*Assumptions!B130/12),0) -> 2633 | V41: =ROUND('Growth Curves'!V20*((1-IF(21<=6,Assumptions!B131,IF(21<=11,0.25,Assumptions!B132)))*Assumptions!B7+IF(21<=6,Assumptions!B131,IF(21<=11,0.25,Assumptions!B132))*Assumptions!B130/12),0) -> 2822 | W41: =ROUND('Growth Curves'!W20*((1-IF(22<=6,Assumptions!B131,IF(22<=11,0.25,Assumptions!B132)))*Assumptions!B7+IF(22<=6,Assumptions!B131,IF(22<=11,0.25,Assumptions!B132))*Assumptions!B130/12),0) -> 2916 | X41: =ROUND('Growth Curves'!X20*((1-IF(23<=6,Assumptions!B131,IF(23<=11,0.25,Assumptions!B132)))*Assumptions!B7+IF(23<=6,Assumptions!B131,IF(23<=11,0.25,Assumptions!B132))*Assumptions!B130/12),0) -> 3010 | Y41: =ROUND('Growth Curves'!Y20*((1-IF(24<=6,Assumptions!B131,IF(24<=11,0.25,Assumptions!B132)))*Assumptions!B7+IF(24<=6,Assumptions!B131,IF(24<=11,0.25,Assumptions!B132))*Assumptions!B130/12),0) -> 3198 | Z41: =SUM(B41:Y41) -> 35698
...

Sheet Assumptions
A1: alche — P&L Assumptions v4
A2: Change any value here → P&L auto-recalculates. All persona findings incorporated.
A4: SUBSCRIPTION MODEL
A5: Core tier price (EUR/mo) | B5: 19 | C5: Entry tier
A6: Pro tier price (EUR/mo) | B6: 49 | C6: Sweet spot
A7: Premium tier price (EUR/mo) | B7: 99 | C7: Highest ARPU
A8: Monthly churn rate | B8: 0.08 | C8: 8% — locked data
A9: Core tier share | B9: 0.52 | C9: 52%
A10: Pro tier share | B10: 0.38 | C10: 38%
A11: Premium tier share | B11: 0.1 | C11: 10%
A13: SUBSCRIBER GROWTH (new subs/month)
A14: M1-M3 | B14: 0 | C14: Pre-launch — no app yet
A15: M4-M6 | B15: 15 | C15: Product launch
A16: M7-M9 | B16: 22 | C16: Growth acceleration
A17: M10-M12 | B17: 28 | C17: Marketing ramp
A18: M13-M18 | B18: 32 | C18: Scaling
A19: M19-M24 | B19: 38 | C19: Scaling phase
A21: PRODUCT PRICING
A22: Retail product price (EUR) | B22: 49 | C22: R10 validated
A23: Retail product COGS (EUR/unit) | B23: 23.5 | C23: R10: wholesale ~48% of retail
A24: LED session price (EUR) | B24: 0 | C24: Free with smoothie purchase
A25: LED practitioner cost (EUR) | B25: 0 | C25: Self-service — no practitioner
A26: Smoothie avg price (EUR) | B26: 9.67 | C26: R2 Cost Analysis
A27: Smoothie COGS rate | B27: 0.35 | C27: 35% ingredients+packaging (R2)
A28: Event ticket price (EUR) | B28: 35 | C28: Community events
A29: Event fixed cost (EUR) | B29: 250 | C29: Venue per event
A30: Ticketing platform fee | B30: 0.07 | C30: 7% Luma/Eventbrite
A31: Doctor SaaS fee (EUR/mo) | B31: 99 | C31: D1: StGB 299a safe
A32: Doctor verify cost (EUR) | B32: 25 | C32: Per new doctor
A33: Doctor max clinics | B33: 20 | C33: Cap M1-24
A35: COST RATES
A36: Waste — blended rate | B36: 0.055 | C36: D7: capsules 4%, powders 7%
A37: 3PL fulfillment (EUR/unit) | B37: 2.5 | C37: Retail products only
A38: Stripe fee rate | B38: 0.029 | C38: 2.9%
A39: AI API per user (EUR/mo) | B39: 0.35 | C39: D6: hybrid Claude+Gemini
A40: Refund/returns reserve | B40: 0.015 | C40: 1.5% of product revenue
A41: Bad debt provision | B41: 0.005 | C41: P5: 0.5% of total revenue
A43: PAYROLL
A44: Founder gross salary (each) | B44: 4166 | C44: EUR 50K/yr (P7: viable)
A45: Employer multiplier | B45: 1.25 | C45: P2/P7: incl. U1/U2/U3 (was 1.22)
...

Sheet Growth Curves
A1: alche — Monthly Growth Curves (Input Data)
A2: Edit numbers to change unit forecasts. P&L formulas reference these cells.
A3: Metric | B3: M1 | C3: M2 | D3: M3 | E3: M4 | F3: M5 | G3: M6 | H3: M7 | I3: M8 | J3: M9 | K3: M10 | L3: M11 | M3: M12 | N3: M13 | O3: M14 | P3: M15 | Q3: M16 | R3: M17 | S3: M18 | T3: M19 | U3: M20 | V3: M21 | W3: M22 | X3: M23 | Y3: M24
A4: Retail Units | B4: 0 | C4: 0 | D4: 0 | E4: 50 | F4: 100 | G4: 150 | H4: 250 | I4: 350 | J4: 450 | K4: 600 | L4: 750 | M4: 900 | N4: 1100 | O4: 1300 | P4: 1500 | Q4: 1800 | R4: 2100 | S4: 2400 | T4: 2700 | U4: 3000 | V4: 3400 | W4: 3800 | X4: 4200 | Y4: 4600
A5: LED Sessions | B5: 0 | C5: 0 | D5: 0 | E5: 10 | F5: 20 | G5: 35 | H5: 50 | I5: 65 | J5: 80 | K5: 100 | L5: 120 | M5: 140 | N5: 160 | O5: 180 | P5: 200 | Q5: 220 | R5: 240 | S5: 260 | T5: 280 | U5: 300 | V5: 300 | W5: 300 | X5: 300 | Y5: 300
A6: Smoothie Units | B6: 0 | C6: 0 | D6: 0 | E6: 100 | F6: 150 | G6: 250 | H6: 350 | I6: 450 | J6: 550 | K6: 650 | L6: 750 | M6: 850 | N6: 950 | O6: 1050 | P6: 1150 | Q6: 1250 | R6: 1350 | S6: 1450 | T6: 1550 | U6: 1650 | V6: 1750 | W6: 1850 | X6: 1950 | Y6: 2000
A7: Event Count | B7: 0 | C7: 0 | D7: 0 | E7: 1 | F7: 1 | G7: 2 | H7: 2 | I7: 3 | J7: 3 | K7: 3 | L7: 3 | M7: 3 | N7: 3 | O7: 3 | P7: 4 | Q7: 4 | R7: 4 | S7: 4 | T7: 4 | U7: 5 | V7: 5 | W7: 5 | X7: 5 | Y7: 5
A8: Event Avg Attendees | B8: 0 | C8: 0 | D8: 0 | E8: 12 | F8: 15 | G8: 15 | H8: 18 | I8: 18 | J8: 18 | K8: 20 | L8: 20 | M8: 20 | N8: 22 | O8: 22 | P8: 22 | Q8: 22 | R8: 24 | S8: 24 | T8: 25 | U8: 25 | V8: 25 | W8: 25 | X8: 25 | Y8: 25
A9: Doctor Clinics | B9: 0 | C9: 0 | D9: 0 | E9: 0 | F9: 0 | G9: 2 | H9: 5 | I9: 8 | J9: 10 | K9: 12 | L9: 15 | M9: 17 | N9: 18 | O9: 19 | P9: 20 | Q9: 20 | R9: 20 | S9: 20 | T9: 20 | U9: 20 | V9: 20 | W9: 20 | X9: 20 | Y9: 20
A10: Marketing Spend (EUR) | B10: 50 | C10: 50 | D10: 100 | E10: 200 | F10: 400 | G10: 600 | H10: 800 | I10: 800 | J10: 1000 | K10: 1200 | L10: 1400 | M10: 1400 | N10: 1800 | O10: 1800 | P10: 2000 | Q10: 2000 | R10: 2200 | S10: 2200 | T10: 2500 | U10: 2500 | V10: 2800 | W10: 2800 | X10: 3000 | Y10: 3000
A11: KSK-Eligible Freelancer Spend | B11: 500 | C11: 500 | D11: 500 | E11: 500 | F11: 800 | G11: 800 | H11: 800 | I11: 800 | J11: 800 | K11: 800 | L11: 800 | M11: 800 | N11: 800 | O11: 800 | P11: 800 | Q11: 800 | R11: 800 | S11: 800 | T11: 800 | U11: 800 | V11: 800 | W11: 800 | X11: 800 | Y11: 800
A12: New Doctors (delta) | B12: 0 | C12: =MAX(0,C9-B9) -> 0 | D12: =MAX(0,D9-C9) -> 0 | E12: =MAX(0,E9-D9) -> 0 | F12: =MAX(0,F9-E9) -> 0 | G12: =MAX(0,G9-F9) -> 2 | H12: =MAX(0,H9-G9) -> 3 | I12: =MAX(0,I9-H9) -> 3 | J12: =MAX(0,J9-I9) -> 2 | ... Y12: =MAX(0,Y9-X9) -> 0
A14: SUBSCRIBER MODEL
A15: New Subs Rate | B15: =IF(1<=3,Assumptions!B14,IF(1<=6,Assumptions!B15,IF(1<=9,Assumptions!B16,IF(1<=12,Assumptions!B17,IF(1<=18,Assumptions!B18,Assumptions!B19))))) -> 0 | C15: =IF(2<=3,Assumptions!B14,IF(2<=6,Assumptions!B15,IF(2<=9,Assumptions!B16,IF(2<=12,Assumptions!B17,IF(2<=18,Assumptions!B18,Assumptions!B19))))) -> 0 | D15: =IF(3<=3,Assumptions!B14,IF(3<=6,Assumptions!B15,IF(3<=9,Assumptions!B16,IF(3<=12,Assumptions!B17,IF(3<=18,Assumptions!B18,Assumptions!B19))))) -> 0 | E15: =IF(4<=3,Assumptions!B14,IF(4<=6,Assumptions!B15,IF(4<=9,Assumptions!B16,IF(4<=12,Assumptions!B17,IF(4<=18,Assumptions!B18,Assumptions!B19))))) -> 15 | F15: =IF(5<=3,Assumptions!B14,IF(5<=6,Assumptions!B15,IF(5<=9,Assumptions!B16,IF(5<=12,Assumptions!B17,IF(5<=18,Assumptions!B18,Assumptions!B19))))) -> 15 | G15: =IF(6<=3,Assumptions!B14,IF(6<=6,Assumptions!B15,IF(6<=9,Assumptions!B16,IF(6<=12,Assumptions!B17,IF(6<=18,Assumptions!B18,Assumptions!B19))))) -> 15 | H15: =IF(7<=3,Assumptions!B14,IF(7<=6,Assumptions!B15,IF(7<=9,Assumptions!B16,IF(7<=12,Assumptions!B17,IF(7<=18,Assumptions!B18,Assumptions!B19))))) -> 22 | I15: =IF(8<=3,Assumptions!B14,IF(8<=6,Assumptions!B15,IF(8<=9,Assumptions!B16,IF(8<=12,Assumptions!B17,IF(8<=18,Assumptions!B18,Assumptions!B19))))) -> 22 | J15: =IF(9<=3,Assumptions!B14,IF(9<=6,Assumptions!B15,IF(9<=9,Assumptions!B16,IF(9<=12,Assumptions!B17,IF(9<=18,Assumptions!B18,Assumptions!B19))))) -> 22 | K15: =IF(10<=3,Assumptions!B14,IF(10<=6,Assumptions!B15,IF(10<=9,Assumptions!B16,IF(10<=12,Assumptions!B17,IF(10<=18,Assumptions!B18,Assumptions!B19))))) -> 28 | L15: =IF(11<=3,Assumptions!B14,IF(11<=6,Assumptions!B15,IF(11<=9,Assumptions!B16,IF(11<=12,Assumptions!B17,IF(11<=18,Assumptions!B18,Assumptions!B19))))) -> 28 | M15: =IF(12<=3,Assumptions!B14,IF(12<=6,Assumptions!B15,IF(12<=9,Assumptions!B16,IF(12<=12,Assumptions!B17,IF(12<=18,Assumptions!B18,Assumptions!B19))))) -> 28 | N15: =IF(13<=3,Assumptions!B14,IF(13<=6,Assumptions!B15,IF(13<=9,Assumptions!B16,IF(13<=12,Assumptions!B17,IF(13<=18,Assumptions!B18,Assumptions!B19))))) -> 32 | O15: =IF(14<=3,Assumptions!B14,IF(14<=6,Assumptions!B15,IF(14<=9,Assumptions!B16,IF(14<=12,Assumptions!B17,IF(14<=18,Assumptions!B18,Assumptions!B19))))) -> 32 | P15: =IF(15<=3,Assumptions!B14,IF(15<=6,Assumptions!B15,IF(15<=9,Assumptions!B16,IF(15<=12,Assumptions!B17,IF(15<=18,Assumptions!B18,Assumptions!B19))))) -> 32 | Q15: =IF(16<=3,Assumptions!B14,IF(16<=6,Assumptions!B15,IF(16<=9,Assumptions!B16,IF(16<=12,Assumptions!B17,IF(16<=18,Assumptions!B18,Assumptions!B19))))) -> 32 | R15: =IF(17<=3,Assumptions!B14,IF(17<=6,Assumptions!B15,IF(17<=9,Assumptions!B16,IF(17<=12,Assumptions!B17,IF(17<=18,Assumptions!B18,Assumptions!B19))))) -> 32 | S15: =IF(18<=3,Assumptions!B14,IF(18<=6,Assumptions!B15,IF(18<=9,Assumptions!B16,IF(18<=12,Assumptions!B17,IF(18<=18,Assumptions!B18,Assumptions!B19))))) -> 32 | T15: =IF(19<=3,Assumptions!B14,IF(19<=6,Assumptions!B15,IF(19<=9,Assumptions!B16,IF(19<=12,Assumptions!B17,IF(19<=18,Assumptions!B18,Assumptions!B19))))) -> 38 | U15: =IF(20<=3,Assumptions!B14,IF(20<=6,Assumptions!B15,IF(20<=9,Assumptions!B16,IF(20<=12,Assumptions!B17,IF(20<=18,Assumptions!B18,Assumptions!B19))))) -> 38 | V15: =IF(21<=3,Assumptions!B14,IF(21<=6,Assumptions!B15,IF(21<=9,Assumptions!B16,IF(21<=12,Assumptions!B17,IF(21<=18,Assumptions!B18,Assumptions!B19))))) -> 38 | W15: =IF(22<=3,Assumptions!B14,IF(22<=6,Assumptions!B15,IF(22<=9,Assumptions!B16,IF(22<=12,Assumptions!B17,IF(22<=18,Assumptions!B18,Assumptions!B19))))) -> 38 | X15: =IF(23<=3,Assumptions!B14,IF(23<=6,Assumptions!B15,IF(23<=9,Assumptions!B16,IF(23<=12,Assumptions!B17,IF(23<=18,Assumptions!B18,Assumptions!B19))))) -> 38 | Y15: =IF(24<=3,Assumptions!B14,IF(24<=6,Assumptions!B15,IF(24<=9,Assumptions!B16,IF(24<=12,Assumptions!B17,IF(24<=18,Assumptions!B18,Assumptions!B19))))) -> 38
A16: Churned Subs | B16: 0 | C16: =ROUND(B17*Assumptions!B8,0) -> 0 | D16: =ROUND(C17*Assumptions!B8,0) -> 0 | E16: =ROUND(D17*Assumptions!B8,0) -> 0 | F16: =ROUND(E17*Assumptions!B8,0) -> 1 | G16: =ROUND(F17*Assumptions!B8,0) -> 2 | H16: =ROUND(G17*Assumptions!B8,0) -> 3 | I16: =ROUND(H17*Assumptions!B8,0) -> 5 | J16: =ROUND(I17*Assumptions!B8,0) -> 6 | K16: =ROUND(J17*Assumptions!B8,0) -> 8 | L16: =ROUND(K17*Assumptions!B8,0) -> 9 | M16: =ROUND(L17*Assumptions!B8,0) -> 11 | N16: =ROUND(M17*Assumptions!B8,0) -> 12 | O16: =ROUND(N17*Assumptions!B8,0) -> 14 | P16: =ROUND(O17*Assumptions!B8,0) -> 15 | Q16: =ROUND(P17*Assumptions!B8,0) -> 16 | R16: =ROUND(Q17*Assumptions!B8,0) -> 18 | S16: =ROUND(R17*Assumptions!B8,0) -> 19 | T16: =ROUND(S17*Assumptions!B8,0) -> 20 | U16: =ROUND(T17*Assumptions!B8,0) -> 21 | V16: =ROUND(U17*Assumptions!B8,0) -> 23 | W16: =ROUND(V17*Assumptions!B8,0) -> 24 | X16: =ROUND(W17*Assumptions!B8,0) -> 25 | Y16: =ROUND(X17*Assumptions!B8,0) -> 26
A17: Total Subscribers | B17: =MAX(0,B15-B16) -> 0 | C17: =MAX(0,B17-C16+C15) -> 0 | D17: =MAX(0,C17-D16+D15) -> 0 | E17: =MAX(0,D17-E16+E15) -> 15 | F17: =MAX(0,E17-F16+F15) -> 29 | G17: =MAX(0,F17-G16+G15) -> 42 | H17: =MAX(0,G17-H16+H15) -> 61 | I17: =MAX(0,H17-I16+I15) -> 78 | J17: =MAX(0,I17-J16+J15) -> 94 | ... Y17: =MAX(0,X17-Y16+Y15) -> 337
A18: Core Subs (52%) | B18: =ROUND(B17*Assumptions!B9,0) -> 0 | C18: =ROUND(C17*Assumptions!B9,0) -> 0 | D18: =ROUND(D17*Assumptions!B9,0) -> 0 | E18: =ROUND(E17*Assumptions!B9,0) -> 8 | F18: =ROUND(F17*Assumptions!B9,0) -> 15 | G18: =ROUND(G17*Assumptions!B9,0) -> 22 | H18: =ROUND(H17*Assumptions!B9,0) -> 32 | I18: =ROUND(I17*Assumptions!B9,0) -> 41 | J18: =ROUND(J17*Assumptions!B9,0) -> 49 | K18: =ROUND(K17*Assumptions!B9,0) -> 59 | L18: =ROUND(L17*Assumptions!B9,0) -> 69 | M18: =ROUND(M17*Assumptions!B9,0) -> 78 | N18: =ROUND(N17*Assumptions!B9,0) -> 88 | O18: =ROUND(O17*Assumptions!B9,0) -> 98 | P18: =ROUND(P17*Assumptions!B9,0) -> 107 | Q18: =ROUND(Q17*Assumptions!B9,0) -> 115 | R18: =ROUND(R17*Assumptions!B9,0) -> 122 | S18: =ROUND(S17*Assumptions!B9,0) -> 129 | T18: =ROUND(T17*Assumptions!B9,0) -> 138 | U18: =ROUND(U17*Assumptions!B9,0) -> 147 | V18: =ROUND(V17*Assumptions!B9,0) -> 155 | W18: =ROUND(W17*Assumptions!B9,0) -> 162 | X18: =ROUND(X17*Assumptions!B9,0) -> 169 | Y18: =ROUND(Y17*Assumptions!B9,0) -> 175
A19: Pro Subs (38%) | B19: =ROUND(B17*Assumptions!B10,0) -> 0 | C19: =ROUND(C17*Assumptions!B10,0) -> 0 | D19: =ROUND(D17*Assumptions!B10,0) -> 0 | E19: =ROUND(E17*Assumptions!B10,0) -> 6 | F19: =ROUND(F17*Assumptions!B10,0) -> 11 | G19: =ROUND(G17*Assumptions!B10,0) -> 16 | H19: =ROUND(H17*Assumptions!B10,0) -> 23 | I19: =ROUND(I17*Assumptions!B10,0) -> 30 | J19: =ROUND(J17*Assumptions!B10,0) -> 36 | K19: =ROUND(K17*Assumptions!B10,0) -> 43 | L19: =ROUND(L17*Assumptions!B10,0) -> 51 | M19: =ROUND(M17*Assumptions!B10,0) -> 57 | N19: =ROUND(N17*Assumptions!B10,0) -> 65 | O19: =ROUND(O17*Assumptions!B10,0) -> 71 | P19: =ROUND(P17*Assumptions!B10,0) -> 78 | Q19: =ROUND(Q17*Assumptions!B10,0) -> 84 | R19: =ROUND(R17*Assumptions!B10,0) -> 89 | S19: =ROUND(S17*Assumptions!B10,0) -> 94 | T19: =ROUND(T17*Assumptions!B10,0) -> 101 | U19: =ROUND(U17*Assumptions!B10,0) -> 108 | V19: =ROUND(V17*Assumptions!B10,0) -> 113 | W19: =ROUND(W17*Assumptions!B10,0) -> 119 | X19: =ROUND(X17*Assumptions!B10,0) -> 124 | Y19: =ROUND(Y17*Assumptions!B10,0) -> 128
A20: Premium Subs (10%) | B20: =MAX(0,B17-B18-B19) -> 0 | C20: =MAX(0,C17-C18-C19) -> 0 | D20: =MAX(0,D17-D18-D19) -> 0 | E20: =MAX(0,E17-E18-E19) -> 1 | F20: =MAX(0,F17-F18-F19) -> 3 | G20: =MAX(0,G17-G18-G19) -> 4 | H20: =MAX(0,H17-H18-H19) -> 6 | I20: =MAX(0,I17-I18-I19) -> 7 | ... Y20: =MAX(0,Y17-Y18-Y19) -> 34

Sheet Cash Flow
A1: alche — Cash Flow Statement v3
A2: P5: EUR ~218K gap between P&L profit and actual cash. This sheet closes that gap.
A3: Cash Flow (EUR) | B3: M1 | C3: M2 | D3: M3 | E3: M4 | F3: M5 | G3: M6 | H3: M7 | I3: M8 | J3: M9 | K3: M10 | L3: M11 | M3: M12 | N3: M13 | O3: M14 | P3: M15 | Q3: M16 | R3: M17 | S3: M18 | T3: M19 | U3: M20 | V3: M21 | W3: M22 | X3: M23 | Y3: M24 | Z3: TOTAL
A4: OPERATING ACTIVITIES
A5: EBITDA | B5: ='P&L'!B136 -> -14979 | C5: ='P&L'!C136 -> -14979 | D5: ='P&L'!D136 -> -15584 | E5: ='P&L'!E136 -> -16715 | F5: ='P&L'!F136 -> -15471 | G5: ='P&L'!G136 -> -16182 | H5: ='P&L'!H136 -> -13391 | I5: ='P&L'!I136 -> -9822 | ... Y5: ='P&L'!Y136 -> 77810 | Z5: =SUM(B5:Y5) -> 369304
A6: - Tax Provision | B6: =-'P&L'!B169 -> 0 | C6: =-'P&L'!C169 -> 0 | D6: =-'P&L'!D169 -> 0 | E6: =-'P&L'!E169 -> 0 | F6: =-'P&L'!F169 -> 0 | G6: =-'P&L'!G169 -> 0 | H6: =-'P&L'!H169 -> 0 | I6: =-'P&L'!I169 -> 0 | ... Y6: =-'P&L'!Y169 -> -23343 | Z6: =SUM(B6:Y6) -> -62881
A7: - Working Capital Build (inventory) | B7: =-ROUND('Growth Curves'!B4*Assumptions!B23*2,0) -> 0 | C7: =-ROUND(MAX(0,('Growth Curves'!C4-'Growth Curves'!B4)*Assumptions!B23*2),0) -> 0 | D7: =-ROUND(MAX(0,('Growth Curves'!D4-'Growth Curves'!C4)*Assumptions!B23*2),0) -> 0 | E7: =-ROUND(MAX(0,('Growth Curves'!E4-'Growth Curves'!D4)*Assumptions!B23*2),0) -> -2350 | F7: =-ROUND(MAX(0,('Growth Curves'!F4-'Growth Curves'!E4)*Assumptions!B23*2),0) -> -2350 | G7: =-ROUND(MAX(0,('Growth Curves'!G4-'Growth Curves'!F4)*Assumptions!B23*2),0) -> -2350 | H7: =-ROUND(MAX(0,('Growth Curves'!H4-'Growth Curves'!G4)*Assumptions!B23*2),0) -> -4700 | I7: =-ROUND(MAX(0,('Growth Curves'!I4-'Growth Curves'!H4)*Assumptions!B23*2),0) -> -4700 | J7: =-ROUND(MAX(0,('Growth Curves'!J4-'Growth Curves'!I4)*Assumptions!B23*2),0) -> -4700 | K7: =-ROUND(MAX(0,('Growth Curves'!K4-'Growth Curves'!J4)*Assumptions!B23*2),0) -> -7050 | L7: =-ROUND(MAX(0,('Growth Curves'!L4-'Growth Curves'!K4)*Assumptions!B23*2),0) -> -7050 | M7: =-ROUND(MAX(0,('Growth Curves'!M4-'Growth Curves'!L4)*Assumptions!B23*2),0) -> -7050 | N7: =-ROUND(MAX(0,('Growth Curves'!N4-'Growth Curves'!M4)*Assumptions!B23*2),0) -> -9400 | O7: =-ROUND(MAX(0,('Growth Curves'!O4-'Growth Curves'!N4)*Assumptions!B23*2),0) -> -9400 | P7: =-ROUND(MAX(0,('Growth Curves'!P4-'Growth Curves'!O4)*Assumptions!B23*2),0) -> -9400 | Q7: =-ROUND(MAX(0,('Growth Curves'!Q4-'Growth Curves'!P4)*Assumptions!B23*2),0) -> -14100 | R7: =-ROUND(MAX(0,('Growth Curves'!R4-'Growth Curves'!Q4)*Assumptions!B23*2),0) -> -14100 | S7: =-ROUND(MAX(0,('Growth Curves'!S4-'Growth Curves'!R4)*Assumptions!B23*2),0) -> -14100 | T7: =-ROUND(MAX(0,('Growth Curves'!T4-'Growth Curves'!S4)*Assumptions!B23*2),0) -> -14100 | U7: =-ROUND(MAX(0,('Growth Curves'!U4-'Growth Curves'!T4)*Assumptions!B23*2),0) -> -14100 | V7: =-ROUND(MAX(0,('Growth Curves'!V4-'Growth Curves'!U4)*Assumptions!B23*2),0) -> -18800 | W7: =-ROUND(MAX(0,('Growth Curves'!W4-'Growth Curves'!V4)*Assumptions!B23*2),0) -> -18800 | X7: =-ROUND(MAX(0,('Growth Curves'!X4-'Growth Curves'!W4)*Assumptions!B23*2),0) -> -18800 | Y7: =-ROUND(MAX(0,('Growth Curves'!Y4-'Growth Curves'!X4)*Assumptions!B23*2),0) -> -18800 | Z7: =SUM(B7:Y7) -> -216200
A8: Operating Cash Flow | B8: =B5+B6+B7 -> -14979 | C8: =C5+C6+C7 -> -14979 | D8: =D5+D6+D7 -> -15584 | E8: =E5+E6+E7 -> -19065 | F8: =F5+F6+F7 -> -17821 | G8: =G5+G6+G7 -> -18532 | H8: =H5+H6+H7 -> -18091 | I8: =I5+I6+I7 -> -14522 | ... Y8: =Y5+Y6+Y7 -> 35667 | Z8: =SUM(B8:Y8) -> 90223
A10: INVESTING ACTIVITIES
A11: CapEx | B11: =-'P&L'!B163 -> -46200 | C11: =-'P&L'!C163 -> 0 | D11: =-'P&L'!D163 -> -103610 | E11: =-'P&L'!E163 -> 0 | F11: =-'P&L'!F163 -> 0 | G11: =-'P&L'!G163 -> 0 | H11: =-'P&L'!H163 -> 0 | I11: =-'P&L'!I163 -> 0 | ... Y11: =-'P&L'!Y163 -> 0 | Z11: =SUM(B11:Y11) -> -168810
A12: Kaution — Security Deposit (M3) | B12: =IF(1=3,-Assumptions!B118,0) -> 0 | C12: =IF(2=3,-Assumptions!B118,0) -> 0 | D12: =IF(3=3,-Assumptions!B118,0) -> -7500 | E12: =IF(4=3,-Assumptions!B118,0) -> 0 | F12: =IF(5=3,-Assumptions!B118,0) -> 0 | G12: =IF(6=3,-Assumptions!B118,0) -> 0 | H12: =IF(7=3,-Assumptions!B118,0) -> 0 | I12: =IF(8=3,-Assumptions!B118,0) -> 0 | J12: =IF(9=3,-Assumptions!B118,0) -> 0 | K12: =IF(10=3,-Assumptions!B118,0) -> 0 | L12: =IF(11=3,-Assumptions!B118,0) -> 0 | M12: =IF(12=3,-Assumptions!B118,0) -> 0 | N12: =IF(13=3,-Assumptions!B118,0) -> 0 | O12: =IF(14=3,-Assumptions!B118,0) -> 0 | P12: =IF(15=3,-Assumptions!B118,0) -> 0 | Q12: =IF(16=3,-Assumptions!B118,0) -> 0 | R12: =IF(17=3,-Assumptions!B118,0) -> 0 | S12: =IF(18=3,-Assumptions!B118,0) -> 0 | T12: =IF(19=3,-Assumptions!B118,0) -> 0 | U12: =IF(20=3,-Assumptions!B118,0) -> 0 | V12: =IF(21=3,-Assumptions!B118,0) -> 0 | W12: =IF(22=3,-Assumptions!B118,0) -> 0 | X12: =IF(23=3,-Assumptions!B118,0) -> 0 | Y12: =IF(24=3,-Assumptions!B118,0) -> 0 | Z12: =SUM(B12:Y12) -> -7500
A13: Space Security Deposit M3 (EX-07: balance sheet, refundable) | B13: =IF(1=3,-Assumptions!B140,0) -> 0 | C13: =IF(2=3,-Assumptions!B140,0) -> 0 | D13: =IF(3=3,-Assumptions!B140,0) -> -3600 | E13: =IF(4=3,-Assumptions!B140,0) -> 0 | F13: =IF(5=3,-Assumptions!B140,0) -> 0 | G13: =IF(6=3,-Assumptions!B140,0) -> 0 | H13: =IF(7=3,-Assumptions!B140,0) -> 0 | I13: =IF(8=3,-Assumptions!B140,0) -> 0 | J13: =IF(9=3,-Assumptions!B140,0) -> 0 | K13: =IF(10=3,-Assumptions!B140,0) -> 0 | L13: =IF(11=3,-Assumptions!B140,0) -> 0 | M13: =IF(12=3,-Assumptions!B140,0) -> 0 | N13: =IF(13=3,-Assumptions!B140,0) -> 0 | O13: =IF(14=3,-Assumptions!B140,0) -> 0 | P13: =IF(15=3,-Assumptions!B140,0) -> 0 | Q13: =IF(16=3,-Assumptions!B140,0) -> 0 | R13: =IF(17=3,-Assumptions!B140,0) -> 0 | S13: =IF(18=3,-Assumptions!B140,0) -> 0 | T13: =IF(19=3,-Assumptions!B140,0) -> 0 | U13: =IF(20=3,-Assumptions!B140,0) -> 0 | V13: =IF(21=3,-Assumptions!B140,0) -> 0 | W13: =IF(22=3,-Assumptions!B140,0) -> 0 | X13: =IF(23=3,-Assumptions!B140,0) -> 0 | Y13: =IF(24=3,-Assumptions!B140,0) -> 0 | Z13: =SUM(B13:Y13) -> -3600
A14: Investing Cash Flow | B14: =B11+B12+B13 -> -46200 | C14: =C11+C12+C13 -> 0 | D14: =D11+D12+D13 -> -114710 | E14: =E11+E12+E13 -> 0 | F14: =F11+F12+F13 -> 0 | G14: =G11+G12+G13 -> 0 | H14: =H11+H12+H13 -> 0 | I14: =I11+I12+I13 -> 0 | ... Y14: =Y11+Y12+Y13 -> 0 | Z14: =SUM(B14:Y14) -> -179910
A16: FINANCING ACTIVITIES
A17: Pre-Seed Funding (M1) | B17: =IF(1=1,500000,0) -> 500000 | C17: =IF(2=1,500000,0) -> 0 | D17: =IF(3=1,500000,0) -> 0 | E17: =IF(4=1,500000,0) -> 0 | F17: =IF(5=1,500000,0) -> 0 | G17: =IF(6=1,500000,0) -> 0 | H17: =IF(7=1,500000,0) -> 0 | I17: =IF(8=1,500000,0) -> 0 | J17: =IF(9=1,500000,0) -> 0 | K17: =IF(10=1,500000,0) -> 0 | L17: =IF(11=1,500000,0) -> 0 | M17: =IF(12=1,500000,0) -> 0 | N17: =IF(13=1,500000,0) -> 0 | O17: =IF(14=1,500000,0) -> 0 | P17: =IF(15=1,500000,0) -> 0 | Q17: =IF(16=1,500000,0) -> 0 | R17: =IF(17=1,500000,0) -> 0 | S17: =IF(18=1,500000,0) -> 0 | T17: =IF(19=1,500000,0) -> 0 | U17: =IF(20=1,500000,0) -> 0 | V17: =IF(21=1,500000,0) -> 0 | W17: =IF(22=1,500000,0) -> 0 | X17: =IF(23=1,500000,0) -> 0 | Y17: =IF(24=1,500000,0) -> 0 | Z17: =SUM(B17:Y17) -> 500000
A18: Financing Cash Flow | B18: =B17 -> 500000 | C18: =C17 -> 0 | D18: =D17 -> 0 | E18: =E17 -> 0 | F18: =F17 -> 0 | G18: =G17 -> 0 | H18: =H17 -> 0 | I18: =I17 -> 0 | ... Y18: =Y17 -> 0 | Z18: =SUM(B18:Y18) -> 500000
A20: NET CASH FLOW | B20: =B8+B14+B18 -> 438821 | C20: =C8+C14+C18 -> -14979 | D20: =D8+D14+D18 -> -130294 | E20: =E8+E14+E18 -> -19065 | F20: =F8+F14+F18 -> -17821 | G20: =G8+G14+G18 -> -18532 | H20: =H8+H14+H18 -> -18091 | I20: =I8+I14+I18 -> -14522 | ... Y20: =Y8+Y14+Y18 -> 35667 | Z20: =SUM(B20:Y20) -> 410313
A21: CUMULATIVE CASH BALANCE | B21: =B20 -> 438821 | C21: =B21+C20 -> 423842 | D21: =C21+D20 -> 293548 | E21: =D21+E20 -> 274483 | F21: =E21+F20 -> 256662 | G21: =F21+G20 -> 238130 | H21: =G21+H20 -> 220039 | I21: =H21+I20 -> 205517 | J21: =I21+J20 -> 194561 | ... Y21: =X21+Y20 -> 410313 | Z21: =Y21 -> 410313
A23: P&L vs CASH GAP ANALYSIS
A24: P&L Cumulative Cash | B24: ='P&L'!B172 -> 438821 | C24: ='P&L'!C172 -> 423842 | D24: ='P&L'!D172 -> 304648 | E24: ='P&L'!E172 -> 287933 | F24: ='P&L'!F172 -> 272462 | G24: ='P&L'!G172 -> 256280 | H24: ='P&L'!H172 -> 242889 | I24: ='P&L'!I172 -> 233067 | ... Y24: ='P&L'!Y172 -> 637613 | Z24: =SUM(B24:Y24) -> 8162237
A25: Actual Cash (this sheet) | B25: =B21 -> 438821 | C25: =C21 -> 423842 | D25: =D21 -> 293548 | E25: =E21 -> 274483 | F25: =F21 -> 256662 | G25: =G21 -> 238130 | H25: =H21 -> 220039 | I25: =I21 -> 205517 | ... Y25: =Y21 -> 410313 | Z25: =SUM(B25:Y25) -> 6249537
A26: GAP (Working Capital Drag) | B26: =B25-B24 -> 0 | C26: =C25-C24 -> 0 | D26: =D25-D24 -> -11100 | E26: =E25-E24 -> -13450 | F26: =F25-F24 -> -15800 | G26: =G25-G24 -> -18150 | H26: =H25-H24 -> -22850 | I26: =I25-I24 -> -27550 | ... Y26: =Y25-Y24 -> -227300 | Z26: =SUM(B26:Y26) -> -1912700

Sheet Unit Economics
A1: alche — Unit Economics Dashboard
A2: P1/P5: LTV:CAC, payback period, contribution margin per stream
A3: Metric | B3: M1 | C3: M2 | D3: M3 | E3: M4 | F3: M5 | G3: M6 | H3: M7 | I3: M8 | J3: M9 | K3: M10 | L3: M11 | M3: M12 | N3: M13 | O3: M14 | P3: M15 | Q3: M16 | R3: M17 | S3: M18 | T3: M19 | U3: M20 | V3: M21 | W3: M22 | X3: M23 | Y3: M24 | Z3: TOTAL
A4: SUBSCRIPTION METRICS
A5: Subscription ARPU (EUR/sub/mo) | B5: =IF('Growth Curves'!B17>0,ROUND('P&L'!B42/'Growth Curves'!B17,2),0) -> 0 | C5: =IF('Growth Curves'!C17>0,ROUND('P&L'!C42/'Growth Curves'!C17,2),0) -> 0 | D5: =IF('Growth Curves'!D17>0,ROUND('P&L'!D42/'Growth Curves'!D17,2),0) -> 0 | E5: =IF('Growth Curves'!E17>0,ROUND('P&L'!E42/'Growth Curves'!E17,2),0) -> 35.13 | F5: =IF('Growth Curves'!F17>0,ROUND('P&L'!F42/'Growth Curves'!F17,2),0) -> 37.38 | G5: =IF('Growth Curves'!G17>0,ROUND('P&L'!G42/'Growth Curves'!G17,2),0) -> 36.79 | H5: =IF('Growth Curves'!H17>0,ROUND('P&L'!H42/'Growth Curves'!H17,2),0) -> 36.59 | I5: =IF('Growth Curves'!I17>0,ROUND('P&L'!I42/'Growth Curves'!I17,2),0) -> 36.15 | ... Y5: =IF('Growth Curves'!Y17>0,ROUND('P&L'!Y42/'Growth Curves'!Y17,2),0) -> 36.54 | Z5: =Y5 -> 36.54
A6: Subscription LTV (ARPU / churn) | B6: =IF('Growth Curves'!B17>0,ROUND(('P&L'!B42/'Growth Curves'!B17)/Assumptions!B8,0),0) -> 0 | C6: =IF('Growth Curves'!C17>0,ROUND(('P&L'!C42/'Growth Curves'!C17)/Assumptions!B8,0),0) -> 0 | D6: =IF('Growth Curves'!D17>0,ROUND(('P&L'!D42/'Growth Curves'!D17)/Assumptions!B8,0),0) -> 0 | E6: =IF('Growth Curves'!E17>0,ROUND(('P&L'!E42/'Growth Curves'!E17)/Assumptions!B8,0),0) -> 439 | F6: =IF('Growth Curves'!F17>0,ROUND(('P&L'!F42/'Growth Curves'!F17)/Assumptions!B8,0),0) -> 467 | G6: =IF('Growth Curves'!G17>0,ROUND(('P&L'!G42/'Growth Curves'!G17)/Assumptions!B8,0),0) -> 460 | H6: =IF('Growth Curves'!H17>0,ROUND(('P&L'!H42/'Growth Curves'!H17)/Assumptions!B8,0),0) -> 457 | I6: =IF('Growth Curves'!I17>0,ROUND(('P&L'!I42/'Growth Curves'!I17)/Assumptions!B8,0),0) -> 452 | J6: =IF('Growth Curves'!J17>0,ROUND(('P&L'!J42/'Growth Curves'!J17)/Assumptions!B8,0),0) -> 457 | K6: =IF('Growth Curves'!K17>0,ROUND(('P&L'!K42/'Growth Curves'!K17)/Assumptions!B8,0),0) -> 464 | L6: =IF('Growth Curves'!L17>0,ROUND(('P&L'!L42/'Growth Curves'!L17)/Assumptions!B8,0),0) -> 459 | M6: =IF('Growth Curves'!M17>0,ROUND(('P&L'!M42/'Growth Curves'!M17)/Assumptions!B8,0),0) -> 456 | N6: =IF('Growth Curves'!N17>0,ROUND(('P&L'!N42/'Growth Curves'!N17)/Assumptions!B8,0),0) -> 457 | O6: =IF('Growth Curves'!O17>0,ROUND(('P&L'!O42/'Growth Curves'!O17)/Assumptions!B8,0),0) -> 456 | P6: =IF('Growth Curves'!P17>0,ROUND(('P&L'!P42/'Growth Curves'!P17)/Assumptions!B8,0),0) -> 454 | Q6: =IF('Growth Curves'!Q17>0,ROUND(('P&L'!Q42/'Growth Curves'!Q17)/Assumptions!B8,0),0) -> 456 | R6: =IF('Growth Curves'!R17>0,ROUND(('P&L'!R42/'Growth Curves'!R17)/Assumptions!B8,0),0) -> 458 | S6: =IF('Growth Curves'!S17>0,ROUND(('P&L'!S42/'Growth Curves'!S17)/Assumptions!B8,0),0) -> 456 | T6: =IF('Growth Curves'!T17>0,ROUND(('P&L'!T42/'Growth Curves'!T17)/Assumptions!B8,0),0) -> 457 | U6: =IF('Growth Curves'!U17>0,ROUND(('P&L'!U42/'Growth Curves'!U17)/Assumptions!B8,0),0) -> 456 | V6: =IF('Growth Curves'!V17>0,ROUND(('P&L'!V42/'Growth Curves'!V17)/Assumptions!B8,0),0) -> 456 | W6: =IF('Growth Curves'!W17>0,ROUND(('P&L'!W42/'Growth Curves'!W17)/Assumptions!B8,0),0) -> 456 | X6: =IF('Growth Curves'!X17>0,ROUND(('P&L'!X42/'Growth Curves'!X17)/Assumptions!B8,0),0) -> 455 | Y6: =IF('Growth Curves'!Y17>0,ROUND(('P&L'!Y42/'Growth Curves'!Y17)/Assumptions!B8,0),0) -> 457 | Z6: =Y6 -> 457
A7: CAC (paid ads / new subs) | B7: =IF('Growth Curves'!B15>0,ROUND('Growth Curves'!B10/'Growth Curves'!B15,0),0) -> 0 | C7: =IF('Growth Curves'!C15>0,ROUND('Growth Curves'!C10/'Growth Curves'!C15,0),0) -> 0 | D7: =IF('Growth Curves'!D15>0,ROUND('Growth Curves'!D10/'Growth Curves'!D15,0),0) -> 0 | E7: =IF('Growth Curves'!E15>0,ROUND('Growth Curves'!E10/'Growth Curves'!E15,0),0) -> 13 | F7: =IF('Growth Curves'!F15>0,ROUND('Growth Curves'!F10/'Growth Curves'!F15,0),0) -> 27 | G7: =IF('Growth Curves'!G15>0,ROUND('Growth Curves'!G10/'Growth Curves'!G15,0),0) -> 40 | H7: =IF('Growth Curves'!H15>0,ROUND('Growth Curves'!H10/'Growth Curves'!H15,0),0) -> 36 | I7: =IF('Growth Curves'!I15>0,ROUND('Growth Curves'!I10/'Growth Curves'!I15,0),0) -> 36 | ... Y7: =IF('Growth Curves'!Y15>0,ROUND('Growth Curves'!Y10/'Growth Curves'!Y15,0),0) -> 79 | Z7: =Y7 -> 79
A8: LTV:CAC Ratio | B8: =IF(B7>0,ROUND(B6/B7,1),0) -> 0 | C8: =IF(C7>0,ROUND(C6/C7,1),0) -> 0 | D8: =IF(D7>0,ROUND(D6/D7,1),0) -> 0 | E8: =IF(E7>0,ROUND(E6/E7,1),0) -> 33.8 | F8: =IF(F7>0,ROUND(F6/F7,1),0) -> 17.3 | G8: =IF(G7>0,ROUND(G6/G7,1),0) -> 11.5 | H8: =IF(H7>0,ROUND(H6/H7,1),0) -> 12.7 | I8: =IF(I7>0,ROUND(I6/I7,1),0) -> 12.6 | ... Y8: =IF(Y7>0,ROUND(Y6/Y7,1),0) -> 5.8 | Z8: =Y8 -> 5.8
A9: CAC Payback (months) | B9: =IF(AND(B6>0,B5>0),ROUND(B7/B5,1),0) -> 0 | C9: =IF(AND(C6>0,C5>0),ROUND(C7/C5,1),0) -> 0 | D9: =IF(AND(D6>0,D5>0),ROUND(D7/D5,1),0) -> 0 | E9: =IF(AND(E6>0,E5>0),ROUND(E7/E5,1),0) -> 0.4 | F9: =IF(AND(F6>0,F5>0),ROUND(F7/F5,1),0) -> 0.7 | G9: =IF(AND(G6>0,G5>0),ROUND(G7/G5,1),0) -> 1.1 | H9: =IF(AND(H6>0,H5>0),ROUND(H7/H5,1),0) -> 1 | I9: =IF(AND(I6>0,I5>0),ROUND(I7/I5,1),0) -> 1 | ... Y9: =IF(AND(Y6>0,Y5>0),ROUND(Y7/Y5,1),0) -> 2.2 | Z9: =Y9 -> 2.2
A11: CONTRIBUTION MARGIN BY STREAM
A12: Retail Contribution Margin % | B12: =IF('P&L'!B17>0,('P&L'!B17-'P&L'!B51-'P&L'!B52-'P&L'!B53)/'P&L'!B17,0) -> 0 | C12: =IF('P&L'!C17>0,('P&L'!C17-'P&L'!C51-'P&L'!C52-'P&L'!C53)/'P&L'!C17,0) -> 0 | D12: =IF('P&L'!D17>0,('P&L'!D17-'P&L'!D51-'P&L'!D52-'P&L'!D53)/'P&L'!D17,0) -> 0 | E12: =IF('P&L'!E17>0,('P&L'!E17-'P&L'!E51-'P&L'!E52-'P&L'!E53)/'P&L'!E17,0) -> 0.41428571 | F12: =IF('P&L'!F17>0,('P&L'!F17-'P&L'!F51-'P&L'!F52-'P&L'!F53)/'P&L'!F17,0) -> 0.41428571 | G12: =IF('P&L'!G17>0,('P&L'!G17-'P&L'!G51-'P&L'!G52-'P&L'!G53)/'P&L'!G17,0) -> 0.41442177 | H12: =IF('P&L'!H17>0,('P&L'!H17-'P&L'!H51-'P&L'!H52-'P&L'!H53)/'P&L'!H17,0) -> 0.41436735 | I12: =IF('P&L'!I17>0,('P&L'!I17-'P&L'!I51-'P&L'!I52-'P&L'!I53)/'P&L'!I17,0) -> 0.41440233 | ... Y12: =IF('P&L'!Y17>0,('P&L'!Y17-'P&L'!Y51-'P&L'!Y52-'P&L'!Y53)/'P&L'!Y17,0) -> 0.41438776 | Z12: =Y12 -> 0.41438776
A13: LED Therapy Contribution Margin % | B13: =IF('P&L'!B21>0,('P&L'!B21-'P&L'!B54)/'P&L'!B21,0) -> 0 | C13: =IF('P&L'!C21>0,('P&L'!C21-'P&L'!C54)/'P&L'!C21,0) -> 0 | D13: =IF('P&L'!D21>0,('P&L'!D21-'P&L'!D54)/'P&L'!D21,0) -> 0 | E13: =IF('P&L'!E21>0,('P&L'!E21-'P&L'!E54)/'P&L'!E21,0) -> 0 | F13: =IF('P&L'!F21>0,('P&L'!F21-'P&L'!F54)/'P&L'!F21,0) -> 0 | G13: =IF('P&L'!G21>0,('P&L'!G21-'P&L'!G54)/'P&L'!G21,0) -> 0 | H13: =IF('P&L'!H21>0,('P&L'!H21-'P&L'!H54)/'P&L'!H21,0) -> 0 | I13: =IF('P&L'!I21>0,('P&L'!I21-'P&L'!I54)/'P&L'!I21,0) -> 0 | ... Y13: =IF('P&L'!Y21>0,('P&L'!Y21-'P&L'!Y54)/'P&L'!Y21,0) -> 0 | Z13: =Y13 -> 0
A14: Smoothie Bar Contribution Margin % | B14: =IF('P&L'!B25>0,('P&L'!B25-'P&L'!B56)/'P&L'!B25,0) -> 0 | C14: =IF('P&L'!C25>0,('P&L'!C25-'P&L'!C56)/'P&L'!C25,0) -> 0 | D14: =IF('P&L'!D25>0,('P&L'!D25-'P&L'!D56)/'P&L'!D25,0) -> 0 | E14: =IF('P&L'!E25>0,('P&L'!E25-'P&L'!E56)/'P&L'!E25,0) -> 0.65046536 | F14: =IF('P&L'!F25>0,('P&L'!F25-'P&L'!F56)/'P&L'!F25,0) -> 0.64989662 | G14: =IF('P&L'!G25>0,('P&L'!G25-'P&L'!G56)/'P&L'!G25,0) -> 0.65012407 | H14: =IF('P&L'!H25>0,('P&L'!H25-'P&L'!H56)/'P&L'!H25,0) -> 0.64992614 | I14: =IF('P&L'!I25>0,('P&L'!I25-'P&L'!I56)/'P&L'!I25,0) -> 0.65004596 | ... Y14: =IF('P&L'!Y25>0,('P&L'!Y25-'P&L'!Y56)/'P&L'!Y25,0) -> 0.65 | Z14: =Y14 -> 0.65
A15: Subscription Contribution Margin % | B15: =IF('P&L'!B42>0,('P&L'!B42-'P&L'!B59)/'P&L'!B42,0) -> 0 | C15: =IF('P&L'!C42>0,('P&L'!C42-'P&L'!C59)/'P&L'!C42,0) -> 0 | D15: =IF('P&L'!D42>0,('P&L'!D42-'P&L'!D59)/'P&L'!D42,0) -> 0 | E15: =IF('P&L'!E42>0,('P&L'!E42-'P&L'!E59)/'P&L'!E42,0) -> 0.99051233 | F15: =IF('P&L'!F42>0,('P&L'!F42-'P&L'!F59)/'P&L'!F42,0) -> 0.99077491 | G15: =IF('P&L'!G42>0,('P&L'!G42-'P&L'!G59)/'P&L'!G42,0) -> 0.99029126 | H15: =IF('P&L'!H42>0,('P&L'!H42-'P&L'!H59)/'P&L'!H42,0) -> 0.9905914 | I15: =IF('P&L'!I42>0,('P&L'!I42-'P&L'!I59)/'P&L'!I42,0) -> 0.99042553 | ... Y15: =IF('P&L'!Y42>0,('P&L'!Y42-'P&L'!Y59)/'P&L'!Y42,0) -> 0.99041819 | Z15: =Y15 -> 0.99041819
A17: REVENUE MIX (P5: only 4.7% subs at M24)
A18: Retail % | B18: =IF('P&L'!B47>0,'P&L'!B17/'P&L'!B47,0) -> 0 | C18: =IF('P&L'!C47>0,'P&L'!C17/'P&L'!C47,0) -> 0 | D18: =IF('P&L'!D47>0,'P&L'!D17/'P&L'!D47,0) -> 0 | E18: =IF('P&L'!E47>0,'P&L'!E17/'P&L'!E47,0) -> 0.50988554 | F18: =IF('P&L'!F47>0,'P&L'!F17/'P&L'!F47,0) -> 0.5832639 | G18: =IF('P&L'!G47>0,'P&L'!G17/'P&L'!G47,0) -> 0.56529765 | H18: =IF('P&L'!H47>0,'P&L'!H17/'P&L'!H47,0) -> 0.60921026 | I18: =IF('P&L'!I47>0,'P&L'!I17/'P&L'!I47,0) -> 0.62284365 | ... Y18: =IF('P&L'!Y47>0,'P&L'!Y17/'P&L'!Y47,0) -> 0.84661729 | Z18: =Y18 -> 0.84661729
