Workbook

Sheet P&L
A1: alche — 24-Month P&L
A2: Pre-Seed | EUR 500K @ EUR 2.5M Cap | All decisions applied | Formula-based
A3: All amounts in EUR. Click any cell to see the formula.
A4: Budget P&L (EUR) | B4: M1 | C4: M2 | D4: M3 | E4: M4 | F4: M5 | G4: M6 | H4: M7 | I4: M8 | J4: M9 | K4: M10 | L4: M11 | M4: M12 | N4: M13 | O4: M14 | P4: M15 | Q4: M16 | R4: M17 | S4: M18 | T4: M19 | U4: M20 | V4: M21 | W4: M22 | X4: M23 | Y4: M24 | Z4: TOTAL
A5: SUBSCRIBER METRICS
A6: New Subs Added | B6: ='Growth Curves'!B14 | C6: ='Growth Curves'!C14 | D6: ='Growth Curves'!D14 | E6: ='Growth Curves'!E14 | F6: ='Growth Curves'!F14 | G6: ='Growth Curves'!G14 | H6: ='Growth Curves'!H14 | I6: ='Growth Curves'!I14 | ... Y6: ='Growth Curves'!Y14 | Z6: =SUM(B6:Y6)
A7: Churned Subs | B7: ='Growth Curves'!B15 | C7: ='Growth Curves'!C15 | D7: ='Growth Curves'!D15 | E7: ='Growth Curves'!E15 | F7: ='Growth Curves'!F15 | G7: ='Growth Curves'!G15 | H7: ='Growth Curves'!H15 | I7: ='Growth Curves'!I15 | ... Y7: ='Growth Curves'!Y15 | Z7: =SUM(B7:Y7)
A8: Total Subscribers | B8: ='Growth Curves'!B16 | C8: ='Growth Curves'!C16 | D8: ='Growth Curves'!D16 | E8: ='Growth Curves'!E16 | F8: ='Growth Curves'!F16 | G8: ='Growth Curves'!G16 | H8: ='Growth Curves'!H16 | I8: ='Growth Curves'!I16 | ... Y8: ='Growth Curves'!Y16 | Z8: =SUM(B8:Y8)
A9: Core (52%) | B9: ='Growth Curves'!B17 | C9: ='Growth Curves'!C17 | D9: ='Growth Curves'!D17 | E9: ='Growth Curves'!E17 | F9: ='Growth Curves'!F17 | G9: ='Growth Curves'!G17 | H9: ='Growth Curves'!H17 | I9: ='Growth Curves'!I17 | ... Y9: ='Growth Curves'!Y17 | Z9: =SUM(B9:Y9)
A10: Pro (38%) | B10: ='Growth Curves'!B18 | C10: ='Growth Curves'!C18 | D10: ='Growth Curves'!D18 | E10: ='Growth Curves'!E18 | F10: ='Growth Curves'!F18 | G10: ='Growth Curves'!G18 | H10: ='Growth Curves'!H18 | I10: ='Growth Curves'!I18 | ... Y10: ='Growth Curves'!Y18 | Z10: =SUM(B10:Y10)
A11: Premium (10%) | B11: ='Growth Curves'!B19 | C11: ='Growth Curves'!C19 | D11: ='Growth Curves'!D19 | E11: ='Growth Curves'!E19 | F11: ='Growth Curves'!F19 | G11: ='Growth Curves'!G19 | H11: ='Growth Curves'!H19 | I11: ='Growth Curves'!I19 | ... Y11: ='Growth Curves'!Y19 | Z11: =SUM(B11:Y11)
A13: INCOME
A14: Potions
A15: Units shipped | B15: ='Growth Curves'!B4 | C15: ='Growth Curves'!C4 | D15: ='Growth Curves'!D4 | E15: ='Growth Curves'!E4 | F15: ='Growth Curves'!F4 | G15: ='Growth Curves'!G4 | H15: ='Growth Curves'!H4 | I15: ='Growth Curves'!I4 | ... Y15: ='Growth Curves'!Y4 | Z15: =SUM(B15:Y15)
A16: Price/unit | B16: =Assumptions!B22 | C16: =Assumptions!B22 | D16: =Assumptions!B22 | E16: =Assumptions!B22 | F16: =Assumptions!B22 | G16: =Assumptions!B22 | H16: =Assumptions!B22 | I16: =Assumptions!B22 | J16: =Assumptions!B22 | K16: =Assumptions!B22 | L16: =Assumptions!B22 | M16: =Assumptions!B22 | N16: =Assumptions!B22 | O16: =Assumptions!B22 | P16: =Assumptions!B22 | Q16: =Assumptions!B22 | R16: =Assumptions!B22 | S16: =Assumptions!B22 | T16: =Assumptions!B22 | U16: =Assumptions!B22 | V16: =Assumptions!B22 | W16: =Assumptions!B22 | X16: =Assumptions!B22 | Y16: =Assumptions!B22 | Z16: =SUM(B16:Y16)
A17: Revenue | B17: =B15*Assumptions!B22 | C17: =C15*Assumptions!B22 | D17: =D15*Assumptions!B22 | E17: =E15*Assumptions!B22 | F17: =F15*Assumptions!B22 | G17: =G15*Assumptions!B22 | H17: =H15*Assumptions!B22 | I17: =I15*Assumptions!B22 | J17: =J15*Assumptions!B22 | K17: =K15*Assumptions!B22 | L17: =L15*Assumptions!B22 | M17: =M15*Assumptions!B22 | N17: =N15*Assumptions!B22 | O17: =O15*Assumptions!B22 | P17: =P15*Assumptions!B22 | Q17: =Q15*Assumptions!B22 | R17: =R15*Assumptions!B22 | S17: =S15*Assumptions!B22 | T17: =T15*Assumptions!B22 | U17: =U15*Assumptions!B22 | V17: =V15*Assumptions!B22 | W17: =W15*Assumptions!B22 | X17: =X15*Assumptions!B22 | Y17: =Y15*Assumptions!B22 | Z17: =SUM(B17:Y17)
A18: LED Therapy
A19: Sessions | B19: ='Growth Curves'!B5 | C19: ='Growth Curves'!C5 | D19: ='Growth Curves'!D5 | E19: ='Growth Curves'!E5 | F19: ='Growth Curves'!F5 | G19: ='Growth Curves'!G5 | H19: ='Growth Curves'!H5 | I19: ='Growth Curves'!I5 | ... Y19: ='Growth Curves'!Y5 | Z19: =SUM(B19:Y19)
A20: Price/session | B20: =Assumptions!B24 | C20: =Assumptions!B24 | D20: =Assumptions!B24 | E20: =Assumptions!B24 | F20: =Assumptions!B24 | G20: =Assumptions!B24 | H20: =Assumptions!B24 | I20: =Assumptions!B24 | J20: =Assumptions!B24 | K20: =Assumptions!B24 | L20: =Assumptions!B24 | M20: =Assumptions!B24 | N20: =Assumptions!B24 | O20: =Assumptions!B24 | P20: =Assumptions!B24 | Q20: =Assumptions!B24 | R20: =Assumptions!B24 | S20: =Assumptions!B24 | T20: =Assumptions!B24 | U20: =Assumptions!B24 | V20: =Assumptions!B24 | W20: =Assumptions!B24 | X20: =Assumptions!B24 | Y20: =Assumptions!B24 | Z20: =SUM(B20:Y20)
A21: Revenue | B21: =B19*Assumptions!B24 | C21: =C19*Assumptions!B24 | D21: =D19*Assumptions!B24 | E21: =E19*Assumptions!B24 | F21: =F19*Assumptions!B24 | G21: =G19*Assumptions!B24 | H21: =H19*Assumptions!B24 | I21: =I19*Assumptions!B24 | J21: =J19*Assumptions!B24 | K21: =K19*Assumptions!B24 | L21: =L19*Assumptions!B24 | M21: =M19*Assumptions!B24 | N21: =N19*Assumptions!B24 | O21: =O19*Assumptions!B24 | P21: =P19*Assumptions!B24 | Q21: =Q19*Assumptions!B24 | R21: =R19*Assumptions!B24 | S21: =S19*Assumptions!B24 | T21: =T19*Assumptions!B24 | U21: =U19*Assumptions!B24 | V21: =V19*Assumptions!B24 | W21: =W19*Assumptions!B24 | X21: =X19*Assumptions!B24 | Y21: =Y19*Assumptions!B24 | Z21: =SUM(B21:Y21)
A22: Smoothie Bar
A23: Units sold | B23: ='Growth Curves'!B6 | C23: ='Growth Curves'!C6 | D23: ='Growth Curves'!D6 | E23: ='Growth Curves'!E6 | F23: ='Growth Curves'!F6 | G23: ='Growth Curves'!G6 | H23: ='Growth Curves'!H6 | I23: ='Growth Curves'!I6 | ... Y23: ='Growth Curves'!Y6 | Z23: =SUM(B23:Y23)
A24: Price/smoothie | B24: =Assumptions!B26 | C24: =Assumptions!B26 | D24: =Assumptions!B26 | E24: =Assumptions!B26 | F24: =Assumptions!B26 | G24: =Assumptions!B26 | H24: =Assumptions!B26 | I24: =Assumptions!B26 | J24: =Assumptions!B26 | K24: =Assumptions!B26 | L24: =Assumptions!B26 | M24: =Assumptions!B26 | N24: =Assumptions!B26 | O24: =Assumptions!B26 | P24: =Assumptions!B26 | Q24: =Assumptions!B26 | R24: =Assumptions!B26 | S24: =Assumptions!B26 | T24: =Assumptions!B26 | U24: =Assumptions!B26 | V24: =Assumptions!B26 | W24: =Assumptions!B26 | X24: =Assumptions!B26 | Y24: =Assumptions!B26 | Z24: =SUM(B24:Y24)
A25: Revenue | B25: =ROUND(B23*Assumptions!B26,0) | C25: =ROUND(C23*Assumptions!B26,0) | D25: =ROUND(D23*Assumptions!B26,0) | E25: =ROUND(E23*Assumptions!B26,0) | F25: =ROUND(F23*Assumptions!B26,0) | G25: =ROUND(G23*Assumptions!B26,0) | H25: =ROUND(H23*Assumptions!B26,0) | I25: =ROUND(I23*Assumptions!B26,0) | J25: =ROUND(J23*Assumptions!B26,0) | K25: =ROUND(K23*Assumptions!B26,0) | L25: =ROUND(L23*Assumptions!B26,0) | M25: =ROUND(M23*Assumptions!B26,0) | N25: =ROUND(N23*Assumptions!B26,0) | O25: =ROUND(O23*Assumptions!B26,0) | P25: =ROUND(P23*Assumptions!B26,0) | Q25: =ROUND(Q23*Assumptions!B26,0) | R25: =ROUND(R23*Assumptions!B26,0) | S25: =ROUND(S23*Assumptions!B26,0) | T25: =ROUND(T23*Assumptions!B26,0) | U25: =ROUND(U23*Assumptions!B26,0) | V25: =ROUND(V23*Assumptions!B26,0) | W25: =ROUND(W23*Assumptions!B26,0) | X25: =ROUND(X23*Assumptions!B26,0) | Y25: =ROUND(Y23*Assumptions!B26,0) | Z25: =SUM(B25:Y25)
A26: Community Events
A27: Event count | B27: ='Growth Curves'!B7 | C27: ='Growth Curves'!C7 | D27: ='Growth Curves'!D7 | E27: ='Growth Curves'!E7 | F27: ='Growth Curves'!F7 | G27: ='Growth Curves'!G7 | H27: ='Growth Curves'!H7 | I27: ='Growth Curves'!I7 | ... Y27: ='Growth Curves'!Y7 | Z27: =SUM(B27:Y27)
A28: Avg attendees/event | B28: ='Growth Curves'!B8 | C28: ='Growth Curves'!C8 | D28: ='Growth Curves'!D8 | E28: ='Growth Curves'!E8 | F28: ='Growth Curves'!F8 | G28: ='Growth Curves'!G8 | H28: ='Growth Curves'!H8 | I28: ='Growth Curves'!I8 | ... Y28: ='Growth Curves'!Y8 | Z28: =SUM(B28:Y28)
A29: Total attendees | B29: =B27*B28 | C29: =C27*C28 | D29: =D27*D28 | E29: =E27*E28 | F29: =F27*F28 | G29: =G27*G28 | H29: =H27*H28 | I29: =I27*I28 | ... Y29: =Y27*Y28 | Z29: =SUM(B29:Y29)
A30: Price/ticket | B30: =Assumptions!B28 | C30: =Assumptions!B28 | D30: =Assumptions!B28 | E30: =Assumptions!B28 | F30: =Assumptions!B28 | G30: =Assumptions!B28 | H30: =Assumptions!B28 | I30: =Assumptions!B28 | J30: =Assumptions!B28 | K30: =Assumptions!B28 | L30: =Assumptions!B28 | M30: =Assumptions!B28 | N30: =Assumptions!B28 | O30: =Assumptions!B28 | P30: =Assumptions!B28 | Q30: =Assumptions!B28 | R30: =Assumptions!B28 | S30: =Assumptions!B28 | T30: =Assumptions!B28 | U30: =Assumptions!B28 | V30: =Assumptions!B28 | W30: =Assumptions!B28 | X30: =Assumptions!B28 | Y30: =Assumptions!B28 | Z30: =SUM(B30:Y30)
A31: Revenue | B31: =B29*Assumptions!B28 | C31: =C29*Assumptions!B28 | D31: =D29*Assumptions!B28 | E31: =E29*Assumptions!B28 | F31: =F29*Assumptions!B28 | G31: =G29*Assumptions!B28 | H31: =H29*Assumptions!B28 | I31: =I29*Assumptions!B28 | J31: =J29*Assumptions!B28 | K31: =K29*Assumptions!B28 | L31: =L29*Assumptions!B28 | M31: =M29*Assumptions!B28 | N31: =N29*Assumptions!B28 | O31: =O29*Assumptions!B28 | P31: =P29*Assumptions!B28 | Q31: =Q29*Assumptions!B28 | R31: =R29*Assumptions!B28 | S31: =S29*Assumptions!B28 | T31: =T29*Assumptions!B28 | U31: =U29*Assumptions!B28 | V31: =V29*Assumptions!B28 | W31: =W29*Assumptions!B28 | X31: =X29*Assumptions!B28 | Y31: =Y29*Assumptions!B28 | Z31: =SUM(B31:Y31)
A32: Doctor SaaS (D1: EUR 99/mo)
A33: Clinics listed | B33: ='Growth Curves'!B9 | C33: ='Growth Curves'!C9 | D33: ='Growth Curves'!D9 | E33: ='Growth Curves'!E9 | F33: ='Growth Curves'!F9 | G33: ='Growth Curves'!G9 | H33: ='Growth Curves'!H9 | I33: ='Growth Curves'!I9 | ... Y33: ='Growth Curves'!Y9 | Z33: =SUM(B33:Y33)
A34: Fee/month | B34: =Assumptions!B31 | C34: =Assumptions!B31 | D34: =Assumptions!B31 | E34: =Assumptions!B31 | F34: =Assumptions!B31 | G34: =Assumptions!B31 | H34: =Assumptions!B31 | I34: =Assumptions!B31 | J34: =Assumptions!B31 | K34: =Assumptions!B31 | L34: =Assumptions!B31 | M34: =Assumptions!B31 | N34: =Assumptions!B31 | O34: =Assumptions!B31 | P34: =Assumptions!B31 | Q34: =Assumptions!B31 | R34: =Assumptions!B31 | S34: =Assumptions!B31 | T34: =Assumptions!B31 | U34: =Assumptions!B31 | V34: =Assumptions!B31 | W34: =Assumptions!B31 | X34: =Assumptions!B31 | Y34: =Assumptions!B31 | Z34: =SUM(B34:Y34)
A35: Revenue | B35: =B33*Assumptions!B31 | C35: =C33*Assumptions!B31 | D35: =D33*Assumptions!B31 | E35: =E33*Assumptions!B31 | F35: =F33*Assumptions!B31 | G35: =G33*Assumptions!B31 | H35: =H33*Assumptions!B31 | I35: =I33*Assumptions!B31 | J35: =J33*Assumptions!B31 | K35: =K33*Assumptions!B31 | L35: =L33*Assumptions!B31 | M35: =M33*Assumptions!B31 | N35: =N33*Assumptions!B31 | O35: =O33*Assumptions!B31 | P35: =P33*Assumptions!B31 | Q35: =Q33*Assumptions!B31 | R35: =R33*Assumptions!B31 | S35: =S33*Assumptions!B31 | T35: =T33*Assumptions!B31 | U35: =U33*Assumptions!B31 | V35: =V33*Assumptions!B31 | W35: =W33*Assumptions!B31 | X35: =X33*Assumptions!B31 | Y35: =Y33*Assumptions!B31 | Z35: =SUM(B35:Y35)
A36: Restaurant (Phase 2 — EUR 0) | B36: 0 | C36: 0 | D36: 0 | E36: 0 | F36: 0 | G36: 0 | H36: 0 | I36: 0 | J36: 0 | K36: 0 | L36: 0 | M36: 0 | N36: 0 | O36: 0 | P36: 0 | Q36: 0 | R36: 0 | S36: 0 | T36: 0 | U36: 0 | V36: 0 | W36: 0 | X36: 0 | Y36: 0 | Z36: =SUM(B36:Y36)
A37: Subscriptions
A38: Core (EUR 19/mo) | B38: ='Growth Curves'!B17*Assumptions!B5 | C38: ='Growth Curves'!C17*Assumptions!B5 | D38: ='Growth Curves'!D17*Assumptions!B5 | E38: ='Growth Curves'!E17*Assumptions!B5 | F38: ='Growth Curves'!F17*Assumptions!B5 | G38: ='Growth Curves'!G17*Assumptions!B5 | H38: ='Growth Curves'!H17*Assumptions!B5 | I38: ='Growth Curves'!I17*Assumptions!B5 | J38: ='Growth Curves'!J17*Assumptions!B5 | K38: ='Growth Curves'!K17*Assumptions!B5 | L38: ='Growth Curves'!L17*Assumptions!B5 | M38: ='Growth Curves'!M17*Assumptions!B5 | N38: ='Growth Curves'!N17*Assumptions!B5 | O38: ='Growth Curves'!O17*Assumptions!B5 | P38: ='Growth Curves'!P17*Assumptions!B5 | Q38: ='Growth Curves'!Q17*Assumptions!B5 | R38: ='Growth Curves'!R17*Assumptions!B5 | S38: ='Growth Curves'!S17*Assumptions!B5 | T38: ='Growth Curves'!T17*Assumptions!B5 | U38: ='Growth Curves'!U17*Assumptions!B5 | V38: ='Growth Curves'!V17*Assumptions!B5 | W38: ='Growth Curves'!W17*Assumptions!B5 | X38: ='Growth Curves'!X17*Assumptions!B5 | Y38: ='Growth Curves'!Y17*Assumptions!B5 | Z38: =SUM(B38:Y38)
A39: Pro (EUR 49/mo) | B39: ='Growth Curves'!B18*Assumptions!B6 | C39: ='Growth Curves'!C18*Assumptions!B6 | D39: ='Growth Curves'!D18*Assumptions!B6 | E39: ='Growth Curves'!E18*Assumptions!B6 | F39: ='Growth Curves'!F18*Assumptions!B6 | G39: ='Growth Curves'!G18*Assumptions!B6 | H39: ='Growth Curves'!H18*Assumptions!B6 | I39: ='Growth Curves'!I18*Assumptions!B6 | J39: ='Growth Curves'!J18*Assumptions!B6 | K39: ='Growth Curves'!K18*Assumptions!B6 | L39: ='Growth Curves'!L18*Assumptions!B6 | M39: ='Growth Curves'!M18*Assumptions!B6 | N39: ='Growth Curves'!N18*Assumptions!B6 | O39: ='Growth Curves'!O18*Assumptions!B6 | P39: ='Growth Curves'!P18*Assumptions!B6 | Q39: ='Growth Curves'!Q18*Assumptions!B6 | R39: ='Growth Curves'!R18*Assumptions!B6 | S39: ='Growth Curves'!S18*Assumptions!B6 | T39: ='Growth Curves'!T18*Assumptions!B6 | U39: ='Growth Curves'!U18*Assumptions!B6 | V39: ='Growth Curves'!V18*Assumptions!B6 | W39: ='Growth Curves'!W18*Assumptions!B6 | X39: ='Growth Curves'!X18*Assumptions!B6 | Y39: ='Growth Curves'!Y18*Assumptions!B6 | Z39: =SUM(B39:Y39)
A40: Premium (EUR 99/mo) | B40: ='Growth Curves'!B19*Assumptions!B7 | C40: ='Growth Curves'!C19*Assumptions!B7 | D40: ='Growth Curves'!D19*Assumptions!B7 | E40: ='Growth Curves'!E19*Assumptions!B7 | F40: ='Growth Curves'!F19*Assumptions!B7 | G40: ='Growth Curves'!G19*Assumptions!B7 | H40: ='Growth Curves'!H19*Assumptions!B7 | I40: ='Growth Curves'!I19*Assumptions!B7 | J40: ='Growth Curves'!J19*Assumptions!B7 | K40: ='Growth Curves'!K19*Assumptions!B7 | L40: ='Growth Curves'!L19*Assumptions!B7 | M40: ='Growth Curves'!M19*Assumptions!B7 | N40: ='Growth Curves'!N19*Assumptions!B7 | O40: ='Growth Curves'!O19*Assumptions!B7 | P40: ='Growth Curves'!P19*Assumptions!B7 | Q40: ='Growth Curves'!Q19*Assumptions!B7 | R40: ='Growth Curves'!R19*Assumptions!B7 | S40: ='Growth Curves'!S19*Assumptions!B7 | T40: ='Growth Curves'!T19*Assumptions!B7 | U40: ='Growth Curves'!U19*Assumptions!B7 | V40: ='Growth Curves'!V19*Assumptions!B7 | W40: ='Growth Curves'!W19*Assumptions!B7 | X40: ='Growth Curves'!X19*Assumptions!B7 | Y40: ='Growth Curves'!Y19*Assumptions!B7 | Z40: =SUM(B40:Y40)
A41: Subscription MRR | B41: =B38+B39+B40 | C41: =C38+C39+C40 | D41: =D38+D39+D40 | E41: =E38+E39+E40 | F41: =F38+F39+F40 | G41: =G38+G39+G40 | H41: =H38+H39+H40 | I41: =I38+I39+I40 | ... Y41: =Y38+Y39+Y40 | Z41: =SUM(B41:Y41)
...

Sheet Assumptions
A1: alche — P&L Assumptions
A2: Change any value here → P&L sheet auto-recalculates
A4: SUBSCRIPTION MODEL
A5: Core tier price (EUR/mo) | B5: 19 | C5: Entry tier
A6: Pro tier price (EUR/mo) | B6: 49 | C6: Sweet spot
A7: Premium tier price (EUR/mo) | B7: 99 | C7: Highest ARPU
A8: Monthly churn rate | B8: 0.08 | C8: 8% — locked data
A9: Core tier share | B9: 0.52 | C9: 52%
A10: Pro tier share | B10: 0.38 | C10: 38%
A11: Premium tier share | B11: 0.1 | C11: 10%
A13: SUBSCRIBER GROWTH (new subs/month)
A14: M1-M3 | B14: 3 | C14: Pre-launch beta
A15: M4-M6 | B15: 15 | C15: Product launch
A16: M7-M9 | B16: 22 | C16: Growth acceleration
A17: M10-M12 | B17: 28 | C17: Marketing ramp
A18: M13-M18 | B18: 32 | C18: Scaling
A19: M19-M24 | B19: 38 | C19: Growth marketer effect
A21: PRODUCT PRICING
A22: Potion retail price (EUR) | B22: 49 | C22: R10 validated
A23: Potion COGS (EUR/unit) | B23: 23.5 | C23: R10: wholesale 48% of retail
A24: LED session price (EUR) | B24: 45 | C24: Red light therapy
A25: LED practitioner cost (EUR) | B25: 25 | C25: Per session
A26: Smoothie avg price (EUR) | B26: 9.67 | C26: R2 Cost Analysis PDF
A27: Smoothie COGS rate | B27: 0.35 | C27: 35% ingredients+packaging (R2)
A28: Event ticket price (EUR) | B28: 35 | C28: Community events
A29: Event fixed cost (EUR) | B29: 250 | C29: Venue per event
A30: Ticketing platform fee | B30: 0.07 | C30: 7% Luma/Eventbrite
A31: Doctor SaaS fee (EUR/mo) | B31: 99 | C31: D1: was EUR 150
A32: Doctor verify cost (EUR) | B32: 25 | C32: Per new doctor
A33: Doctor max clinics | B33: 20 | C33: D1: cap for M1-24
A35: COST RATES
A36: Waste — blended rate | B36: 0.055 | C36: D7: capsules 4%, powders 7%
A37: 3PL fulfillment (EUR/unit) | B37: 2.5 | C37: Potions only
A38: Stripe fee rate | B38: 0.029 | C38: 2.9%
A39: AI API per user (EUR/mo) | B39: 0.35 | C39: D6: hybrid Claude+Gemini R9
A40: Refund/returns reserve | B40: 0.015 | C40: 1.5% of product revenue
A42: PAYROLL
A43: Founder gross salary (each) | B43: 4166 | C43: EUR/mo
A44: Employer multiplier | B44: 1.22 | C44: German social contributions
A45: Space staff gross (M4+) | B45: 1230 | C45: Part-time
...

Sheet Growth Curves
A1: alche — Monthly Growth Curves (Input Data)
A2: Edit these numbers to change unit forecasts. P&L formulas reference these cells.
A3: Metric | B3: M1 | C3: M2 | D3: M3 | E3: M4 | F3: M5 | G3: M6 | H3: M7 | I3: M8 | J3: M9 | K3: M10 | L3: M11 | M3: M12 | N3: M13 | O3: M14 | P3: M15 | Q3: M16 | R3: M17 | S3: M18 | T3: M19 | U3: M20 | V3: M21 | W3: M22 | X3: M23 | Y3: M24
A4: Potion Units | B4: 0 | C4: 0 | D4: 0 | E4: 50 | F4: 100 | G4: 150 | H4: 250 | I4: 350 | J4: 450 | K4: 600 | L4: 750 | M4: 900 | N4: 1100 | O4: 1300 | P4: 1500 | Q4: 1800 | R4: 2100 | S4: 2400 | T4: 2700 | U4: 3000 | V4: 3400 | W4: 3800 | X4: 4200 | Y4: 4600
A5: LED Sessions | B5: 0 | C5: 0 | D5: 0 | E5: 10 | F5: 20 | G5: 35 | H5: 50 | I5: 65 | J5: 80 | K5: 100 | L5: 120 | M5: 140 | N5: 160 | O5: 180 | P5: 200 | Q5: 220 | R5: 240 | S5: 260 | T5: 280 | U5: 300 | V5: 300 | W5: 300 | X5: 300 | Y5: 300
A6: Smoothie Units | B6: 0 | C6: 0 | D6: 0 | E6: 100 | F6: 150 | G6: 250 | H6: 350 | I6: 450 | J6: 550 | K6: 650 | L6: 750 | M6: 850 | N6: 950 | O6: 1050 | P6: 1150 | Q6: 1250 | R6: 1350 | S6: 1450 | T6: 1550 | U6: 1650 | V6: 1750 | W6: 1850 | X6: 1950 | Y6: 2000
A7: Event Count | B7: 0 | C7: 0 | D7: 0 | E7: 1 | F7: 1 | G7: 2 | H7: 2 | I7: 3 | J7: 3 | K7: 3 | L7: 3 | M7: 3 | N7: 3 | O7: 3 | P7: 4 | Q7: 4 | R7: 4 | S7: 4 | T7: 4 | U7: 5 | V7: 5 | W7: 5 | X7: 5 | Y7: 5
A8: Event Avg Attendees | B8: 0 | C8: 0 | D8: 0 | E8: 12 | F8: 15 | G8: 15 | H8: 18 | I8: 18 | J8: 18 | K8: 20 | L8: 20 | M8: 20 | N8: 22 | O8: 22 | P8: 22 | Q8: 22 | R8: 24 | S8: 24 | T8: 25 | U8: 25 | V8: 25 | W8: 25 | X8: 25 | Y8: 25
A9: Doctor Clinics | B9: 0 | C9: 0 | D9: 0 | E9: 0 | F9: 0 | G9: 2 | H9: 5 | I9: 8 | J9: 10 | K9: 12 | L9: 15 | M9: 17 | N9: 18 | O9: 19 | P9: 20 | Q9: 20 | R9: 20 | S9: 20 | T9: 20 | U9: 20 | V9: 20 | W9: 20 | X9: 20 | Y9: 20
A10: Marketing Spend (EUR) | B10: 50 | C10: 50 | D10: 100 | E10: 200 | F10: 400 | G10: 600 | H10: 800 | I10: 800 | J10: 1000 | K10: 1200 | L10: 1400 | M10: 1400 | N10: 1800 | O10: 1800 | P10: 2000 | Q10: 2000 | R10: 2200 | S10: 2200 | T10: 2500 | U10: 2500 | V10: 2800 | W10: 2800 | X10: 3000 | Y10: 3000
A11: New Doctors (delta) | B11: 0 | C11: =MAX(0,C9-B9) | D11: =MAX(0,D9-C9) | E11: =MAX(0,E9-D9) | F11: =MAX(0,F9-E9) | G11: =MAX(0,G9-F9) | H11: =MAX(0,H9-G9) | I11: =MAX(0,I9-H9) | J11: =MAX(0,J9-I9) | ... Y11: =MAX(0,Y9-X9)
A13: SUBSCRIBER MODEL
A14: New Subs Rate | B14: =IF(1<=3,Assumptions!B14,IF(1<=6,Assumptions!B15,IF(1<=9,Assumptions!B16,IF(1<=12,Assumptions!B17,IF(1<=18,Assumptions!B18,Assumptions!B19))))) | C14: =IF(2<=3,Assumptions!B14,IF(2<=6,Assumptions!B15,IF(2<=9,Assumptions!B16,IF(2<=12,Assumptions!B17,IF(2<=18,Assumptions!B18,Assumptions!B19))))) | D14: =IF(3<=3,Assumptions!B14,IF(3<=6,Assumptions!B15,IF(3<=9,Assumptions!B16,IF(3<=12,Assumptions!B17,IF(3<=18,Assumptions!B18,Assumptions!B19))))) | E14: =IF(4<=3,Assumptions!B14,IF(4<=6,Assumptions!B15,IF(4<=9,Assumptions!B16,IF(4<=12,Assumptions!B17,IF(4<=18,Assumptions!B18,Assumptions!B19))))) | F14: =IF(5<=3,Assumptions!B14,IF(5<=6,Assumptions!B15,IF(5<=9,Assumptions!B16,IF(5<=12,Assumptions!B17,IF(5<=18,Assumptions!B18,Assumptions!B19))))) | G14: =IF(6<=3,Assumptions!B14,IF(6<=6,Assumptions!B15,IF(6<=9,Assumptions!B16,IF(6<=12,Assumptions!B17,IF(6<=18,Assumptions!B18,Assumptions!B19))))) | H14: =IF(7<=3,Assumptions!B14,IF(7<=6,Assumptions!B15,IF(7<=9,Assumptions!B16,IF(7<=12,Assumptions!B17,IF(7<=18,Assumptions!B18,Assumptions!B19))))) | I14: =IF(8<=3,Assumptions!B14,IF(8<=6,Assumptions!B15,IF(8<=9,Assumptions!B16,IF(8<=12,Assumptions!B17,IF(8<=18,Assumptions!B18,Assumptions!B19))))) | J14: =IF(9<=3,Assumptions!B14,IF(9<=6,Assumptions!B15,IF(9<=9,Assumptions!B16,IF(9<=12,Assumptions!B17,IF(9<=18,Assumptions!B18,Assumptions!B19))))) | K14: =IF(10<=3,Assumptions!B14,IF(10<=6,Assumptions!B15,IF(10<=9,Assumptions!B16,IF(10<=12,Assumptions!B17,IF(10<=18,Assumptions!B18,Assumptions!B19))))) | L14: =IF(11<=3,Assumptions!B14,IF(11<=6,Assumptions!B15,IF(11<=9,Assumptions!B16,IF(11<=12,Assumptions!B17,IF(11<=18,Assumptions!B18,Assumptions!B19))))) | M14: =IF(12<=3,Assumptions!B14,IF(12<=6,Assumptions!B15,IF(12<=9,Assumptions!B16,IF(12<=12,Assumptions!B17,IF(12<=18,Assumptions!B18,Assumptions!B19))))) | N14: =IF(13<=3,Assumptions!B14,IF(13<=6,Assumptions!B15,IF(13<=9,Assumptions!B16,IF(13<=12,Assumptions!B17,IF(13<=18,Assumptions!B18,Assumptions!B19))))) | O14: =IF(14<=3,Assumptions!B14,IF(14<=6,Assumptions!B15,IF(14<=9,Assumptions!B16,IF(14<=12,Assumptions!B17,IF(14<=18,Assumptions!B18,Assumptions!B19))))) | P14: =IF(15<=3,Assumptions!B14,IF(15<=6,Assumptions!B15,IF(15<=9,Assumptions!B16,IF(15<=12,Assumptions!B17,IF(15<=18,Assumptions!B18,Assumptions!B19))))) | Q14: =IF(16<=3,Assumptions!B14,IF(16<=6,Assumptions!B15,IF(16<=9,Assumptions!B16,IF(16<=12,Assumptions!B17,IF(16<=18,Assumptions!B18,Assumptions!B19))))) | R14: =IF(17<=3,Assumptions!B14,IF(17<=6,Assumptions!B15,IF(17<=9,Assumptions!B16,IF(17<=12,Assumptions!B17,IF(17<=18,Assumptions!B18,Assumptions!B19))))) | S14: =IF(18<=3,Assumptions!B14,IF(18<=6,Assumptions!B15,IF(18<=9,Assumptions!B16,IF(18<=12,Assumptions!B17,IF(18<=18,Assumptions!B18,Assumptions!B19))))) | T14: =IF(19<=3,Assumptions!B14,IF(19<=6,Assumptions!B15,IF(19<=9,Assumptions!B16,IF(19<=12,Assumptions!B17,IF(19<=18,Assumptions!B18,Assumptions!B19))))) | U14: =IF(20<=3,Assumptions!B14,IF(20<=6,Assumptions!B15,IF(20<=9,Assumptions!B16,IF(20<=12,Assumptions!B17,IF(20<=18,Assumptions!B18,Assumptions!B19))))) | V14: =IF(21<=3,Assumptions!B14,IF(21<=6,Assumptions!B15,IF(21<=9,Assumptions!B16,IF(21<=12,Assumptions!B17,IF(21<=18,Assumptions!B18,Assumptions!B19))))) | W14: =IF(22<=3,Assumptions!B14,IF(22<=6,Assumptions!B15,IF(22<=9,Assumptions!B16,IF(22<=12,Assumptions!B17,IF(22<=18,Assumptions!B18,Assumptions!B19))))) | X14: =IF(23<=3,Assumptions!B14,IF(23<=6,Assumptions!B15,IF(23<=9,Assumptions!B16,IF(23<=12,Assumptions!B17,IF(23<=18,Assumptions!B18,Assumptions!B19))))) | Y14: =IF(24<=3,Assumptions!B14,IF(24<=6,Assumptions!B15,IF(24<=9,Assumptions!B16,IF(24<=12,Assumptions!B17,IF(24<=18,Assumptions!B18,Assumptions!B19)))))
A15: Churned Subs | B15: 0 | C15: =ROUND(B16*Assumptions!B8,0) | D15: =ROUND(C16*Assumptions!B8,0) | E15: =ROUND(D16*Assumptions!B8,0) | F15: =ROUND(E16*Assumptions!B8,0) | G15: =ROUND(F16*Assumptions!B8,0) | H15: =ROUND(G16*Assumptions!B8,0) | I15: =ROUND(H16*Assumptions!B8,0) | J15: =ROUND(I16*Assumptions!B8,0) | K15: =ROUND(J16*Assumptions!B8,0) | L15: =ROUND(K16*Assumptions!B8,0) | M15: =ROUND(L16*Assumptions!B8,0) | N15: =ROUND(M16*Assumptions!B8,0) | O15: =ROUND(N16*Assumptions!B8,0) | P15: =ROUND(O16*Assumptions!B8,0) | Q15: =ROUND(P16*Assumptions!B8,0) | R15: =ROUND(Q16*Assumptions!B8,0) | S15: =ROUND(R16*Assumptions!B8,0) | T15: =ROUND(S16*Assumptions!B8,0) | U15: =ROUND(T16*Assumptions!B8,0) | V15: =ROUND(U16*Assumptions!B8,0) | W15: =ROUND(V16*Assumptions!B8,0) | X15: =ROUND(W16*Assumptions!B8,0) | Y15: =ROUND(X16*Assumptions!B8,0)
A16: Total Subscribers | B16: =MAX(0,B14-B15) | C16: =MAX(0,B16-C15+C14) | D16: =MAX(0,C16-D15+D14) | E16: =MAX(0,D16-E15+E14) | F16: =MAX(0,E16-F15+F14) | G16: =MAX(0,F16-G15+G14) | H16: =MAX(0,G16-H15+H14) | I16: =MAX(0,H16-I15+I14) | J16: =MAX(0,I16-J15+J14) | ... Y16: =MAX(0,X16-Y15+Y14)
A17: Core Subs (52%) | B17: =ROUND(B16*Assumptions!B9,0) | C17: =ROUND(C16*Assumptions!B9,0) | D17: =ROUND(D16*Assumptions!B9,0) | E17: =ROUND(E16*Assumptions!B9,0) | F17: =ROUND(F16*Assumptions!B9,0) | G17: =ROUND(G16*Assumptions!B9,0) | H17: =ROUND(H16*Assumptions!B9,0) | I17: =ROUND(I16*Assumptions!B9,0) | J17: =ROUND(J16*Assumptions!B9,0) | K17: =ROUND(K16*Assumptions!B9,0) | L17: =ROUND(L16*Assumptions!B9,0) | M17: =ROUND(M16*Assumptions!B9,0) | N17: =ROUND(N16*Assumptions!B9,0) | O17: =ROUND(O16*Assumptions!B9,0) | P17: =ROUND(P16*Assumptions!B9,0) | Q17: =ROUND(Q16*Assumptions!B9,0) | R17: =ROUND(R16*Assumptions!B9,0) | S17: =ROUND(S16*Assumptions!B9,0) | T17: =ROUND(T16*Assumptions!B9,0) | U17: =ROUND(U16*Assumptions!B9,0) | V17: =ROUND(V16*Assumptions!B9,0) | W17: =ROUND(W16*Assumptions!B9,0) | X17: =ROUND(X16*Assumptions!B9,0) | Y17: =ROUND(Y16*Assumptions!B9,0)
A18: Pro Subs (38%) | B18: =ROUND(B16*Assumptions!B10,0) | C18: =ROUND(C16*Assumptions!B10,0) | D18: =ROUND(D16*Assumptions!B10,0) | E18: =ROUND(E16*Assumptions!B10,0) | F18: =ROUND(F16*Assumptions!B10,0) | G18: =ROUND(G16*Assumptions!B10,0) | H18: =ROUND(H16*Assumptions!B10,0) | I18: =ROUND(I16*Assumptions!B10,0) | J18: =ROUND(J16*Assumptions!B10,0) | K18: =ROUND(K16*Assumptions!B10,0) | L18: =ROUND(L16*Assumptions!B10,0) | M18: =ROUND(M16*Assumptions!B10,0) | N18: =ROUND(N16*Assumptions!B10,0) | O18: =ROUND(O16*Assumptions!B10,0) | P18: =ROUND(P16*Assumptions!B10,0) | Q18: =ROUND(Q16*Assumptions!B10,0) | R18: =ROUND(R16*Assumptions!B10,0) | S18: =ROUND(S16*Assumptions!B10,0) | T18: =ROUND(T16*Assumptions!B10,0) | U18: =ROUND(U16*Assumptions!B10,0) | V18: =ROUND(V16*Assumptions!B10,0) | W18: =ROUND(W16*Assumptions!B10,0) | X18: =ROUND(X16*Assumptions!B10,0) | Y18: =ROUND(Y16*Assumptions!B10,0)
A19: Premium Subs (10%) | B19: =MAX(0,B16-B17-B18) | C19: =MAX(0,C16-C17-C18) | D19: =MAX(0,D16-D17-D18) | E19: =MAX(0,E16-E17-E18) | F19: =MAX(0,F16-F17-F18) | G19: =MAX(0,G16-G17-G18) | H19: =MAX(0,H16-H17-H18) | I19: =MAX(0,I16-I17-I18) | ... Y19: =MAX(0,Y16-Y17-Y18)

Sheet Decisions
A1: alche — Decision Log (D1-D11)
A2: All decisions from P&L session, 2026-02-23
A4: # | B4: Decision | C4: Choice Made | D4: Old Value | E4: P&L Impact
A5: D1 | B5: Doctor Revenue | C5: C. SaaS EUR 99/mo × 20 clinics | D5: EUR 150/mo × 865 | E5: Revenue -75%; legally safe (StGB §299a)
A6: D2 | B6: Restaurant Revenue | C6: B. Phase 2 (500+ users) | D6: EUR 1.50/cover M6+ | E6: EUR 0 all 24 months
A7: D3 | B7: CGM Hardware | C7: A. Software-Only BYOD | D7: EUR 130 × units | E7: Removed; margin 80-90%
A8: D4 | B8: Physical Space | C8: A. Smoothie bar + space | D8: EUR 0 | E8: New rev + EUR 2,500/mo rent + CapEx
A9: D5 | B9: CapEx Section | C9: Yes, include | D9: All OpEx | E9: EUR 51,000 total
A10: D6 | B10: AI Cost Model | C10: Both internal + user-facing | D10: EUR 210 + EUR 499 Terra | E10: EUR 210 + EUR 0.35/sub (R9)
A11: D7 | B11: Product Waste | C11: Category-weighted | D11: Flat 5% | E11: 5.5% blended
A12: D8 | B12: Terra CGM API | C12: Defer — free HealthKit | D12: EUR 499/mo M6+ | E12: Saves EUR 9,481
A13: D9 | B13: SaaS Stack | C13: Itemized (R8) | D13: EUR 350→1800 | E13: EUR 338→500→750
A14: D10 | B14: Menu Analysis | C14: EUR 0 — founders do it | D14: EUR 500/mo | E14: Saves EUR 12,000
A15: D11 | B15: Retail Products | C15: EUR 49 validated; COGS EUR 23.50 | D15: EUR 11.50 COGS | E15: Margin 76% → 52% (R10)
A18: NEW LINES ADDED (7-Persona Audit)
A19: # | B19: Line Item | C19: Amount | D19: Source Persona | E19: Rationale
A20: P1 | B20: Utilities (Strom/Gas/Wasser) | C20: EUR 400/mo from M4 | D20: Operations Manager | E20: Can't run smoothie bar without electricity
A21: P2 | B21: Cleaning/Maintenance | C21: EUR 300/mo from M4 | D21: Operations Manager | E21: Physical space upkeep
A22: P3 | B22: BG Insurance | C22: ~1.5% of gross payroll | D22: Steuerberater | E22: MANDATORY German employer insurance
A23: P4 | B23: Contingency Buffer | C23: 10% of OpEx | D23: Angel Investor | E23: Every serious investor expects this
A24: P5 | B24: Refund/Returns Reserve | C24: 1.5% of product revenue | D24: CFO/FP&A | E24: Physical product returns
A25: P6 | B25: IHK Berlin | C25: EUR 25/mo (EUR 300/yr) | D25: Steuerberater | E25: Mandatory chamber membership
A26: P7 | B26: Recruitment Cost | C26: EUR 5,000 one-off M17 | D26: HR Manager | E26: CTO job posting / headhunter
A27: P8 | B27: POS System | C27: EUR 50/mo from M4 | D27: Operations Manager | E27: Cash register for space
A28: P9 | B28: Depreciation | C28: CapEx / 36 months linear | D28: CFO/FP&A | E28: Tax-accurate P&L presentation
A29: P10 | B29: Permits & Licenses | C29: EUR 500 one-off M3 | D29: Food Inspector | E29: Lebensmittelüberwachung
A30: P11 | B30: Space Staff | C30: EUR 1,501/mo from M4 | D30: Operations Manager | E30: Part-time for smoothie bar
