Workbook

Sheet P&L
A1: alche — 24-Month P&L v4
A2: Pre-Seed | EUR 300K @ EUR 2.5M Cap | v4: Annual subs + B2B + Gift Cards + Corrected App/Rent costs
A3: All amounts in EUR net of VAT. Click any cell to see the formula.
A4: Budget P&L (EUR) | B4: M1 | C4: M2 | D4: M3 | E4: M4 | F4: M5 | G4: M6 | H4: M7 | I4: M8 | J4: M9 | K4: M10 | L4: M11 | M4: M12 | N4: M13 | O4: M14 | P4: M15 | Q4: M16 | R4: M17 | S4: M18 | T4: M19 | U4: M20 | V4: M21 | W4: M22 | X4: M23 | Y4: M24 | Z4: TOTAL
A5: SUBSCRIBER METRICS
A6: New Subs Added | B6: ='Growth Curves'!B15 | C6: ='Growth Curves'!C15 | D6: ='Growth Curves'!D15 | E6: ='Growth Curves'!E15 | F6: ='Growth Curves'!F15 | G6: ='Growth Curves'!G15 | H6: ='Growth Curves'!H15 | I6: ='Growth Curves'!I15 | ... Y6: ='Growth Curves'!Y15 | Z6: =SUM(B6:Y6)
A7: Churned Subs | B7: ='Growth Curves'!B16 | C7: ='Growth Curves'!C16 | D7: ='Growth Curves'!D16 | E7: ='Growth Curves'!E16 | F7: ='Growth Curves'!F16 | G7: ='Growth Curves'!G16 | H7: ='Growth Curves'!H16 | I7: ='Growth Curves'!I16 | ... Y7: ='Growth Curves'!Y16 | Z7: =SUM(B7:Y7)
A8: Total Subscribers | B8: ='Growth Curves'!B17 | C8: ='Growth Curves'!C17 | D8: ='Growth Curves'!D17 | E8: ='Growth Curves'!E17 | F8: ='Growth Curves'!F17 | G8: ='Growth Curves'!G17 | H8: ='Growth Curves'!H17 | I8: ='Growth Curves'!I17 | ... Y8: ='Growth Curves'!Y17 | Z8: =SUM(B8:Y8)
A9: Core (52%) | B9: ='Growth Curves'!B18 | C9: ='Growth Curves'!C18 | D9: ='Growth Curves'!D18 | E9: ='Growth Curves'!E18 | F9: ='Growth Curves'!F18 | G9: ='Growth Curves'!G18 | H9: ='Growth Curves'!H18 | I9: ='Growth Curves'!I18 | ... Y9: ='Growth Curves'!Y18 | Z9: =SUM(B9:Y9)
A10: Pro (38%) | B10: ='Growth Curves'!B19 | C10: ='Growth Curves'!C19 | D10: ='Growth Curves'!D19 | E10: ='Growth Curves'!E19 | F10: ='Growth Curves'!F19 | G10: ='Growth Curves'!G19 | H10: ='Growth Curves'!H19 | I10: ='Growth Curves'!I19 | ... Y10: ='Growth Curves'!Y19 | Z10: =SUM(B10:Y10)
A11: Premium (10%) | B11: ='Growth Curves'!B20 | C11: ='Growth Curves'!C20 | D11: ='Growth Curves'!D20 | E11: ='Growth Curves'!E20 | F11: ='Growth Curves'!F20 | G11: ='Growth Curves'!G20 | H11: ='Growth Curves'!H20 | I11: ='Growth Curves'!I20 | ... Y11: ='Growth Curves'!Y20 | Z11: =SUM(B11:Y11)
A13: INCOME
A14: Retail Products (D11: EUR 49 validated, COGS EUR 23.50)
A15: Units sold | B15: ='Growth Curves'!B4 | C15: ='Growth Curves'!C4 | D15: ='Growth Curves'!D4 | E15: ='Growth Curves'!E4 | F15: ='Growth Curves'!F4 | G15: ='Growth Curves'!G4 | H15: ='Growth Curves'!H4 | I15: ='Growth Curves'!I4 | ... Y15: ='Growth Curves'!Y4 | Z15: =SUM(B15:Y15)
A16: Price/unit | B16: =Assumptions!B22 | C16: =Assumptions!B22 | D16: =Assumptions!B22 | E16: =Assumptions!B22 | F16: =Assumptions!B22 | G16: =Assumptions!B22 | H16: =Assumptions!B22 | I16: =Assumptions!B22 | J16: =Assumptions!B22 | K16: =Assumptions!B22 | L16: =Assumptions!B22 | M16: =Assumptions!B22 | N16: =Assumptions!B22 | O16: =Assumptions!B22 | P16: =Assumptions!B22 | Q16: =Assumptions!B22 | R16: =Assumptions!B22 | S16: =Assumptions!B22 | T16: =Assumptions!B22 | U16: =Assumptions!B22 | V16: =Assumptions!B22 | W16: =Assumptions!B22 | X16: =Assumptions!B22 | Y16: =Assumptions!B22 | Z16: =SUM(B16:Y16)
A17: Revenue | B17: =B15*Assumptions!B22 | C17: =C15*Assumptions!B22 | D17: =D15*Assumptions!B22 | E17: =E15*Assumptions!B22 | F17: =F15*Assumptions!B22 | G17: =G15*Assumptions!B22 | H17: =H15*Assumptions!B22 | I17: =I15*Assumptions!B22 | J17: =J15*Assumptions!B22 | K17: =K15*Assumptions!B22 | L17: =L15*Assumptions!B22 | M17: =M15*Assumptions!B22 | N17: =N15*Assumptions!B22 | O17: =O15*Assumptions!B22 | P17: =P15*Assumptions!B22 | Q17: =Q15*Assumptions!B22 | R17: =R15*Assumptions!B22 | S17: =S15*Assumptions!B22 | T17: =T15*Assumptions!B22 | U17: =U15*Assumptions!B22 | V17: =V15*Assumptions!B22 | W17: =W15*Assumptions!B22 | X17: =X15*Assumptions!B22 | Y17: =Y15*Assumptions!B22 | Z17: =SUM(B17:Y17)
A18: LED Therapy (Free with Smoothie)
A19: Sessions (self-service) | B19: ='Growth Curves'!B5 | C19: ='Growth Curves'!C5 | D19: ='Growth Curves'!D5 | E19: ='Growth Curves'!E5 | F19: ='Growth Curves'!F5 | G19: ='Growth Curves'!G5 | H19: ='Growth Curves'!H5 | I19: ='Growth Curves'!I5 | ... Y19: ='Growth Curves'!Y5 | Z19: =SUM(B19:Y19)
A20: Price/session | B20: =Assumptions!B24 | C20: =Assumptions!B24 | D20: =Assumptions!B24 | E20: =Assumptions!B24 | F20: =Assumptions!B24 | G20: =Assumptions!B24 | H20: =Assumptions!B24 | I20: =Assumptions!B24 | J20: =Assumptions!B24 | K20: =Assumptions!B24 | L20: =Assumptions!B24 | M20: =Assumptions!B24 | N20: =Assumptions!B24 | O20: =Assumptions!B24 | P20: =Assumptions!B24 | Q20: =Assumptions!B24 | R20: =Assumptions!B24 | S20: =Assumptions!B24 | T20: =Assumptions!B24 | U20: =Assumptions!B24 | V20: =Assumptions!B24 | W20: =Assumptions!B24 | X20: =Assumptions!B24 | Y20: =Assumptions!B24 | Z20: =SUM(B20:Y20)
A21: Revenue (EUR 0 — free amenity) | B21: =B19*Assumptions!B24 | C21: =C19*Assumptions!B24 | D21: =D19*Assumptions!B24 | E21: =E19*Assumptions!B24 | F21: =F19*Assumptions!B24 | G21: =G19*Assumptions!B24 | H21: =H19*Assumptions!B24 | I21: =I19*Assumptions!B24 | J21: =J19*Assumptions!B24 | K21: =K19*Assumptions!B24 | L21: =L19*Assumptions!B24 | M21: =M19*Assumptions!B24 | N21: =N19*Assumptions!B24 | O21: =O19*Assumptions!B24 | P21: =P19*Assumptions!B24 | Q21: =Q19*Assumptions!B24 | R21: =R19*Assumptions!B24 | S21: =S19*Assumptions!B24 | T21: =T19*Assumptions!B24 | U21: =U19*Assumptions!B24 | V21: =V19*Assumptions!B24 | W21: =W19*Assumptions!B24 | X21: =X19*Assumptions!B24 | Y21: =Y19*Assumptions!B24 | Z21: =SUM(B21:Y21)
A22: Smoothie Bar
A23: Units sold | B23: ='Growth Curves'!B6 | C23: ='Growth Curves'!C6 | D23: ='Growth Curves'!D6 | E23: ='Growth Curves'!E6 | F23: ='Growth Curves'!F6 | G23: ='Growth Curves'!G6 | H23: ='Growth Curves'!H6 | I23: ='Growth Curves'!I6 | ... Y23: ='Growth Curves'!Y6 | Z23: =SUM(B23:Y23)
A24: Price/smoothie | B24: =Assumptions!B26 | C24: =Assumptions!B26 | D24: =Assumptions!B26 | E24: =Assumptions!B26 | F24: =Assumptions!B26 | G24: =Assumptions!B26 | H24: =Assumptions!B26 | I24: =Assumptions!B26 | J24: =Assumptions!B26 | K24: =Assumptions!B26 | L24: =Assumptions!B26 | M24: =Assumptions!B26 | N24: =Assumptions!B26 | O24: =Assumptions!B26 | P24: =Assumptions!B26 | Q24: =Assumptions!B26 | R24: =Assumptions!B26 | S24: =Assumptions!B26 | T24: =Assumptions!B26 | U24: =Assumptions!B26 | V24: =Assumptions!B26 | W24: =Assumptions!B26 | X24: =Assumptions!B26 | Y24: =Assumptions!B26 | Z24: =SUM(B24:Y24)
A25: Revenue | B25: =ROUND(B23*Assumptions!B26,0) | C25: =ROUND(C23*Assumptions!B26,0) | D25: =ROUND(D23*Assumptions!B26,0) | E25: =ROUND(E23*Assumptions!B26,0) | F25: =ROUND(F23*Assumptions!B26,0) | G25: =ROUND(G23*Assumptions!B26,0) | H25: =ROUND(H23*Assumptions!B26,0) | I25: =ROUND(I23*Assumptions!B26,0) | J25: =ROUND(J23*Assumptions!B26,0) | K25: =ROUND(K23*Assumptions!B26,0) | L25: =ROUND(L23*Assumptions!B26,0) | M25: =ROUND(M23*Assumptions!B26,0) | N25: =ROUND(N23*Assumptions!B26,0) | O25: =ROUND(O23*Assumptions!B26,0) | P25: =ROUND(P23*Assumptions!B26,0) | Q25: =ROUND(Q23*Assumptions!B26,0) | R25: =ROUND(R23*Assumptions!B26,0) | S25: =ROUND(S23*Assumptions!B26,0) | T25: =ROUND(T23*Assumptions!B26,0) | U25: =ROUND(U23*Assumptions!B26,0) | V25: =ROUND(V23*Assumptions!B26,0) | W25: =ROUND(W23*Assumptions!B26,0) | X25: =ROUND(X23*Assumptions!B26,0) | Y25: =ROUND(Y23*Assumptions!B26,0) | Z25: =SUM(B25:Y25)
A26: Community Events
A27: Event count | B27: ='Growth Curves'!B7 | C27: ='Growth Curves'!C7 | D27: ='Growth Curves'!D7 | E27: ='Growth Curves'!E7 | F27: ='Growth Curves'!F7 | G27: ='Growth Curves'!G7 | H27: ='Growth Curves'!H7 | I27: ='Growth Curves'!I7 | ... Y27: ='Growth Curves'!Y7 | Z27: =SUM(B27:Y27)
A28: Avg attendees/event | B28: ='Growth Curves'!B8 | C28: ='Growth Curves'!C8 | D28: ='Growth Curves'!D8 | E28: ='Growth Curves'!E8 | F28: ='Growth Curves'!F8 | G28: ='Growth Curves'!G8 | H28: ='Growth Curves'!H8 | I28: ='Growth Curves'!I8 | ... Y28: ='Growth Curves'!Y8 | Z28: =SUM(B28:Y28)
A29: Total attendees | B29: =B27*B28 | C29: =C27*C28 | D29: =D27*D28 | E29: =E27*E28 | F29: =F27*F28 | G29: =G27*G28 | H29: =H27*H28 | I29: =I27*I28 | ... Y29: =Y27*Y28 | Z29: =SUM(B29:Y29)
A30: Price/ticket | B30: =Assumptions!B28 | C30: =Assumptions!B28 | D30: =Assumptions!B28 | E30: =Assumptions!B28 | F30: =Assumptions!B28 | G30: =Assumptions!B28 | H30: =Assumptions!B28 | I30: =Assumptions!B28 | J30: =Assumptions!B28 | K30: =Assumptions!B28 | L30: =Assumptions!B28 | M30: =Assumptions!B28 | N30: =Assumptions!B28 | O30: =Assumptions!B28 | P30: =Assumptions!B28 | Q30: =Assumptions!B28 | R30: =Assumptions!B28 | S30: =Assumptions!B28 | T30: =Assumptions!B28 | U30: =Assumptions!B28 | V30: =Assumptions!B28 | W30: =Assumptions!B28 | X30: =Assumptions!B28 | Y30: =Assumptions!B28 | Z30: =SUM(B30:Y30)
A31: Revenue | B31: =B29*Assumptions!B28 | C31: =C29*Assumptions!B28 | D31: =D29*Assumptions!B28 | E31: =E29*Assumptions!B28 | F31: =F29*Assumptions!B28 | G31: =G29*Assumptions!B28 | H31: =H29*Assumptions!B28 | I31: =I29*Assumptions!B28 | J31: =J29*Assumptions!B28 | K31: =K29*Assumptions!B28 | L31: =L29*Assumptions!B28 | M31: =M29*Assumptions!B28 | N31: =N29*Assumptions!B28 | O31: =O29*Assumptions!B28 | P31: =P29*Assumptions!B28 | Q31: =Q29*Assumptions!B28 | R31: =R29*Assumptions!B28 | S31: =S29*Assumptions!B28 | T31: =T29*Assumptions!B28 | U31: =U29*Assumptions!B28 | V31: =V29*Assumptions!B28 | W31: =W29*Assumptions!B28 | X31: =X29*Assumptions!B28 | Y31: =Y29*Assumptions!B28 | Z31: =SUM(B31:Y31)
A32: Doctor SaaS (D1: EUR 99/mo)
A33: Clinics listed | B33: ='Growth Curves'!B9 | C33: ='Growth Curves'!C9 | D33: ='Growth Curves'!D9 | E33: ='Growth Curves'!E9 | F33: ='Growth Curves'!F9 | G33: ='Growth Curves'!G9 | H33: ='Growth Curves'!H9 | I33: ='Growth Curves'!I9 | ... Y33: ='Growth Curves'!Y9 | Z33: =SUM(B33:Y33)
A34: Fee/month | B34: =Assumptions!B31 | C34: =Assumptions!B31 | D34: =Assumptions!B31 | E34: =Assumptions!B31 | F34: =Assumptions!B31 | G34: =Assumptions!B31 | H34: =Assumptions!B31 | I34: =Assumptions!B31 | J34: =Assumptions!B31 | K34: =Assumptions!B31 | L34: =Assumptions!B31 | M34: =Assumptions!B31 | N34: =Assumptions!B31 | O34: =Assumptions!B31 | P34: =Assumptions!B31 | Q34: =Assumptions!B31 | R34: =Assumptions!B31 | S34: =Assumptions!B31 | T34: =Assumptions!B31 | U34: =Assumptions!B31 | V34: =Assumptions!B31 | W34: =Assumptions!B31 | X34: =Assumptions!B31 | Y34: =Assumptions!B31 | Z34: =SUM(B34:Y34)
A35: Revenue | B35: =B33*Assumptions!B31 | C35: =C33*Assumptions!B31 | D35: =D33*Assumptions!B31 | E35: =E33*Assumptions!B31 | F35: =F33*Assumptions!B31 | G35: =G33*Assumptions!B31 | H35: =H33*Assumptions!B31 | I35: =I33*Assumptions!B31 | J35: =J33*Assumptions!B31 | K35: =K33*Assumptions!B31 | L35: =L33*Assumptions!B31 | M35: =M33*Assumptions!B31 | N35: =N33*Assumptions!B31 | O35: =O33*Assumptions!B31 | P35: =P33*Assumptions!B31 | Q35: =Q33*Assumptions!B31 | R35: =R33*Assumptions!B31 | S35: =S33*Assumptions!B31 | T35: =T33*Assumptions!B31 | U35: =U33*Assumptions!B31 | V35: =V33*Assumptions!B31 | W35: =W33*Assumptions!B31 | X35: =X33*Assumptions!B31 | Y35: =Y33*Assumptions!B31 | Z35: =SUM(B35:Y35)
A36: CGM Referral Commission (D3: EUR 15/user/mo — Premium 3-mo gate or add-on) | B36: =ROUND('Growth Curves'!B21*Assumptions!B140,0) | C36: =ROUND('Growth Curves'!C21*Assumptions!B140,0) | D36: =ROUND('Growth Curves'!D21*Assumptions!B140,0) | E36: =ROUND('Growth Curves'!E21*Assumptions!B140,0) | F36: =ROUND('Growth Curves'!F21*Assumptions!B140,0) | G36: =ROUND('Growth Curves'!G21*Assumptions!B140,0) | H36: =ROUND('Growth Curves'!H21*Assumptions!B140,0) | I36: =ROUND('Growth Curves'!I21*Assumptions!B140,0) | J36: =ROUND('Growth Curves'!J21*Assumptions!B140,0) | K36: =ROUND('Growth Curves'!K21*Assumptions!B140,0) | L36: =ROUND('Growth Curves'!L21*Assumptions!B140,0) | M36: =ROUND('Growth Curves'!M21*Assumptions!B140,0) | N36: =ROUND('Growth Curves'!N21*Assumptions!B140,0) | O36: =ROUND('Growth Curves'!O21*Assumptions!B140,0) | P36: =ROUND('Growth Curves'!P21*Assumptions!B140,0) | Q36: =ROUND('Growth Curves'!Q21*Assumptions!B140,0) | R36: =ROUND('Growth Curves'!R21*Assumptions!B140,0) | S36: =ROUND('Growth Curves'!S21*Assumptions!B140,0) | T36: =ROUND('Growth Curves'!T21*Assumptions!B140,0) | U36: =ROUND('Growth Curves'!U21*Assumptions!B140,0) | V36: =ROUND('Growth Curves'!V21*Assumptions!B140,0) | W36: =ROUND('Growth Curves'!W21*Assumptions!B140,0) | X36: =ROUND('Growth Curves'!X21*Assumptions!B140,0) | Y36: =ROUND('Growth Curves'!Y21*Assumptions!B140,0) | Z36: =SUM(B36:Y36)
A37: Restaurant (D2: Phase 2 — EUR 0) | B37: 0 | C37: 0 | D37: 0 | E37: 0 | F37: 0 | G37: 0 | H37: 0 | I37: 0 | J37: 0 | K37: 0 | L37: 0 | M37: 0 | N37: 0 | O37: 0 | P37: 0 | Q37: 0 | R37: 0 | S37: 0 | T37: 0 | U37: 0 | V37: 0 | W37: 0 | X37: 0 | Y37: 0 | Z37: =SUM(B37:Y37)
A38: Subscriptions (EX-01: blended monthly + annual recognition)
A39: Core (blended: monthly EUR 19 / annual EUR 190/yr) | B39: =ROUND('Growth Curves'!B18*((1-IF(1<=6,Assumptions!B131,IF(1<=11,Assumptions!B141,Assumptions!B132)))*Assumptions!B5+IF(1<=6,Assumptions!B131,IF(1<=11,Assumptions!B141,Assumptions!B132))*Assumptions!B128/12),0) | C39: =ROUND('Growth Curves'!C18*((1-IF(2<=6,Assumptions!B131,IF(2<=11,Assumptions!B141,Assumptions!B132)))*Assumptions!B5+IF(2<=6,Assumptions!B131,IF(2<=11,Assumptions!B141,Assumptions!B132))*Assumptions!B128/12),0) | D39: =ROUND('Growth Curves'!D18*((1-IF(3<=6,Assumptions!B131,IF(3<=11,Assumptions!B141,Assumptions!B132)))*Assumptions!B5+IF(3<=6,Assumptions!B131,IF(3<=11,Assumptions!B141,Assumptions!B132))*Assumptions!B128/12),0) | E39: =ROUND('Growth Curves'!E18*((1-IF(4<=6,Assumptions!B131,IF(4<=11,Assumptions!B141,Assumptions!B132)))*Assumptions!B5+IF(4<=6,Assumptions!B131,IF(4<=11,Assumptions!B141,Assumptions!B132))*Assumptions!B128/12),0) | F39: =ROUND('Growth Curves'!F18*((1-IF(5<=6,Assumptions!B131,IF(5<=11,Assumptions!B141,Assumptions!B132)))*Assumptions!B5+IF(5<=6,Assumptions!B131,IF(5<=11,Assumptions!B141,Assumptions!B132))*Assumptions!B128/12),0) | G39: =ROUND('Growth Curves'!G18*((1-IF(6<=6,Assumptions!B131,IF(6<=11,Assumptions!B141,Assumptions!B132)))*Assumptions!B5+IF(6<=6,Assumptions!B131,IF(6<=11,Assumptions!B141,Assumptions!B132))*Assumptions!B128/12),0) | H39: =ROUND('Growth Curves'!H18*((1-IF(7<=6,Assumptions!B131,IF(7<=11,Assumptions!B141,Assumptions!B132)))*Assumptions!B5+IF(7<=6,Assumptions!B131,IF(7<=11,Assumptions!B141,Assumptions!B132))*Assumptions!B128/12),0) | I39: =ROUND('Growth Curves'!I18*((1-IF(8<=6,Assumptions!B131,IF(8<=11,Assumptions!B141,Assumptions!B132)))*Assumptions!B5+IF(8<=6,Assumptions!B131,IF(8<=11,Assumptions!B141,Assumptions!B132))*Assumptions!B128/12),0) | J39: =ROUND('Growth Curves'!J18*((1-IF(9<=6,Assumptions!B131,IF(9<=11,Assumptions!B141,Assumptions!B132)))*Assumptions!B5+IF(9<=6,Assumptions!B131,IF(9<=11,Assumptions!B141,Assumptions!B132))*Assumptions!B128/12),0) | K39: =ROUND('Growth Curves'!K18*((1-IF(10<=6,Assumptions!B131,IF(10<=11,Assumptions!B141,Assumptions!B132)))*Assumptions!B5+IF(10<=6,Assumptions!B131,IF(10<=11,Assumptions!B141,Assumptions!B132))*Assumptions!B128/12),0) | L39: =ROUND('Growth Curves'!L18*((1-IF(11<=6,Assumptions!B131,IF(11<=11,Assumptions!B141,Assumptions!B132)))*Assumptions!B5+IF(11<=6,Assumptions!B131,IF(11<=11,Assumptions!B141,Assumptions!B132))*Assumptions!B128/12),0) | M39: =ROUND('Growth Curves'!M18*((1-IF(12<=6,Assumptions!B131,IF(12<=11,Assumptions!B141,Assumptions!B132)))*Assumptions!B5+IF(12<=6,Assumptions!B131,IF(12<=11,Assumptions!B141,Assumptions!B132))*Assumptions!B128/12),0) | N39: =ROUND('Growth Curves'!N18*((1-IF(13<=6,Assumptions!B131,IF(13<=11,Assumptions!B141,Assumptions!B132)))*Assumptions!B5+IF(13<=6,Assumptions!B131,IF(13<=11,Assumptions!B141,Assumptions!B132))*Assumptions!B128/12),0) | O39: =ROUND('Growth Curves'!O18*((1-IF(14<=6,Assumptions!B131,IF(14<=11,Assumptions!B141,Assumptions!B132)))*Assumptions!B5+IF(14<=6,Assumptions!B131,IF(14<=11,Assumptions!B141,Assumptions!B132))*Assumptions!B128/12),0) | P39: =ROUND('Growth Curves'!P18*((1-IF(15<=6,Assumptions!B131,IF(15<=11,Assumptions!B141,Assumptions!B132)))*Assumptions!B5+IF(15<=6,Assumptions!B131,IF(15<=11,Assumptions!B141,Assumptions!B132))*Assumptions!B128/12),0) | Q39: =ROUND('Growth Curves'!Q18*((1-IF(16<=6,Assumptions!B131,IF(16<=11,Assumptions!B141,Assumptions!B132)))*Assumptions!B5+IF(16<=6,Assumptions!B131,IF(16<=11,Assumptions!B141,Assumptions!B132))*Assumptions!B128/12),0) | R39: =ROUND('Growth Curves'!R18*((1-IF(17<=6,Assumptions!B131,IF(17<=11,Assumptions!B141,Assumptions!B132)))*Assumptions!B5+IF(17<=6,Assumptions!B131,IF(17<=11,Assumptions!B141,Assumptions!B132))*Assumptions!B128/12),0) | S39: =ROUND('Growth Curves'!S18*((1-IF(18<=6,Assumptions!B131,IF(18<=11,Assumptions!B141,Assumptions!B132)))*Assumptions!B5+IF(18<=6,Assumptions!B131,IF(18<=11,Assumptions!B141,Assumptions!B132))*Assumptions!B128/12),0) | T39: =ROUND('Growth Curves'!T18*((1-IF(19<=6,Assumptions!B131,IF(19<=11,Assumptions!B141,Assumptions!B132)))*Assumptions!B5+IF(19<=6,Assumptions!B131,IF(19<=11,Assumptions!B141,Assumptions!B132))*Assumptions!B128/12),0) | U39: =ROUND('Growth Curves'!U18*((1-IF(20<=6,Assumptions!B131,IF(20<=11,Assumptions!B141,Assumptions!B132)))*Assumptions!B5+IF(20<=6,Assumptions!B131,IF(20<=11,Assumptions!B141,Assumptions!B132))*Assumptions!B128/12),0) | V39: =ROUND('Growth Curves'!V18*((1-IF(21<=6,Assumptions!B131,IF(21<=11,Assumptions!B141,Assumptions!B132)))*Assumptions!B5+IF(21<=6,Assumptions!B131,IF(21<=11,Assumptions!B141,Assumptions!B132))*Assumptions!B128/12),0) | W39: =ROUND('Growth Curves'!W18*((1-IF(22<=6,Assumptions!B131,IF(22<=11,Assumptions!B141,Assumptions!B132)))*Assumptions!B5+IF(22<=6,Assumptions!B131,IF(22<=11,Assumptions!B141,Assumptions!B132))*Assumptions!B128/12),0) | X39: =ROUND('Growth Curves'!X18*((1-IF(23<=6,Assumptions!B131,IF(23<=11,Assumptions!B141,Assumptions!B132)))*Assumptions!B5+IF(23<=6,Assumptions!B131,IF(23<=11,Assumptions!B141,Assumptions!B132))*Assumptions!B128/12),0) | Y39: =ROUND('Growth Curves'!Y18*((1-IF(24<=6,Assumptions!B131,IF(24<=11,Assumptions!B141,Assumptions!B132)))*Assumptions!B5+IF(24<=6,Assumptions!B131,IF(24<=11,Assumptions!B141,Assumptions!B132))*Assumptions!B128/12),0) | Z39: =SUM(B39:Y39)
A40: Pro (blended: monthly EUR 49 / annual EUR 490/yr) | B40: =ROUND('Growth Curves'!B19*((1-IF(1<=6,Assumptions!B131,IF(1<=11,Assumptions!B141,Assumptions!B132)))*Assumptions!B6+IF(1<=6,Assumptions!B131,IF(1<=11,Assumptions!B141,Assumptions!B132))*Assumptions!B129/12),0) | C40: =ROUND('Growth Curves'!C19*((1-IF(2<=6,Assumptions!B131,IF(2<=11,Assumptions!B141,Assumptions!B132)))*Assumptions!B6+IF(2<=6,Assumptions!B131,IF(2<=11,Assumptions!B141,Assumptions!B132))*Assumptions!B129/12),0) | D40: =ROUND('Growth Curves'!D19*((1-IF(3<=6,Assumptions!B131,IF(3<=11,Assumptions!B141,Assumptions!B132)))*Assumptions!B6+IF(3<=6,Assumptions!B131,IF(3<=11,Assumptions!B141,Assumptions!B132))*Assumptions!B129/12),0) | E40: =ROUND('Growth Curves'!E19*((1-IF(4<=6,Assumptions!B131,IF(4<=11,Assumptions!B141,Assumptions!B132)))*Assumptions!B6+IF(4<=6,Assumptions!B131,IF(4<=11,Assumptions!B141,Assumptions!B132))*Assumptions!B129/12),0) | F40: =ROUND('Growth Curves'!F19*((1-IF(5<=6,Assumptions!B131,IF(5<=11,Assumptions!B141,Assumptions!B132)))*Assumptions!B6+IF(5<=6,Assumptions!B131,IF(5<=11,Assumptions!B141,Assumptions!B132))*Assumptions!B129/12),0) | G40: =ROUND('Growth Curves'!G19*((1-IF(6<=6,Assumptions!B131,IF(6<=11,Assumptions!B141,Assumptions!B132)))*Assumptions!B6+IF(6<=6,Assumptions!B131,IF(6<=11,Assumptions!B141,Assumptions!B132))*Assumptions!B129/12),0) | H40: =ROUND('Growth Curves'!H19*((1-IF(7<=6,Assumptions!B131,IF(7<=11,Assumptions!B141,Assumptions!B132)))*Assumptions!B6+IF(7<=6,Assumptions!B131,IF(7<=11,Assumptions!B141,Assumptions!B132))*Assumptions!B129/12),0) | I40: =ROUND('Growth Curves'!I19*((1-IF(8<=6,Assumptions!B131,IF(8<=11,Assumptions!B141,Assumptions!B132)))*Assumptions!B6+IF(8<=6,Assumptions!B131,IF(8<=11,Assumptions!B141,Assumptions!B132))*Assumptions!B129/12),0) | J40: =ROUND('Growth Curves'!J19*((1-IF(9<=6,Assumptions!B131,IF(9<=11,Assumptions!B141,Assumptions!B132)))*Assumptions!B6+IF(9<=6,Assumptions!B131,IF(9<=11,Assumptions!B141,Assumptions!B132))*Assumptions!B129/12),0) | K40: =ROUND('Growth Curves'!K19*((1-IF(10<=6,Assumptions!B131,IF(10<=11,Assumptions!B141,Assumptions!B132)))*Assumptions!B6+IF(10<=6,Assumptions!B131,IF(10<=11,Assumptions!B141,Assumptions!B132))*Assumptions!B129/12),0) | L40: =ROUND('Growth Curves'!L19*((1-IF(11<=6,Assumptions!B131,IF(11<=11,Assumptions!B141,Assumptions!B132)))*Assumptions!B6+IF(11<=6,Assumptions!B131,IF(11<=11,Assumptions!B141,Assumptions!B132))*Assumptions!B129/12),0) | M40: =ROUND('Growth Curves'!M19*((1-IF(12<=6,Assumptions!B131,IF(12<=11,Assumptions!B141,Assumptions!B132)))*Assumptions!B6+IF(12<=6,Assumptions!B131,IF(12<=11,Assumptions!B141,Assumptions!B132))*Assumptions!B129/12),0) | N40: =ROUND('Growth Curves'!N19*((1-IF(13<=6,Assumptions!B131,IF(13<=11,Assumptions!B141,Assumptions!B132)))*Assumptions!B6+IF(13<=6,Assumptions!B131,IF(13<=11,Assumptions!B141,Assumptions!B132))*Assumptions!B129/12),0) | O40: =ROUND('Growth Curves'!O19*((1-IF(14<=6,Assumptions!B131,IF(14<=11,Assumptions!B141,Assumptions!B132)))*Assumptions!B6+IF(14<=6,Assumptions!B131,IF(14<=11,Assumptions!B141,Assumptions!B132))*Assumptions!B129/12),0) | P40: =ROUND('Growth Curves'!P19*((1-IF(15<=6,Assumptions!B131,IF(15<=11,Assumptions!B141,Assumptions!B132)))*Assumptions!B6+IF(15<=6,Assumptions!B131,IF(15<=11,Assumptions!B141,Assumptions!B132))*Assumptions!B129/12),0) | Q40: =ROUND('Growth Curves'!Q19*((1-IF(16<=6,Assumptions!B131,IF(16<=11,Assumptions!B141,Assumptions!B132)))*Assumptions!B6+IF(16<=6,Assumptions!B131,IF(16<=11,Assumptions!B141,Assumptions!B132))*Assumptions!B129/12),0) | R40: =ROUND('Growth Curves'!R19*((1-IF(17<=6,Assumptions!B131,IF(17<=11,Assumptions!B141,Assumptions!B132)))*Assumptions!B6+IF(17<=6,Assumptions!B131,IF(17<=11,Assumptions!B141,Assumptions!B132))*Assumptions!B129/12),0) | S40: =ROUND('Growth Curves'!S19*((1-IF(18<=6,Assumptions!B131,IF(18<=11,Assumptions!B141,Assumptions!B132)))*Assumptions!B6+IF(18<=6,Assumptions!B131,IF(18<=11,Assumptions!B141,Assumptions!B132))*Assumptions!B129/12),0) | T40: =ROUND('Growth Curves'!T19*((1-IF(19<=6,Assumptions!B131,IF(19<=11,Assumptions!B141,Assumptions!B132)))*Assumptions!B6+IF(19<=6,Assumptions!B131,IF(19<=11,Assumptions!B141,Assumptions!B132))*Assumptions!B129/12),0) | U40: =ROUND('Growth Curves'!U19*((1-IF(20<=6,Assumptions!B131,IF(20<=11,Assumptions!B141,Assumptions!B132)))*Assumptions!B6+IF(20<=6,Assumptions!B131,IF(20<=11,Assumptions!B141,Assumptions!B132))*Assumptions!B129/12),0) | V40: =ROUND('Growth Curves'!V19*((1-IF(21<=6,Assumptions!B131,IF(21<=11,Assumptions!B141,Assumptions!B132)))*Assumptions!B6+IF(21<=6,Assumptions!B131,IF(21<=11,Assumptions!B141,Assumptions!B132))*Assumptions!B129/12),0) | W40: =ROUND('Growth Curves'!W19*((1-IF(22<=6,Assumptions!B131,IF(22<=11,Assumptions!B141,Assumptions!B132)))*Assumptions!B6+IF(22<=6,Assumptions!B131,IF(22<=11,Assumptions!B141,Assumptions!B132))*Assumptions!B129/12),0) | X40: =ROUND('Growth Curves'!X19*((1-IF(23<=6,Assumptions!B131,IF(23<=11,Assumptions!B141,Assumptions!B132)))*Assumptions!B6+IF(23<=6,Assumptions!B131,IF(23<=11,Assumptions!B141,Assumptions!B132))*Assumptions!B129/12),0) | Y40: =ROUND('Growth Curves'!Y19*((1-IF(24<=6,Assumptions!B131,IF(24<=11,Assumptions!B141,Assumptions!B132)))*Assumptions!B6+IF(24<=6,Assumptions!B131,IF(24<=11,Assumptions!B141,Assumptions!B132))*Assumptions!B129/12),0) | Z40: =SUM(B40:Y40)
A41: Premium (blended: monthly EUR 99 / annual EUR 990/yr) | B41: =ROUND('Growth Curves'!B20*((1-IF(1<=6,Assumptions!B131,IF(1<=11,Assumptions!B141,Assumptions!B132)))*Assumptions!B7+IF(1<=6,Assumptions!B131,IF(1<=11,Assumptions!B141,Assumptions!B132))*Assumptions!B130/12),0) | C41: =ROUND('Growth Curves'!C20*((1-IF(2<=6,Assumptions!B131,IF(2<=11,Assumptions!B141,Assumptions!B132)))*Assumptions!B7+IF(2<=6,Assumptions!B131,IF(2<=11,Assumptions!B141,Assumptions!B132))*Assumptions!B130/12),0) | D41: =ROUND('Growth Curves'!D20*((1-IF(3<=6,Assumptions!B131,IF(3<=11,Assumptions!B141,Assumptions!B132)))*Assumptions!B7+IF(3<=6,Assumptions!B131,IF(3<=11,Assumptions!B141,Assumptions!B132))*Assumptions!B130/12),0) | E41: =ROUND('Growth Curves'!E20*((1-IF(4<=6,Assumptions!B131,IF(4<=11,Assumptions!B141,Assumptions!B132)))*Assumptions!B7+IF(4<=6,Assumptions!B131,IF(4<=11,Assumptions!B141,Assumptions!B132))*Assumptions!B130/12),0) | F41: =ROUND('Growth Curves'!F20*((1-IF(5<=6,Assumptions!B131,IF(5<=11,Assumptions!B141,Assumptions!B132)))*Assumptions!B7+IF(5<=6,Assumptions!B131,IF(5<=11,Assumptions!B141,Assumptions!B132))*Assumptions!B130/12),0) | G41: =ROUND('Growth Curves'!G20*((1-IF(6<=6,Assumptions!B131,IF(6<=11,Assumptions!B141,Assumptions!B132)))*Assumptions!B7+IF(6<=6,Assumptions!B131,IF(6<=11,Assumptions!B141,Assumptions!B132))*Assumptions!B130/12),0) | H41: =ROUND('Growth Curves'!H20*((1-IF(7<=6,Assumptions!B131,IF(7<=11,Assumptions!B141,Assumptions!B132)))*Assumptions!B7+IF(7<=6,Assumptions!B131,IF(7<=11,Assumptions!B141,Assumptions!B132))*Assumptions!B130/12),0) | I41: =ROUND('Growth Curves'!I20*((1-IF(8<=6,Assumptions!B131,IF(8<=11,Assumptions!B141,Assumptions!B132)))*Assumptions!B7+IF(8<=6,Assumptions!B131,IF(8<=11,Assumptions!B141,Assumptions!B132))*Assumptions!B130/12),0) | J41: =ROUND('Growth Curves'!J20*((1-IF(9<=6,Assumptions!B131,IF(9<=11,Assumptions!B141,Assumptions!B132)))*Assumptions!B7+IF(9<=6,Assumptions!B131,IF(9<=11,Assumptions!B141,Assumptions!B132))*Assumptions!B130/12),0) | K41: =ROUND('Growth Curves'!K20*((1-IF(10<=6,Assumptions!B131,IF(10<=11,Assumptions!B141,Assumptions!B132)))*Assumptions!B7+IF(10<=6,Assumptions!B131,IF(10<=11,Assumptions!B141,Assumptions!B132))*Assumptions!B130/12),0) | L41: =ROUND('Growth Curves'!L20*((1-IF(11<=6,Assumptions!B131,IF(11<=11,Assumptions!B141,Assumptions!B132)))*Assumptions!B7+IF(11<=6,Assumptions!B131,IF(11<=11,Assumptions!B141,Assumptions!B132))*Assumptions!B130/12),0) | M41: =ROUND('Growth Curves'!M20*((1-IF(12<=6,Assumptions!B131,IF(12<=11,Assumptions!B141,Assumptions!B132)))*Assumptions!B7+IF(12<=6,Assumptions!B131,IF(12<=11,Assumptions!B141,Assumptions!B132))*Assumptions!B130/12),0) | N41: =ROUND('Growth Curves'!N20*((1-IF(13<=6,Assumptions!B131,IF(13<=11,Assumptions!B141,Assumptions!B132)))*Assumptions!B7+IF(13<=6,Assumptions!B131,IF(13<=11,Assumptions!B141,Assumptions!B132))*Assumptions!B130/12),0) | O41: =ROUND('Growth Curves'!O20*((1-IF(14<=6,Assumptions!B131,IF(14<=11,Assumptions!B141,Assumptions!B132)))*Assumptions!B7+IF(14<=6,Assumptions!B131,IF(14<=11,Assumptions!B141,Assumptions!B132))*Assumptions!B130/12),0) | P41: =ROUND('Growth Curves'!P20*((1-IF(15<=6,Assumptions!B131,IF(15<=11,Assumptions!B141,Assumptions!B132)))*Assumptions!B7+IF(15<=6,Assumptions!B131,IF(15<=11,Assumptions!B141,Assumptions!B132))*Assumptions!B130/12),0) | Q41: =ROUND('Growth Curves'!Q20*((1-IF(16<=6,Assumptions!B131,IF(16<=11,Assumptions!B141,Assumptions!B132)))*Assumptions!B7+IF(16<=6,Assumptions!B131,IF(16<=11,Assumptions!B141,Assumptions!B132))*Assumptions!B130/12),0) | R41: =ROUND('Growth Curves'!R20*((1-IF(17<=6,Assumptions!B131,IF(17<=11,Assumptions!B141,Assumptions!B132)))*Assumptions!B7+IF(17<=6,Assumptions!B131,IF(17<=11,Assumptions!B141,Assumptions!B132))*Assumptions!B130/12),0) | S41: =ROUND('Growth Curves'!S20*((1-IF(18<=6,Assumptions!B131,IF(18<=11,Assumptions!B141,Assumptions!B132)))*Assumptions!B7+IF(18<=6,Assumptions!B131,IF(18<=11,Assumptions!B141,Assumptions!B132))*Assumptions!B130/12),0) | T41: =ROUND('Growth Curves'!T20*((1-IF(19<=6,Assumptions!B131,IF(19<=11,Assumptions!B141,Assumptions!B132)))*Assumptions!B7+IF(19<=6,Assumptions!B131,IF(19<=11,Assumptions!B141,Assumptions!B132))*Assumptions!B130/12),0) | U41: =ROUND('Growth Curves'!U20*((1-IF(20<=6,Assumptions!B131,IF(20<=11,Assumptions!B141,Assumptions!B132)))*Assumptions!B7+IF(20<=6,Assumptions!B131,IF(20<=11,Assumptions!B141,Assumptions!B132))*Assumptions!B130/12),0) | V41: =ROUND('Growth Curves'!V20*((1-IF(21<=6,Assumptions!B131,IF(21<=11,Assumptions!B141,Assumptions!B132)))*Assumptions!B7+IF(21<=6,Assumptions!B131,IF(21<=11,Assumptions!B141,Assumptions!B132))*Assumptions!B130/12),0) | W41: =ROUND('Growth Curves'!W20*((1-IF(22<=6,Assumptions!B131,IF(22<=11,Assumptions!B141,Assumptions!B132)))*Assumptions!B7+IF(22<=6,Assumptions!B131,IF(22<=11,Assumptions!B141,Assumptions!B132))*Assumptions!B130/12),0) | X41: =ROUND('Growth Curves'!X20*((1-IF(23<=6,Assumptions!B131,IF(23<=11,Assumptions!B141,Assumptions!B132)))*Assumptions!B7+IF(23<=6,Assumptions!B131,IF(23<=11,Assumptions!B141,Assumptions!B132))*Assumptions!B130/12),0) | Y41: =ROUND('Growth Curves'!Y20*((1-IF(24<=6,Assumptions!B131,IF(24<=11,Assumptions!B141,Assumptions!B132)))*Assumptions!B7+IF(24<=6,Assumptions!B131,IF(24<=11,Assumptions!B141,Assumptions!B132))*Assumptions!B130/12),0) | Z41: =SUM(B41:Y41)
...

Sheet Assumptions
A1: alche — P&L Assumptions v4
A2: Change any value here → P&L auto-recalculates. All persona findings incorporated.
A4: SUBSCRIPTION MODEL
A5: Core tier price (EUR/mo) | B5: 19 | C5: Entry tier
A6: Pro tier price (EUR/mo) | B6: 49 | C6: Sweet spot
A7: Premium tier price (EUR/mo) | B7: 99 | C7: Highest ARPU
A8: Monthly churn rate | B8: 0.08 | C8: 8% — locked data
A9: Core tier share | B9: 0.52 | C9: 52%
A10: Pro tier share | B10: 0.38 | C10: 38%
A11: Premium tier share | B11: 0.1 | C11: 10%
A13: SUBSCRIBER GROWTH (new subs/month)
A14: M1-M3 | B14: 0 | C14: Pre-launch — no app yet
A15: M4-M6 | B15: 15 | C15: Product launch
A16: M7-M9 | B16: 22 | C16: Growth acceleration
A17: M10-M12 | B17: 28 | C17: Marketing ramp
A18: M13-M18 | B18: 32 | C18: Scaling
A19: M19-M24 | B19: 38 | C19: Scaling phase
A21: PRODUCT PRICING
A22: Retail product price (EUR) | B22: 49 | C22: R10 validated
A23: Retail product COGS (EUR/unit) | B23: 23.5 | C23: R10: wholesale ~48% of retail
A24: LED session price (EUR) | B24: 0 | C24: Free with smoothie purchase
A25: LED practitioner cost (EUR) | B25: 0 | C25: Self-service — no practitioner
A26: Smoothie avg price (EUR) | B26: 9.67 | C26: R2 Cost Analysis
A27: Smoothie COGS rate | B27: 0.35 | C27: 35% ingredients+packaging (R2)
A28: Event ticket price (EUR) | B28: 35 | C28: Community events
A29: Event fixed cost (EUR) | B29: 250 | C29: Venue per event
A30: Ticketing platform fee | B30: 0.07 | C30: 7% Luma/Eventbrite
A31: Doctor SaaS fee (EUR/mo) | B31: 99 | C31: D1: StGB 299a safe
A32: Doctor verify cost (EUR) | B32: 25 | C32: Per new doctor
A33: Doctor max clinics | B33: 20 | C33: Cap M1-24
A35: COST RATES
A36: Waste — blended rate | B36: 0.055 | C36: D7: capsules 4%, powders 7%
A37: 3PL fulfillment (EUR/unit) | B37: 2.5 | C37: Retail products only
A38: Stripe fee rate | B38: 0.029 | C38: 2.9%
A39: AI API per user (EUR/mo) | B39: 0.35 | C39: D6: hybrid Claude+Gemini
A40: Refund/returns reserve | B40: 0.015 | C40: 1.5% of product revenue
A41: Bad debt provision | B41: 0.005 | C41: P5: 0.5% of total revenue
A43: PAYROLL
A44: Founder gross salary (each) | B44: 2000 | C44: EUR 24K/yr gross each (Timu + Daria)
A45: Employer multiplier | B45: 1.25 | C45: P2/P7: incl. U1/U2/U3 (was 1.22)
...

Sheet Growth Curves
A1: alche — Monthly Growth Curves (Input Data)
A2: Edit numbers to change unit forecasts. P&L formulas reference these cells.
A3: Metric | B3: M1 | C3: M2 | D3: M3 | E3: M4 | F3: M5 | G3: M6 | H3: M7 | I3: M8 | J3: M9 | K3: M10 | L3: M11 | M3: M12 | N3: M13 | O3: M14 | P3: M15 | Q3: M16 | R3: M17 | S3: M18 | T3: M19 | U3: M20 | V3: M21 | W3: M22 | X3: M23 | Y3: M24
A4: Retail Units | B4: 0 | C4: 0 | D4: 0 | E4: 50 | F4: 100 | G4: 150 | H4: 250 | I4: 350 | J4: 450 | K4: 600 | L4: 750 | M4: 900 | N4: 1100 | O4: 1300 | P4: 1500 | Q4: 1800 | R4: 2100 | S4: 2400 | T4: 2700 | U4: 3000 | V4: 3400 | W4: 3800 | X4: 4200 | Y4: 4600
A5: LED Sessions | B5: 0 | C5: 0 | D5: 0 | E5: 10 | F5: 20 | G5: 35 | H5: 50 | I5: 65 | J5: 80 | K5: 100 | L5: 120 | M5: 140 | N5: 160 | O5: 180 | P5: 200 | Q5: 220 | R5: 240 | S5: 260 | T5: 280 | U5: 300 | V5: 300 | W5: 300 | X5: 300 | Y5: 300
A6: Smoothie Units | B6: 0 | C6: 0 | D6: 0 | E6: 100 | F6: 150 | G6: 250 | H6: 350 | I6: 450 | J6: 550 | K6: 650 | L6: 750 | M6: 850 | N6: 950 | O6: 1050 | P6: 1150 | Q6: 1250 | R6: 1350 | S6: 1450 | T6: 1550 | U6: 1650 | V6: 1750 | W6: 1850 | X6: 1950 | Y6: 2000
A7: Event Count | B7: 0 | C7: 0 | D7: 0 | E7: 1 | F7: 1 | G7: 2 | H7: 2 | I7: 3 | J7: 3 | K7: 3 | L7: 3 | M7: 3 | N7: 3 | O7: 3 | P7: 4 | Q7: 4 | R7: 4 | S7: 4 | T7: 4 | U7: 5 | V7: 5 | W7: 5 | X7: 5 | Y7: 5
A8: Event Avg Attendees | B8: 0 | C8: 0 | D8: 0 | E8: 12 | F8: 15 | G8: 15 | H8: 18 | I8: 18 | J8: 18 | K8: 20 | L8: 20 | M8: 20 | N8: 22 | O8: 22 | P8: 22 | Q8: 22 | R8: 24 | S8: 24 | T8: 25 | U8: 25 | V8: 25 | W8: 25 | X8: 25 | Y8: 25
A9: Doctor Clinics | B9: 0 | C9: 0 | D9: 0 | E9: 0 | F9: 0 | G9: 2 | H9: 5 | I9: 8 | J9: 10 | K9: 12 | L9: 15 | M9: 17 | N9: 18 | O9: 19 | P9: 20 | Q9: 20 | R9: 20 | S9: 20 | T9: 20 | U9: 20 | V9: 20 | W9: 20 | X9: 20 | Y9: 20
A10: Marketing Spend (EUR) | B10: 50 | C10: 50 | D10: 100 | E10: 200 | F10: 400 | G10: 600 | H10: 800 | I10: 800 | J10: 1000 | K10: 1200 | L10: 1400 | M10: 1400 | N10: 1800 | O10: 1800 | P10: 2000 | Q10: 2000 | R10: 2200 | S10: 2200 | T10: 2500 | U10: 2500 | V10: 2800 | W10: 2800 | X10: 3000 | Y10: 3000
A11: KSK-Eligible Freelancer Spend | B11: 500 | C11: 500 | D11: 500 | E11: 500 | F11: 800 | G11: 800 | H11: 800 | I11: 800 | J11: 800 | K11: 800 | L11: 800 | M11: 800 | N11: 800 | O11: 800 | P11: 800 | Q11: 800 | R11: 800 | S11: 800 | T11: 800 | U11: 800 | V11: 800 | W11: 800 | X11: 800 | Y11: 800
A12: New Doctors (delta) | B12: 0 | C12: =MAX(0,C9-B9) | D12: =MAX(0,D9-C9) | E12: =MAX(0,E9-D9) | F12: =MAX(0,F9-E9) | G12: =MAX(0,G9-F9) | H12: =MAX(0,H9-G9) | I12: =MAX(0,I9-H9) | J12: =MAX(0,J9-I9) | ... Y12: =MAX(0,Y9-X9)
A14: SUBSCRIBER MODEL
A15: New Subs Rate | B15: =IF(1<=3,Assumptions!B14,IF(1<=6,Assumptions!B15,IF(1<=9,Assumptions!B16,IF(1<=12,Assumptions!B17,IF(1<=18,Assumptions!B18,Assumptions!B19))))) | C15: =IF(2<=3,Assumptions!B14,IF(2<=6,Assumptions!B15,IF(2<=9,Assumptions!B16,IF(2<=12,Assumptions!B17,IF(2<=18,Assumptions!B18,Assumptions!B19))))) | D15: =IF(3<=3,Assumptions!B14,IF(3<=6,Assumptions!B15,IF(3<=9,Assumptions!B16,IF(3<=12,Assumptions!B17,IF(3<=18,Assumptions!B18,Assumptions!B19))))) | E15: =IF(4<=3,Assumptions!B14,IF(4<=6,Assumptions!B15,IF(4<=9,Assumptions!B16,IF(4<=12,Assumptions!B17,IF(4<=18,Assumptions!B18,Assumptions!B19))))) | F15: =IF(5<=3,Assumptions!B14,IF(5<=6,Assumptions!B15,IF(5<=9,Assumptions!B16,IF(5<=12,Assumptions!B17,IF(5<=18,Assumptions!B18,Assumptions!B19))))) | G15: =IF(6<=3,Assumptions!B14,IF(6<=6,Assumptions!B15,IF(6<=9,Assumptions!B16,IF(6<=12,Assumptions!B17,IF(6<=18,Assumptions!B18,Assumptions!B19))))) | H15: =IF(7<=3,Assumptions!B14,IF(7<=6,Assumptions!B15,IF(7<=9,Assumptions!B16,IF(7<=12,Assumptions!B17,IF(7<=18,Assumptions!B18,Assumptions!B19))))) | I15: =IF(8<=3,Assumptions!B14,IF(8<=6,Assumptions!B15,IF(8<=9,Assumptions!B16,IF(8<=12,Assumptions!B17,IF(8<=18,Assumptions!B18,Assumptions!B19))))) | J15: =IF(9<=3,Assumptions!B14,IF(9<=6,Assumptions!B15,IF(9<=9,Assumptions!B16,IF(9<=12,Assumptions!B17,IF(9<=18,Assumptions!B18,Assumptions!B19))))) | K15: =IF(10<=3,Assumptions!B14,IF(10<=6,Assumptions!B15,IF(10<=9,Assumptions!B16,IF(10<=12,Assumptions!B17,IF(10<=18,Assumptions!B18,Assumptions!B19))))) | L15: =IF(11<=3,Assumptions!B14,IF(11<=6,Assumptions!B15,IF(11<=9,Assumptions!B16,IF(11<=12,Assumptions!B17,IF(11<=18,Assumptions!B18,Assumptions!B19))))) | M15: =IF(12<=3,Assumptions!B14,IF(12<=6,Assumptions!B15,IF(12<=9,Assumptions!B16,IF(12<=12,Assumptions!B17,IF(12<=18,Assumptions!B18,Assumptions!B19))))) | N15: =IF(13<=3,Assumptions!B14,IF(13<=6,Assumptions!B15,IF(13<=9,Assumptions!B16,IF(13<=12,Assumptions!B17,IF(13<=18,Assumptions!B18,Assumptions!B19))))) | O15: =IF(14<=3,Assumptions!B14,IF(14<=6,Assumptions!B15,IF(14<=9,Assumptions!B16,IF(14<=12,Assumptions!B17,IF(14<=18,Assumptions!B18,Assumptions!B19))))) | P15: =IF(15<=3,Assumptions!B14,IF(15<=6,Assumptions!B15,IF(15<=9,Assumptions!B16,IF(15<=12,Assumptions!B17,IF(15<=18,Assumptions!B18,Assumptions!B19))))) | Q15: =IF(16<=3,Assumptions!B14,IF(16<=6,Assumptions!B15,IF(16<=9,Assumptions!B16,IF(16<=12,Assumptions!B17,IF(16<=18,Assumptions!B18,Assumptions!B19))))) | R15: =IF(17<=3,Assumptions!B14,IF(17<=6,Assumptions!B15,IF(17<=9,Assumptions!B16,IF(17<=12,Assumptions!B17,IF(17<=18,Assumptions!B18,Assumptions!B19))))) | S15: =IF(18<=3,Assumptions!B14,IF(18<=6,Assumptions!B15,IF(18<=9,Assumptions!B16,IF(18<=12,Assumptions!B17,IF(18<=18,Assumptions!B18,Assumptions!B19))))) | T15: =IF(19<=3,Assumptions!B14,IF(19<=6,Assumptions!B15,IF(19<=9,Assumptions!B16,IF(19<=12,Assumptions!B17,IF(19<=18,Assumptions!B18,Assumptions!B19))))) | U15: =IF(20<=3,Assumptions!B14,IF(20<=6,Assumptions!B15,IF(20<=9,Assumptions!B16,IF(20<=12,Assumptions!B17,IF(20<=18,Assumptions!B18,Assumptions!B19))))) | V15: =IF(21<=3,Assumptions!B14,IF(21<=6,Assumptions!B15,IF(21<=9,Assumptions!B16,IF(21<=12,Assumptions!B17,IF(21<=18,Assumptions!B18,Assumptions!B19))))) | W15: =IF(22<=3,Assumptions!B14,IF(22<=6,Assumptions!B15,IF(22<=9,Assumptions!B16,IF(22<=12,Assumptions!B17,IF(22<=18,Assumptions!B18,Assumptions!B19))))) | X15: =IF(23<=3,Assumptions!B14,IF(23<=6,Assumptions!B15,IF(23<=9,Assumptions!B16,IF(23<=12,Assumptions!B17,IF(23<=18,Assumptions!B18,Assumptions!B19))))) | Y15: =IF(24<=3,Assumptions!B14,IF(24<=6,Assumptions!B15,IF(24<=9,Assumptions!B16,IF(24<=12,Assumptions!B17,IF(24<=18,Assumptions!B18,Assumptions!B19)))))
A16: Churned Subs | B16: 0 | C16: =ROUND(B17*Assumptions!B8,0) | D16: =ROUND(C17*Assumptions!B8,0) | E16: =ROUND(D17*Assumptions!B8,0) | F16: =ROUND(E17*Assumptions!B8,0) | G16: =ROUND(F17*Assumptions!B8,0) | H16: =ROUND(G17*Assumptions!B8,0) | I16: =ROUND(H17*Assumptions!B8,0) | J16: =ROUND(I17*Assumptions!B8,0) | K16: =ROUND(J17*Assumptions!B8,0) | L16: =ROUND(K17*Assumptions!B8,0) | M16: =ROUND(L17*Assumptions!B8,0) | N16: =ROUND(M17*Assumptions!B8,0) | O16: =ROUND(N17*Assumptions!B8,0) | P16: =ROUND(O17*Assumptions!B8,0) | Q16: =ROUND(P17*Assumptions!B8,0) | R16: =ROUND(Q17*Assumptions!B8,0) | S16: =ROUND(R17*Assumptions!B8,0) | T16: =ROUND(S17*Assumptions!B8,0) | U16: =ROUND(T17*Assumptions!B8,0) | V16: =ROUND(U17*Assumptions!B8,0) | W16: =ROUND(V17*Assumptions!B8,0) | X16: =ROUND(W17*Assumptions!B8,0) | Y16: =ROUND(X17*Assumptions!B8,0)
A17: Total Subscribers | B17: =MAX(0,B15-B16) | C17: =MAX(0,B17-C16+C15) | D17: =MAX(0,C17-D16+D15) | E17: =MAX(0,D17-E16+E15) | F17: =MAX(0,E17-F16+F15) | G17: =MAX(0,F17-G16+G15) | H17: =MAX(0,G17-H16+H15) | I17: =MAX(0,H17-I16+I15) | J17: =MAX(0,I17-J16+J15) | ... Y17: =MAX(0,X17-Y16+Y15)
A18: Core Subs (52%) | B18: =ROUND(B17*Assumptions!B9,0) | C18: =ROUND(C17*Assumptions!B9,0) | D18: =ROUND(D17*Assumptions!B9,0) | E18: =ROUND(E17*Assumptions!B9,0) | F18: =ROUND(F17*Assumptions!B9,0) | G18: =ROUND(G17*Assumptions!B9,0) | H18: =ROUND(H17*Assumptions!B9,0) | I18: =ROUND(I17*Assumptions!B9,0) | J18: =ROUND(J17*Assumptions!B9,0) | K18: =ROUND(K17*Assumptions!B9,0) | L18: =ROUND(L17*Assumptions!B9,0) | M18: =ROUND(M17*Assumptions!B9,0) | N18: =ROUND(N17*Assumptions!B9,0) | O18: =ROUND(O17*Assumptions!B9,0) | P18: =ROUND(P17*Assumptions!B9,0) | Q18: =ROUND(Q17*Assumptions!B9,0) | R18: =ROUND(R17*Assumptions!B9,0) | S18: =ROUND(S17*Assumptions!B9,0) | T18: =ROUND(T17*Assumptions!B9,0) | U18: =ROUND(U17*Assumptions!B9,0) | V18: =ROUND(V17*Assumptions!B9,0) | W18: =ROUND(W17*Assumptions!B9,0) | X18: =ROUND(X17*Assumptions!B9,0) | Y18: =ROUND(Y17*Assumptions!B9,0)
A19: Pro Subs (38%) | B19: =ROUND(B17*Assumptions!B10,0) | C19: =ROUND(C17*Assumptions!B10,0) | D19: =ROUND(D17*Assumptions!B10,0) | E19: =ROUND(E17*Assumptions!B10,0) | F19: =ROUND(F17*Assumptions!B10,0) | G19: =ROUND(G17*Assumptions!B10,0) | H19: =ROUND(H17*Assumptions!B10,0) | I19: =ROUND(I17*Assumptions!B10,0) | J19: =ROUND(J17*Assumptions!B10,0) | K19: =ROUND(K17*Assumptions!B10,0) | L19: =ROUND(L17*Assumptions!B10,0) | M19: =ROUND(M17*Assumptions!B10,0) | N19: =ROUND(N17*Assumptions!B10,0) | O19: =ROUND(O17*Assumptions!B10,0) | P19: =ROUND(P17*Assumptions!B10,0) | Q19: =ROUND(Q17*Assumptions!B10,0) | R19: =ROUND(R17*Assumptions!B10,0) | S19: =ROUND(S17*Assumptions!B10,0) | T19: =ROUND(T17*Assumptions!B10,0) | U19: =ROUND(U17*Assumptions!B10,0) | V19: =ROUND(V17*Assumptions!B10,0) | W19: =ROUND(W17*Assumptions!B10,0) | X19: =ROUND(X17*Assumptions!B10,0) | Y19: =ROUND(Y17*Assumptions!B10,0)
A20: Premium Subs (10%) | B20: =MAX(0,B17-B18-B19) | C20: =MAX(0,C17-C18-C19) | D20: =MAX(0,D17-D18-D19) | E20: =MAX(0,E17-E18-E19) | F20: =MAX(0,F17-F18-F19) | G20: =MAX(0,G17-G18-G19) | H20: =MAX(0,H17-H18-H19) | I20: =MAX(0,I17-I18-I19) | ... Y20: =MAX(0,Y17-Y18-Y19)
A21: CGM Active Users | B21: 0 | C21: 0 | D21: 0 | E21: 0 | F21: 0 | G21: 0 | H21: 3 | I21: 6 | J21: 9 | K21: 12 | L21: 15 | M21: 18 | N21: 21 | O21: 24 | P21: 27 | Q21: 30 | R21: 32 | S21: 34 | T21: 36 | U21: 38 | V21: 39 | W21: 40 | X21: 41 | Y21: 42
A22: B2B Clients | B22: 0 | C22: 0 | D22: 0 | E22: 0 | F22: 0 | G22: 0 | H22: 0 | I22: 0 | J22: 1 | K22: 1 | L22: 1 | M22: 2 | N22: 2 | O22: 2 | P22: 2 | Q22: 2 | R22: 2 | S22: 3 | T22: 3 | U22: 3 | V22: 3 | W22: 3 | X22: 3 | Y22: 3

Sheet Cash Flow
A1: alche — Cash Flow Statement v3
A2: P5: EUR ~218K gap between P&L profit and actual cash. This sheet closes that gap.
A3: Cash Flow (EUR) | B3: M1 | C3: M2 | D3: M3 | E3: M4 | F3: M5 | G3: M6 | H3: M7 | I3: M8 | J3: M9 | K3: M10 | L3: M11 | M3: M12 | N3: M13 | O3: M14 | P3: M15 | Q3: M16 | R3: M17 | S3: M18 | T3: M19 | U3: M20 | V3: M21 | W3: M22 | X3: M23 | Y3: M24 | Z3: TOTAL
A4: OPERATING ACTIVITIES
A5: EBITDA | B5: ='P&L'!B133 | C5: ='P&L'!C133 | D5: ='P&L'!D133 | E5: ='P&L'!E133 | F5: ='P&L'!F133 | G5: ='P&L'!G133 | H5: ='P&L'!H133 | I5: ='P&L'!I133 | ... Y5: ='P&L'!Y133 | Z5: =SUM(B5:Y5)
A6: - Tax Provision | B6: =-'P&L'!B166 | C6: =-'P&L'!C166 | D6: =-'P&L'!D166 | E6: =-'P&L'!E166 | F6: =-'P&L'!F166 | G6: =-'P&L'!G166 | H6: =-'P&L'!H166 | I6: =-'P&L'!I166 | ... Y6: =-'P&L'!Y166 | Z6: =SUM(B6:Y6)
A7: - Working Capital Build (inventory) | B7: =-ROUND('Growth Curves'!B4*Assumptions!B23*2,0) | C7: =-ROUND(MAX(0,('Growth Curves'!C4-'Growth Curves'!B4)*Assumptions!B23*2),0) | D7: =-ROUND(MAX(0,('Growth Curves'!D4-'Growth Curves'!C4)*Assumptions!B23*2),0) | E7: =-ROUND(MAX(0,('Growth Curves'!E4-'Growth Curves'!D4)*Assumptions!B23*2),0) | F7: =-ROUND(MAX(0,('Growth Curves'!F4-'Growth Curves'!E4)*Assumptions!B23*2),0) | G7: =-ROUND(MAX(0,('Growth Curves'!G4-'Growth Curves'!F4)*Assumptions!B23*2),0) | H7: =-ROUND(MAX(0,('Growth Curves'!H4-'Growth Curves'!G4)*Assumptions!B23*2),0) | I7: =-ROUND(MAX(0,('Growth Curves'!I4-'Growth Curves'!H4)*Assumptions!B23*2),0) | J7: =-ROUND(MAX(0,('Growth Curves'!J4-'Growth Curves'!I4)*Assumptions!B23*2),0) | K7: =-ROUND(MAX(0,('Growth Curves'!K4-'Growth Curves'!J4)*Assumptions!B23*2),0) | L7: =-ROUND(MAX(0,('Growth Curves'!L4-'Growth Curves'!K4)*Assumptions!B23*2),0) | M7: =-ROUND(MAX(0,('Growth Curves'!M4-'Growth Curves'!L4)*Assumptions!B23*2),0) | N7: =-ROUND(MAX(0,('Growth Curves'!N4-'Growth Curves'!M4)*Assumptions!B23*2),0) | O7: =-ROUND(MAX(0,('Growth Curves'!O4-'Growth Curves'!N4)*Assumptions!B23*2),0) | P7: =-ROUND(MAX(0,('Growth Curves'!P4-'Growth Curves'!O4)*Assumptions!B23*2),0) | Q7: =-ROUND(MAX(0,('Growth Curves'!Q4-'Growth Curves'!P4)*Assumptions!B23*2),0) | R7: =-ROUND(MAX(0,('Growth Curves'!R4-'Growth Curves'!Q4)*Assumptions!B23*2),0) | S7: =-ROUND(MAX(0,('Growth Curves'!S4-'Growth Curves'!R4)*Assumptions!B23*2),0) | T7: =-ROUND(MAX(0,('Growth Curves'!T4-'Growth Curves'!S4)*Assumptions!B23*2),0) | U7: =-ROUND(MAX(0,('Growth Curves'!U4-'Growth Curves'!T4)*Assumptions!B23*2),0) | V7: =-ROUND(MAX(0,('Growth Curves'!V4-'Growth Curves'!U4)*Assumptions!B23*2),0) | W7: =-ROUND(MAX(0,('Growth Curves'!W4-'Growth Curves'!V4)*Assumptions!B23*2),0) | X7: =-ROUND(MAX(0,('Growth Curves'!X4-'Growth Curves'!W4)*Assumptions!B23*2),0) | Y7: =-ROUND(MAX(0,('Growth Curves'!Y4-'Growth Curves'!X4)*Assumptions!B23*2),0) | Z7: =SUM(B7:Y7)
A8: Operating Cash Flow | B8: =B5+B6+B7 | C8: =C5+C6+C7 | D8: =D5+D6+D7 | E8: =E5+E6+E7 | F8: =F5+F6+F7 | G8: =G5+G6+G7 | H8: =H5+H6+H7 | I8: =I5+I6+I7 | ... Y8: =Y5+Y6+Y7 | Z8: =SUM(B8:Y8)
A10: INVESTING ACTIVITIES
A11: CapEx | B11: =-'P&L'!B160 | C11: =-'P&L'!C160 | D11: =-'P&L'!D160 | E11: =-'P&L'!E160 | F11: =-'P&L'!F160 | G11: =-'P&L'!G160 | H11: =-'P&L'!H160 | I11: =-'P&L'!I160 | ... Y11: =-'P&L'!Y160 | Z11: =SUM(B11:Y11)
A12: Kaution — Security Deposit (M3) | B12: =IF(1=3,-Assumptions!B118,0) | C12: =IF(2=3,-Assumptions!B118,0) | D12: =IF(3=3,-Assumptions!B118,0) | E12: =IF(4=3,-Assumptions!B118,0) | F12: =IF(5=3,-Assumptions!B118,0) | G12: =IF(6=3,-Assumptions!B118,0) | H12: =IF(7=3,-Assumptions!B118,0) | I12: =IF(8=3,-Assumptions!B118,0) | J12: =IF(9=3,-Assumptions!B118,0) | K12: =IF(10=3,-Assumptions!B118,0) | L12: =IF(11=3,-Assumptions!B118,0) | M12: =IF(12=3,-Assumptions!B118,0) | N12: =IF(13=3,-Assumptions!B118,0) | O12: =IF(14=3,-Assumptions!B118,0) | P12: =IF(15=3,-Assumptions!B118,0) | Q12: =IF(16=3,-Assumptions!B118,0) | R12: =IF(17=3,-Assumptions!B118,0) | S12: =IF(18=3,-Assumptions!B118,0) | T12: =IF(19=3,-Assumptions!B118,0) | U12: =IF(20=3,-Assumptions!B118,0) | V12: =IF(21=3,-Assumptions!B118,0) | W12: =IF(22=3,-Assumptions!B118,0) | X12: =IF(23=3,-Assumptions!B118,0) | Y12: =IF(24=3,-Assumptions!B118,0) | Z12: =SUM(B12:Y12)
A13: Space Security Deposit M3 (EX-07: balance sheet, refundable) | B13: =IF(1=3,-Assumptions!B139,0) | C13: =IF(2=3,-Assumptions!B139,0) | D13: =IF(3=3,-Assumptions!B139,0) | E13: =IF(4=3,-Assumptions!B139,0) | F13: =IF(5=3,-Assumptions!B139,0) | G13: =IF(6=3,-Assumptions!B139,0) | H13: =IF(7=3,-Assumptions!B139,0) | I13: =IF(8=3,-Assumptions!B139,0) | J13: =IF(9=3,-Assumptions!B139,0) | K13: =IF(10=3,-Assumptions!B139,0) | L13: =IF(11=3,-Assumptions!B139,0) | M13: =IF(12=3,-Assumptions!B139,0) | N13: =IF(13=3,-Assumptions!B139,0) | O13: =IF(14=3,-Assumptions!B139,0) | P13: =IF(15=3,-Assumptions!B139,0) | Q13: =IF(16=3,-Assumptions!B139,0) | R13: =IF(17=3,-Assumptions!B139,0) | S13: =IF(18=3,-Assumptions!B139,0) | T13: =IF(19=3,-Assumptions!B139,0) | U13: =IF(20=3,-Assumptions!B139,0) | V13: =IF(21=3,-Assumptions!B139,0) | W13: =IF(22=3,-Assumptions!B139,0) | X13: =IF(23=3,-Assumptions!B139,0) | Y13: =IF(24=3,-Assumptions!B139,0) | Z13: =SUM(B13:Y13)
A14: Investing Cash Flow | B14: =B11+B12+B13 | C14: =C11+C12+C13 | D14: =D11+D12+D13 | E14: =E11+E12+E13 | F14: =F11+F12+F13 | G14: =G11+G12+G13 | H14: =H11+H12+H13 | I14: =I11+I12+I13 | ... Y14: =Y11+Y12+Y13 | Z14: =SUM(B14:Y14)
A16: FINANCING ACTIVITIES
A17: Pre-Seed Funding (M1) | B17: =IF(1=1,Assumptions!B142,0) | C17: =IF(2=1,Assumptions!B142,0) | D17: =IF(3=1,Assumptions!B142,0) | E17: =IF(4=1,Assumptions!B142,0) | F17: =IF(5=1,Assumptions!B142,0) | G17: =IF(6=1,Assumptions!B142,0) | H17: =IF(7=1,Assumptions!B142,0) | I17: =IF(8=1,Assumptions!B142,0) | J17: =IF(9=1,Assumptions!B142,0) | K17: =IF(10=1,Assumptions!B142,0) | L17: =IF(11=1,Assumptions!B142,0) | M17: =IF(12=1,Assumptions!B142,0) | N17: =IF(13=1,Assumptions!B142,0) | O17: =IF(14=1,Assumptions!B142,0) | P17: =IF(15=1,Assumptions!B142,0) | Q17: =IF(16=1,Assumptions!B142,0) | R17: =IF(17=1,Assumptions!B142,0) | S17: =IF(18=1,Assumptions!B142,0) | T17: =IF(19=1,Assumptions!B142,0) | U17: =IF(20=1,Assumptions!B142,0) | V17: =IF(21=1,Assumptions!B142,0) | W17: =IF(22=1,Assumptions!B142,0) | X17: =IF(23=1,Assumptions!B142,0) | Y17: =IF(24=1,Assumptions!B142,0) | Z17: =SUM(B17:Y17)
A18: Financing Cash Flow | B18: =B17 | C18: =C17 | D18: =D17 | E18: =E17 | F18: =F17 | G18: =G17 | H18: =H17 | I18: =I17 | ... Y18: =Y17 | Z18: =SUM(B18:Y18)
A20: NET CASH FLOW | B20: =B8+B14+B18 | C20: =C8+C14+C18 | D20: =D8+D14+D18 | E20: =E8+E14+E18 | F20: =F8+F14+F18 | G20: =G8+G14+G18 | H20: =H8+H14+H18 | I20: =I8+I14+I18 | ... Y20: =Y8+Y14+Y18 | Z20: =SUM(B20:Y20)
A21: CUMULATIVE CASH BALANCE | B21: =B20 | C21: =B21+C20 | D21: =C21+D20 | E21: =D21+E20 | F21: =E21+F20 | G21: =F21+G20 | H21: =G21+H20 | I21: =H21+I20 | J21: =I21+J20 | ... Y21: =X21+Y20 | Z21: =Y21
A23: P&L vs CASH GAP ANALYSIS
A24: P&L Cumulative Cash | B24: ='P&L'!B169 | C24: ='P&L'!C169 | D24: ='P&L'!D169 | E24: ='P&L'!E169 | F24: ='P&L'!F169 | G24: ='P&L'!G169 | H24: ='P&L'!H169 | I24: ='P&L'!I169 | ... Y24: ='P&L'!Y169 | Z24: =SUM(B24:Y24)
A25: Actual Cash (this sheet) | B25: =B21 | C25: =C21 | D25: =D21 | E25: =E21 | F25: =F21 | G25: =G21 | H25: =H21 | I25: =I21 | ... Y25: =Y21 | Z25: =SUM(B25:Y25)
A26: GAP (Working Capital Drag) | B26: =B25-B24 | C26: =C25-C24 | D26: =D25-D24 | E26: =E25-E24 | F26: =F25-F24 | G26: =G25-G24 | H26: =H25-H24 | I26: =I25-I24 | ... Y26: =Y25-Y24 | Z26: =SUM(B26:Y26)

Sheet Unit Economics
A1: alche — Unit Economics Dashboard
A2: P1/P5: LTV:CAC, payback period, contribution margin per stream
A3: Metric | B3: M1 | C3: M2 | D3: M3 | E3: M4 | F3: M5 | G3: M6 | H3: M7 | I3: M8 | J3: M9 | K3: M10 | L3: M11 | M3: M12 | N3: M13 | O3: M14 | P3: M15 | Q3: M16 | R3: M17 | S3: M18 | T3: M19 | U3: M20 | V3: M21 | W3: M22 | X3: M23 | Y3: M24 | Z3: TOTAL
A4: SUBSCRIPTION METRICS
A5: Subscription ARPU (EUR/sub/mo) | B5: =IF('Growth Curves'!B17>0,ROUND('P&L'!B42/'Growth Curves'!B17,2),0) | C5: =IF('Growth Curves'!C17>0,ROUND('P&L'!C42/'Growth Curves'!C17,2),0) | D5: =IF('Growth Curves'!D17>0,ROUND('P&L'!D42/'Growth Curves'!D17,2),0) | E5: =IF('Growth Curves'!E17>0,ROUND('P&L'!E42/'Growth Curves'!E17,2),0) | F5: =IF('Growth Curves'!F17>0,ROUND('P&L'!F42/'Growth Curves'!F17,2),0) | G5: =IF('Growth Curves'!G17>0,ROUND('P&L'!G42/'Growth Curves'!G17,2),0) | H5: =IF('Growth Curves'!H17>0,ROUND('P&L'!H42/'Growth Curves'!H17,2),0) | I5: =IF('Growth Curves'!I17>0,ROUND('P&L'!I42/'Growth Curves'!I17,2),0) | ... Y5: =IF('Growth Curves'!Y17>0,ROUND('P&L'!Y42/'Growth Curves'!Y17,2),0) | Z5: =Y5
A6: Subscription LTV (ARPU / churn) | B6: =IF('Growth Curves'!B17>0,ROUND(('P&L'!B42/'Growth Curves'!B17)/Assumptions!B8,0),0) | C6: =IF('Growth Curves'!C17>0,ROUND(('P&L'!C42/'Growth Curves'!C17)/Assumptions!B8,0),0) | D6: =IF('Growth Curves'!D17>0,ROUND(('P&L'!D42/'Growth Curves'!D17)/Assumptions!B8,0),0) | E6: =IF('Growth Curves'!E17>0,ROUND(('P&L'!E42/'Growth Curves'!E17)/Assumptions!B8,0),0) | F6: =IF('Growth Curves'!F17>0,ROUND(('P&L'!F42/'Growth Curves'!F17)/Assumptions!B8,0),0) | G6: =IF('Growth Curves'!G17>0,ROUND(('P&L'!G42/'Growth Curves'!G17)/Assumptions!B8,0),0) | H6: =IF('Growth Curves'!H17>0,ROUND(('P&L'!H42/'Growth Curves'!H17)/Assumptions!B8,0),0) | I6: =IF('Growth Curves'!I17>0,ROUND(('P&L'!I42/'Growth Curves'!I17)/Assumptions!B8,0),0) | J6: =IF('Growth Curves'!J17>0,ROUND(('P&L'!J42/'Growth Curves'!J17)/Assumptions!B8,0),0) | K6: =IF('Growth Curves'!K17>0,ROUND(('P&L'!K42/'Growth Curves'!K17)/Assumptions!B8,0),0) | L6: =IF('Growth Curves'!L17>0,ROUND(('P&L'!L42/'Growth Curves'!L17)/Assumptions!B8,0),0) | M6: =IF('Growth Curves'!M17>0,ROUND(('P&L'!M42/'Growth Curves'!M17)/Assumptions!B8,0),0) | N6: =IF('Growth Curves'!N17>0,ROUND(('P&L'!N42/'Growth Curves'!N17)/Assumptions!B8,0),0) | O6: =IF('Growth Curves'!O17>0,ROUND(('P&L'!O42/'Growth Curves'!O17)/Assumptions!B8,0),0) | P6: =IF('Growth Curves'!P17>0,ROUND(('P&L'!P42/'Growth Curves'!P17)/Assumptions!B8,0),0) | Q6: =IF('Growth Curves'!Q17>0,ROUND(('P&L'!Q42/'Growth Curves'!Q17)/Assumptions!B8,0),0) | R6: =IF('Growth Curves'!R17>0,ROUND(('P&L'!R42/'Growth Curves'!R17)/Assumptions!B8,0),0) | S6: =IF('Growth Curves'!S17>0,ROUND(('P&L'!S42/'Growth Curves'!S17)/Assumptions!B8,0),0) | T6: =IF('Growth Curves'!T17>0,ROUND(('P&L'!T42/'Growth Curves'!T17)/Assumptions!B8,0),0) | U6: =IF('Growth Curves'!U17>0,ROUND(('P&L'!U42/'Growth Curves'!U17)/Assumptions!B8,0),0) | V6: =IF('Growth Curves'!V17>0,ROUND(('P&L'!V42/'Growth Curves'!V17)/Assumptions!B8,0),0) | W6: =IF('Growth Curves'!W17>0,ROUND(('P&L'!W42/'Growth Curves'!W17)/Assumptions!B8,0),0) | X6: =IF('Growth Curves'!X17>0,ROUND(('P&L'!X42/'Growth Curves'!X17)/Assumptions!B8,0),0) | Y6: =IF('Growth Curves'!Y17>0,ROUND(('P&L'!Y42/'Growth Curves'!Y17)/Assumptions!B8,0),0) | Z6: =Y6
A7: CAC (paid ads / new subs) | B7: =IF('Growth Curves'!B15>0,ROUND('Growth Curves'!B10/'Growth Curves'!B15,0),0) | C7: =IF('Growth Curves'!C15>0,ROUND('Growth Curves'!C10/'Growth Curves'!C15,0),0) | D7: =IF('Growth Curves'!D15>0,ROUND('Growth Curves'!D10/'Growth Curves'!D15,0),0) | E7: =IF('Growth Curves'!E15>0,ROUND('Growth Curves'!E10/'Growth Curves'!E15,0),0) | F7: =IF('Growth Curves'!F15>0,ROUND('Growth Curves'!F10/'Growth Curves'!F15,0),0) | G7: =IF('Growth Curves'!G15>0,ROUND('Growth Curves'!G10/'Growth Curves'!G15,0),0) | H7: =IF('Growth Curves'!H15>0,ROUND('Growth Curves'!H10/'Growth Curves'!H15,0),0) | I7: =IF('Growth Curves'!I15>0,ROUND('Growth Curves'!I10/'Growth Curves'!I15,0),0) | ... Y7: =IF('Growth Curves'!Y15>0,ROUND('Growth Curves'!Y10/'Growth Curves'!Y15,0),0) | Z7: =Y7
A8: LTV:CAC Ratio | B8: =IF(B7>0,ROUND(B6/B7,1),0) | C8: =IF(C7>0,ROUND(C6/C7,1),0) | D8: =IF(D7>0,ROUND(D6/D7,1),0) | E8: =IF(E7>0,ROUND(E6/E7,1),0) | F8: =IF(F7>0,ROUND(F6/F7,1),0) | G8: =IF(G7>0,ROUND(G6/G7,1),0) | H8: =IF(H7>0,ROUND(H6/H7,1),0) | I8: =IF(I7>0,ROUND(I6/I7,1),0) | ... Y8: =IF(Y7>0,ROUND(Y6/Y7,1),0) | Z8: =Y8
A9: CAC Payback (months) | B9: =IF(AND(B6>0,B5>0),ROUND(B7/B5,1),0) | C9: =IF(AND(C6>0,C5>0),ROUND(C7/C5,1),0) | D9: =IF(AND(D6>0,D5>0),ROUND(D7/D5,1),0) | E9: =IF(AND(E6>0,E5>0),ROUND(E7/E5,1),0) | F9: =IF(AND(F6>0,F5>0),ROUND(F7/F5,1),0) | G9: =IF(AND(G6>0,G5>0),ROUND(G7/G5,1),0) | H9: =IF(AND(H6>0,H5>0),ROUND(H7/H5,1),0) | I9: =IF(AND(I6>0,I5>0),ROUND(I7/I5,1),0) | ... Y9: =IF(AND(Y6>0,Y5>0),ROUND(Y7/Y5,1),0) | Z9: =Y9
A11: CONTRIBUTION MARGIN BY STREAM
A12: Retail Contribution Margin % | B12: =IF('P&L'!B17>0,('P&L'!B17-'P&L'!B51-'P&L'!B52-'P&L'!B53)/'P&L'!B17,0) | C12: =IF('P&L'!C17>0,('P&L'!C17-'P&L'!C51-'P&L'!C52-'P&L'!C53)/'P&L'!C17,0) | D12: =IF('P&L'!D17>0,('P&L'!D17-'P&L'!D51-'P&L'!D52-'P&L'!D53)/'P&L'!D17,0) | E12: =IF('P&L'!E17>0,('P&L'!E17-'P&L'!E51-'P&L'!E52-'P&L'!E53)/'P&L'!E17,0) | F12: =IF('P&L'!F17>0,('P&L'!F17-'P&L'!F51-'P&L'!F52-'P&L'!F53)/'P&L'!F17,0) | G12: =IF('P&L'!G17>0,('P&L'!G17-'P&L'!G51-'P&L'!G52-'P&L'!G53)/'P&L'!G17,0) | H12: =IF('P&L'!H17>0,('P&L'!H17-'P&L'!H51-'P&L'!H52-'P&L'!H53)/'P&L'!H17,0) | I12: =IF('P&L'!I17>0,('P&L'!I17-'P&L'!I51-'P&L'!I52-'P&L'!I53)/'P&L'!I17,0) | ... Y12: =IF('P&L'!Y17>0,('P&L'!Y17-'P&L'!Y51-'P&L'!Y52-'P&L'!Y53)/'P&L'!Y17,0) | Z12: =Y12
A13: LED Therapy Contribution Margin % | B13: =IF('P&L'!B21>0,('P&L'!B21-'P&L'!B54)/'P&L'!B21,0) | C13: =IF('P&L'!C21>0,('P&L'!C21-'P&L'!C54)/'P&L'!C21,0) | D13: =IF('P&L'!D21>0,('P&L'!D21-'P&L'!D54)/'P&L'!D21,0) | E13: =IF('P&L'!E21>0,('P&L'!E21-'P&L'!E54)/'P&L'!E21,0) | F13: =IF('P&L'!F21>0,('P&L'!F21-'P&L'!F54)/'P&L'!F21,0) | G13: =IF('P&L'!G21>0,('P&L'!G21-'P&L'!G54)/'P&L'!G21,0) | H13: =IF('P&L'!H21>0,('P&L'!H21-'P&L'!H54)/'P&L'!H21,0) | I13: =IF('P&L'!I21>0,('P&L'!I21-'P&L'!I54)/'P&L'!I21,0) | ... Y13: =IF('P&L'!Y21>0,('P&L'!Y21-'P&L'!Y54)/'P&L'!Y21,0) | Z13: =Y13
A14: Smoothie Bar Contribution Margin % | B14: =IF('P&L'!B25>0,('P&L'!B25-'P&L'!B56)/'P&L'!B25,0) | C14: =IF('P&L'!C25>0,('P&L'!C25-'P&L'!C56)/'P&L'!C25,0) | D14: =IF('P&L'!D25>0,('P&L'!D25-'P&L'!D56)/'P&L'!D25,0) | E14: =IF('P&L'!E25>0,('P&L'!E25-'P&L'!E56)/'P&L'!E25,0) | F14: =IF('P&L'!F25>0,('P&L'!F25-'P&L'!F56)/'P&L'!F25,0) | G14: =IF('P&L'!G25>0,('P&L'!G25-'P&L'!G56)/'P&L'!G25,0) | H14: =IF('P&L'!H25>0,('P&L'!H25-'P&L'!H56)/'P&L'!H25,0) | I14: =IF('P&L'!I25>0,('P&L'!I25-'P&L'!I56)/'P&L'!I25,0) | ... Y14: =IF('P&L'!Y25>0,('P&L'!Y25-'P&L'!Y56)/'P&L'!Y25,0) | Z14: =Y14
A15: Subscription Contribution Margin % | B15: =IF('P&L'!B42>0,('P&L'!B42-'P&L'!B59)/'P&L'!B42,0) | C15: =IF('P&L'!C42>0,('P&L'!C42-'P&L'!C59)/'P&L'!C42,0) | D15: =IF('P&L'!D42>0,('P&L'!D42-'P&L'!D59)/'P&L'!D42,0) | E15: =IF('P&L'!E42>0,('P&L'!E42-'P&L'!E59)/'P&L'!E42,0) | F15: =IF('P&L'!F42>0,('P&L'!F42-'P&L'!F59)/'P&L'!F42,0) | G15: =IF('P&L'!G42>0,('P&L'!G42-'P&L'!G59)/'P&L'!G42,0) | H15: =IF('P&L'!H42>0,('P&L'!H42-'P&L'!H59)/'P&L'!H42,0) | I15: =IF('P&L'!I42>0,('P&L'!I42-'P&L'!I59)/'P&L'!I42,0) | ... Y15: =IF('P&L'!Y42>0,('P&L'!Y42-'P&L'!Y59)/'P&L'!Y42,0) | Z15: =Y15
A17: REVENUE MIX (P5: only 4.7% subs at M24)
A18: Retail % | B18: =IF('P&L'!B47>0,'P&L'!B17/'P&L'!B47,0) | C18: =IF('P&L'!C47>0,'P&L'!C17/'P&L'!C47,0) | D18: =IF('P&L'!D47>0,'P&L'!D17/'P&L'!D47,0) | E18: =IF('P&L'!E47>0,'P&L'!E17/'P&L'!E47,0) | F18: =IF('P&L'!F47>0,'P&L'!F17/'P&L'!F47,0) | G18: =IF('P&L'!G47>0,'P&L'!G17/'P&L'!G47,0) | H18: =IF('P&L'!H47>0,'P&L'!H17/'P&L'!H47,0) | I18: =IF('P&L'!I47>0,'P&L'!I17/'P&L'!I47,0) | ... Y18: =IF('P&L'!Y47>0,'P&L'!Y17/'P&L'!Y47,0) | Z18: =Y18
A19: LED % | B19: =IF('P&L'!B47>0,'P&L'!B21/'P&L'!B47,0) | C19: =IF('P&L'!C47>0,'P&L'!C21/'P&L'!C47,0) | D19: =IF('P&L'!D47>0,'P&L'!D21/'P&L'!D47,0) | E19: =IF('P&L'!E47>0,'P&L'!E21/'P&L'!E47,0) | F19: =IF('P&L'!F47>0,'P&L'!F21/'P&L'!F47,0) | G19: =IF('P&L'!G47>0,'P&L'!G21/'P&L'!G47,0) | H19: =IF('P&L'!H47>0,'P&L'!H21/'P&L'!H47,0) | I19: =IF('P&L'!I47>0,'P&L'!I21/'P&L'!I47,0) | ... Y19: =IF('P&L'!Y47>0,'P&L'!Y21/'P&L'!Y47,0) | Z19: =Y19
A20: Smoothie % | B20: =IF('P&L'!B47>0,'P&L'!B25/'P&L'!B47,0) | C20: =IF('P&L'!C47>0,'P&L'!C25/'P&L'!C47,0) | D20: =IF('P&L'!D47>0,'P&L'!D25/'P&L'!D47,0) | E20: =IF('P&L'!E47>0,'P&L'!E25/'P&L'!E47,0) | F20: =IF('P&L'!F47>0,'P&L'!F25/'P&L'!F47,0) | G20: =IF('P&L'!G47>0,'P&L'!G25/'P&L'!G47,0) | H20: =IF('P&L'!H47>0,'P&L'!H25/'P&L'!H47,0) | I20: =IF('P&L'!I47>0,'P&L'!I25/'P&L'!I47,0) | ... Y20: =IF('P&L'!Y47>0,'P&L'!Y25/'P&L'!Y47,0) | Z20: =Y20
A21: Events % | B21: =IF('P&L'!B47>0,'P&L'!B31/'P&L'!B47,0) | C21: =IF('P&L'!C47>0,'P&L'!C31/'P&L'!C47,0) | D21: =IF('P&L'!D47>0,'P&L'!D31/'P&L'!D47,0) | E21: =IF('P&L'!E47>0,'P&L'!E31/'P&L'!E47,0) | F21: =IF('P&L'!F47>0,'P&L'!F31/'P&L'!F47,0) | G21: =IF('P&L'!G47>0,'P&L'!G31/'P&L'!G47,0) | H21: =IF('P&L'!H47>0,'P&L'!H31/'P&L'!H47,0) | I21: =IF('P&L'!I47>0,'P&L'!I31/'P&L'!I47,0) | ... Y21: =IF('P&L'!Y47>0,'P&L'!Y31/'P&L'!Y47,0) | Z21: =Y21
A22: Doctor SaaS % | B22: =IF('P&L'!B47>0,'P&L'!B35/'P&L'!B47,0) | C22: =IF('P&L'!C47>0,'P&L'!C35/'P&L'!C47,0) | D22: =IF('P&L'!D47>0,'P&L'!D35/'P&L'!D47,0) | E22: =IF('P&L'!E47>0,'P&L'!E35/'P&L'!E47,0) | F22: =IF('P&L'!F47>0,'P&L'!F35/'P&L'!F47,0) | G22: =IF('P&L'!G47>0,'P&L'!G35/'P&L'!G47,0) | H22: =IF('P&L'!H47>0,'P&L'!H35/'P&L'!H47,0) | I22: =IF('P&L'!I47>0,'P&L'!I35/'P&L'!I47,0) | ... Y22: =IF('P&L'!Y47>0,'P&L'!Y35/'P&L'!Y47,0) | Z22: =Y22
A23: CGM % | B23: =IF('P&L'!B47>0,'P&L'!B36/'P&L'!B47,0) | C23: =IF('P&L'!C47>0,'P&L'!C36/'P&L'!C47,0) | D23: =IF('P&L'!D47>0,'P&L'!D36/'P&L'!D47,0) | E23: =IF('P&L'!E47>0,'P&L'!E36/'P&L'!E47,0) | F23: =IF('P&L'!F47>0,'P&L'!F36/'P&L'!F47,0) | G23: =IF('P&L'!G47>0,'P&L'!G36/'P&L'!G47,0) | H23: =IF('P&L'!H47>0,'P&L'!H36/'P&L'!H47,0) | I23: =IF('P&L'!I47>0,'P&L'!I36/'P&L'!I47,0) | ... Y23: =IF('P&L'!Y47>0,'P&L'!Y36/'P&L'!Y47,0) | Z23: =Y23
A24: B2B Corporate % | B24: =IF('P&L'!B47>0,'P&L'!B44/'P&L'!B47,0) | C24: =IF('P&L'!C47>0,'P&L'!C44/'P&L'!C47,0) | D24: =IF('P&L'!D47>0,'P&L'!D44/'P&L'!D47,0) | E24: =IF('P&L'!E47>0,'P&L'!E44/'P&L'!E47,0) | F24: =IF('P&L'!F47>0,'P&L'!F44/'P&L'!F47,0) | G24: =IF('P&L'!G47>0,'P&L'!G44/'P&L'!G47,0) | H24: =IF('P&L'!H47>0,'P&L'!H44/'P&L'!H47,0) | I24: =IF('P&L'!I47>0,'P&L'!I44/'P&L'!I47,0) | ... Y24: =IF('P&L'!Y47>0,'P&L'!Y44/'P&L'!Y47,0) | Z24: =Y24
A25: Gift Cards % | B25: =IF('P&L'!B47>0,'P&L'!B45/'P&L'!B47,0) | C25: =IF('P&L'!C47>0,'P&L'!C45/'P&L'!C47,0) | D25: =IF('P&L'!D47>0,'P&L'!D45/'P&L'!D47,0) | E25: =IF('P&L'!E47>0,'P&L'!E45/'P&L'!E47,0) | F25: =IF('P&L'!F47>0,'P&L'!F45/'P&L'!F47,0) | G25: =IF('P&L'!G47>0,'P&L'!G45/'P&L'!G47,0) | H25: =IF('P&L'!H47>0,'P&L'!H45/'P&L'!H47,0) | I25: =IF('P&L'!I47>0,'P&L'!I45/'P&L'!I47,0) | ... Y25: =IF('P&L'!Y47>0,'P&L'!Y45/'P&L'!Y47,0) | Z25: =Y25
